Workbook

Sheet Consolidated Financials
B1: Everbridge Inc (29978A10)
B2: Consolidated Financials
C3: Actual | H3: Forecast
B4: FYE December | C4: 43830 | D4: 44196 | E4: 44561 | F4: 44926 | G4: 45291 | H4: =EDATE(G4,12) -> 45657 | I4: =EDATE(H4,12) -> 46022 | J4: =EDATE(I4,12) -> 46387 | K4: =EDATE(J4,12) -> 46752 | L4: =EDATE(K4,12) -> 47118 | M4: =EDATE(L4,12) -> 47483 | N4: =EDATE(M4,12) -> 47848 | O4: =EDATE(N4,12) -> 48213 | ... Q4: =EDATE(P4,12) -> 48944
B5: Currency | C5: USD | D5: USD | E5: USD | F5: USD | G5: USD | H5: USD | I5: USD | J5: USD | K5: USD | L5: USD | M5: USD | N5: USD | O5: USD | P5: USD | Q5: USD
B6: Scale | C6: Million | D6: Million | E6: Million | F6: Million | G6: Million | H6: Million | I6: Million | J6: Million | K6: Million | L6: Million | M6: Million | N6: Million | O6: Million | P6: Million | Q6: Million
B7: Total Revenue | C7: 200.882 | D7: 271.141 | E7: 368.433 | F7: 431.892 | G7: 448.788 | H7: ='Revenue Build'!H10 -> 475.62 | I7: ='Revenue Build'!I10 -> 511.4865 | J7: ='Revenue Build'!J10 -> 550.54979 | K7: ='Revenue Build'!K10 -> 587.55923 | L7: ='Revenue Build'!L10 -> 624.37253 | M7: ='Revenue Build'!M10 -> 660.61826 | N7: ='Revenue Build'!N10 -> 686.62528 | O7: ='Revenue Build'!O10 -> 711.72925 | ... Q7: ='Revenue Build'!Q10 -> 755.74765
B8: Year-over-year growth | D8: =D7/C7 - 1 -> 0.34975259 | E8: =E7/D7 - 1 -> 0.35882438 | F8: =F7/E7 - 1 -> 0.17224027 | G8: =G7/F7 - 1 -> 0.039120891 | H8: =H7/G7 - 1 -> 0.059787695 | I8: =I7/H7 - 1 -> 0.075409991 | J8: =J7/I7 - 1 -> 0.076372074 | K8: =K7/J7 - 1 -> 0.067222698 | ... Q8: =Q7/P7 - 1 -> 0.026247924
B10: Cost of Revenue, Total | C10: 63.535 | D10: 83.028 | E10: 114.216 | F10: 133.981 | G10: 130.673 | H10: =H$7*(H38) -> 145.9097 | I10: =I$7*(I38) -> 155.94069 | J10: =J$7*(J38) -> 167.7027 | K10: =K$7*(K38) -> 178.34212 | L10: =L$7*(L38) -> 188.68088 | M10: =M$7*(M38) -> 198.8461 | N10: =N$7*(N38) -> 205.30096 | O10: =O$7*(O38) -> 212.80705 | ... Q10: =Q$7*(Q38) -> 223.7013
B11: Gross Profit | C11: 137.347 | D11: 188.113 | E11: 254.217 | F11: 297.911 | G11: 318.115 | H11: =H7-H10 -> 329.7103 | I11: =I7-I10 -> 355.54581 | J11: =J7-J10 -> 382.84708 | K11: =K7-K10 -> 409.21711 | L11: =L7-L10 -> 435.69165 | M11: =M7-M10 -> 461.77216 | N11: =N7-N10 -> 481.32432 | O11: =O7-O10 -> 498.9222 | ... Q11: =Q7-Q10 -> 532.04634
B12: Selling/General/Admin. Expenses, Total | C12: 124.816 | D12: 179.818 | E12: 217.869 | F12: 234.794 | G12: 217.39 | H12: =H39*H$7 -> 212.60214 | I12: =I39*I$7 -> 209.70947 | J12: =J39*J$7 -> 216.36607 | K12: =K39*K$7 -> 217.39691 | L12: =L39*L$7 -> 223.52536 | M12: =M39*M$7 -> 231.87701 | N12: =N39*N$7 -> 237.57235 | O12: =O39*O$7 -> 243.4114 | ... Q12: =Q39*Q$7 -> 250.15247
B13: Research & Development | C13: 49.522 | D13: 61.915 | E13: 80.937 | F13: 94.039 | G13: 91.173 | H13: =H40*H$7 -> 93.22152 | I13: =I40*I$7 -> 98.205408 | J13: =J40*J$7 -> 103.50336 | K13: =K40*K$7 -> 107.52334 | L13: =L40*L$7 -> 111.76268 | M13: =M40*M$7 -> 117.59005 | N13: =N40*N$7 -> 119.4728 | O13: =O40*O$7 -> 121.7057 | ... Q13: =Q40*Q$7 -> 126.96561
B14: Depreciation/Amortization | C14: 10.2 | D14: 18.6 | E14: 31.7 | F14: 35.7 | G14: 33.2 | H14: =H41*H$7 -> 34.439807 | I14: =I41*I$7 -> 37.036913 | J14: =J41*J$7 -> 39.865499 | K14: =K41*K$7 -> 42.545365 | L14: =L41*L$7 -> 45.211029 | M14: =M41*M$7 -> 47.835595 | N14: =N41*N$7 -> 49.718772 | O14: =O41*O$7 -> 51.536559 | ... Q14: =Q41*Q$7 -> 54.723947
B16: Unusual Expense (Income) | C16: 1.4 | D16: 0.4 | E16: -7.2 | F16: -1.7 | G16: 25.1 | H16: =H$7*(H42) -> 3.8900514 | I16: =I$7*(I42) -> 3.5804055 | J16: =J$7*(J42) -> 3.8538485 | K16: =K$7*(K42) -> 3.5253554 | L16: =L$7*(L42) -> 2.4974901 | M16: =M$7*(M42) -> 1.3212365 | N16: =N$7*(N42) -> 0 | O16: =O$7*(O42) -> 0 | ... Q16: =Q$7*(Q42) -> 0
B18: Total Operating Expense | C18: 249.5 | D18: 343.8 | E18: 437.5 | F18: 496.8 | G18: 497.5 | H18: =SUM(H12:H14)+H10 -> 486.17317 | I18: =SUM(I12:I14)+I10 -> 500.89248 | J18: =SUM(J12:J14)+J10 -> 527.43762 | K18: =SUM(K12:K14)+K10 -> 545.80774 | L18: =SUM(L12:L14)+L10 -> 569.17995 | M18: =SUM(M12:M14)+M10 -> 596.14875 | N18: =SUM(N12:N14)+N10 -> 612.06488 | O18: =SUM(O12:O14)+O10 -> 629.46071 | ... Q18: =SUM(Q12:Q14)+Q10 -> 655.54333
B19: Operating Income | C19: =C7-C18 -> -48.618 | D19: =D7-D18 -> -72.659 | E19: =E7-E18 -> -69.067 | F19: =F7-F18 -> -64.908 | G19: =G7-G18 -> -48.712 | H19: =H7-H18 -> -10.553171 | I19: =I7-I18 -> 10.594021 | J19: =J7-J18 -> 23.11216 | ... Q19: =Q7-Q18 -> 100.20432
B20: Operating Margin | C20: =C19/C7 -> -0.24202268 | D20: =D19/D7 -> -0.26797497 | E20: =E19/E7 -> -0.18746149 | F20: =F19/F7 -> -0.15028757 | G20: =G19/G7 -> -0.10854123 | H20: =H19/H7 -> -0.02218824 | I20: =I19/I7 -> 0.020712221 | J20: =J19/J7 -> 0.041980146 | ... Q20: =Q19/Q7 -> 0.13258966
B21: EBITDA | C21: =C19+C14 -> -38.418 | D21: =D19+D14 -> -54.059 | E21: =E19+E14 -> -37.367 | F21: =F19+F14 -> -29.208 | G21: =G19+G14 -> -15.512 | H21: =H19+H14 -> 23.886637 | I21: =I19+I14 -> 47.630934 | J21: =J19+J14 -> 62.977659 | ... Q21: =Q19+Q14 -> 154.92827
B22: EBITDA Margin | C22: =C21/C7 -> -0.1912466 | D22: =D21/D7 -> -0.19937597 | E22: =E21/E7 -> -0.10142143 | F22: =F21/F7 -> -0.067628018 | G22: =G21/G7 -> -0.034564204 | H22: =H21/H7 -> 0.050222103 | I22: =I21/I7 -> 0.093122564 | J22: =J21/J7 -> 0.11439049 | ... Q22: =Q21/Q7 -> 0.205
B24: Beginning NOL | C24: 165 | D24: =C27 -> 213.618 | E24: =D27 -> 286.277 | F24: =E27 -> 355.344 | G24: =F27 -> 420.252 | H24: =G27 -> 468.964 | I24: =H27 -> 479.51717 | J24: =I27 -> 468.92315 | K24: =J27 -> 445.81099 | ... Q24: =P27 -> 36.554798
B25: Current-Year Tax Loss Generated | C25: =MAX(0,-C19) -> 48.618 | D25: =MAX(0,-D19) -> 72.659 | E25: =MAX(0,-E19) -> 69.067 | F25: =MAX(0,-F19) -> 64.908 | G25: =MAX(0,-G19) -> 48.712 | H25: =MAX(0,-H19) -> 10.553171 | I25: =MAX(0,-I19) -> 0 | J25: =MAX(0,-J19) -> 0 | ... Q25: =MAX(0,-Q19) -> 0
B26: NOL Used | C26: =MIN(C24,MAX(0,C19)) -> 0 | D26: =MIN(D24,MAX(0,D19)) -> 0 | E26: =MIN(E24,MAX(0,E19)) -> 0 | F26: =MIN(F24,MAX(0,F19)) -> 0 | G26: =MIN(G24,MAX(0,G19)) -> 0 | H26: =MIN(H24,MAX(0,H19)) -> 0 | I26: =MIN(I24,MAX(0,I19)) -> 10.594021 | J26: =MIN(J24,MAX(0,J19)) -> 23.11216 | ... Q26: =MIN(Q24,MAX(0,Q19)) -> 36.554798
B27: Ending NOL Balance | C27: =C24+C25-C26 -> 213.618 | D27: =D24+D25-D26 -> 286.277 | E27: =E24+E25-E26 -> 355.344 | F27: =F24+F25-F26 -> 420.252 | G27: =G24+G25-G26 -> 468.964 | H27: =H24+H25-H26 -> 479.51717 | I27: =I24+I25-I26 -> 468.92315 | J27: =J24+J25-J26 -> 445.81099 | ... Q27: =Q24+Q25-Q26 -> 0
B28: Taxable Income | C28: =MAX(0,C19-C26) -> 0 | D28: =MAX(0,D19-D26) -> 0 | E28: =MAX(0,E19-E26) -> 0 | F28: =MAX(0,F19-F26) -> 0 | G28: =MAX(0,G19-G26) -> 0 | H28: =MAX(0,H19-H26) -> 0 | I28: =MAX(0,I19-I26) -> 0 | J28: =MAX(0,J19-J26) -> 0 | ... Q28: =MAX(0,Q19-Q26) -> 63.649523
B29: Cash Taxes | C29: =C28*C48 -> 0 | D29: =D28*D48 -> 0 | E29: =E28*E48 -> 0 | F29: =F28*F48 -> 0 | G29: =G28*G48 -> 0 | H29: =H28*H48 -> 0 | I29: =I28*I48 -> 0 | J29: =J28*J48 -> 0 | ... Q29: =Q28*Q48 -> 13.3664
B33: Key Model Drivers
B35: Revenue Drivers | C35: see revenue forecast build
B38: Cost of revenue (% Revenue) | C38: =C10/C7 -> 0.3162802 | D38: =D10/D7 -> 0.30621706 | E38: =E10/E7 -> 0.3100048 | F38: =F10/F7 -> 0.31021876 | G38: =G10/G7 -> 0.29116866 | H38: =AVERAGE(C38:G38) -> 0.3067779 | I38: =AVERAGE(D38:H38) -> 0.30487744 | J38: =AVERAGE(E38:I38) -> 0.30460951 | K38: =AVERAGE(F38:J38) -> 0.30353045 | L38: =AVERAGE(G38:K38) -> 0.30219279 | M38: 0.301 | N38: 0.299 | O38: 0.299 | P38: 0.297 | Q38: 0.296
B39: SG&A (% of Revenue) | C39: =C12/C$7 -> 0.62133989 | D39: =D12/D$7 -> 0.66319 | E39: =E12/E$7 -> 0.59133954 | F39: =F12/F$7 -> 0.54364054 | G39: =G12/G$7 -> 0.48439352 | H39: 0.447 | I39: 0.41 | J39: 0.393 | K39: 0.37 | L39: 0.358 | M39: 0.351 | N39: 0.346 | O39: 0.342 | P39: 0.338 | Q39: 0.331
B40: R&D (% of Revenue) | C40: =C13/C$7 -> 0.24652283 | D40: =D13/D$7 -> 0.22834983 | E40: =E13/E$7 -> 0.21967902 | F40: =F13/F$7 -> 0.2177373 | G40: =G13/G$7 -> 0.20315383 | H40: 0.196 | I40: 0.192 | J40: 0.188 | K40: 0.183 | L40: 0.179 | M40: 0.178 | N40: 0.174 | O40: 0.171 | P40: 0.169 | Q40: 0.168
B41: D&A (% of Revenue) | C41: =C14/C$7 -> 0.050776077 | D41: =D14/D$7 -> 0.068598995 | E41: =E14/E$7 -> 0.086040067 | F41: =F14/F$7 -> 0.082659554 | G41: =G14/G$7 -> 0.073977023 | H41: =AVERAGE($C$41:$G$41) -> 0.072410343 | I41: =AVERAGE($C$41:$G$41) -> 0.072410343 | J41: =AVERAGE($C$41:$G$41) -> 0.072410343 | K41: =AVERAGE($C$41:$G$41) -> 0.072410343 | L41: =AVERAGE($C$41:$G$41) -> 0.072410343 | M41: =AVERAGE($C$41:$G$41) -> 0.072410343 | N41: =AVERAGE($C$41:$G$41) -> 0.072410343 | O41: =AVERAGE($C$41:$G$41) -> 0.072410343 | ... Q41: =AVERAGE($C$41:$G$41) -> 0.072410343
B42: Unusual Expense (% of Revenue) | C42: =C16/C$7 -> 0.0069692655 | D42: =D16/D$7 -> 0.0014752472 | E42: =E16/E$7 -> -0.019542223 | F42: =F16/F$7 -> -0.0039361692 | G42: =G16/G$7 -> 0.055928412 | H42: =AVERAGE($C$42:$G$42) -> 0.0081789063 | I42: 0.007 | J42: 0.007 | K42: 0.006 | L42: 0.004 | M42: 0.002 | N42: 0 | O42: 0 | P42: 0 | Q42: 0
B44: Cash Flow Drivers
B45: CapEx(% of revenue) | C45: 0.0651527 | D45: 0.1108169 | E45: 0.0536108 | F45: 0.0428973 | G45: 0.0484795 | H45: 0.0484795 | I45: 0.0484795 | J45: 0.047 | K45: 0.047 | L45: 0.046 | M45: 0.046 | N45: 0.046 | O45: 0.045 | P45: 0.044 | Q45: 0.044
B46: NWC (% of revenue) | C46: -0.0282305 | D46: -0.0253263 | E46: -0.0121976 | F46: -0.060999 | G46: 0.00723059 | H46: =AVERAGE($C$46:$G$46) -> -0.023904562 | I46: =AVERAGE($C$46:$G$46) -> -0.023904562 | J46: =AVERAGE($C$46:$G$46) -> -0.023904562 | K46: =AVERAGE($C$46:$G$46) -> -0.023904562 | L46: =AVERAGE($C$46:$G$46) -> -0.023904562 | M46: =AVERAGE($C$46:$G$46) -> -0.023904562 | N46: =AVERAGE($C$46:$G$46) -> -0.023904562 | O46: =AVERAGE($C$46:$G$46) -> -0.023904562 | ... Q46: =AVERAGE($C$46:$G$46) -> -0.023904562
B48: Tax Rate | C48: 0.21 | D48: =C48 -> 0.21 | E48: =D48 -> 0.21 | F48: =E48 -> 0.21 | G48: =F48 -> 0.21 | H48: =G48 -> 0.21 | I48: =H48 -> 0.21 | J48: =I48 -> 0.21 | K48: =J48 -> 0.21 | ... Q48: =P48 -> 0.21

Sheet Revenue Build
B1: Revenue Build
C2: Actual | H2: Forecast
B3: FYE December | C3: 43830 | D3: 44196 | E3: 44561 | F3: 44926 | G3: 45291 | H3: =G3+366 -> 45657 | I3: =H3+365 -> 46022 | J3: =I3+365 -> 46387 | K3: =J3+365 -> 46752 | L3: =K3+366 -> 47118 | M3: =L3+365 -> 47483 | N3: =M3+365 -> 47848 | O3: =N3+365 -> 48213 | P3: =O3+366 -> 48579 | Q3: =P3+365 -> 48944
B4: Currency | C4: USD | D4: USD | E4: USD | F4: USD | G4: USD | H4: USD | I4: USD | J4: USD | K4: USD | L4: USD | M4: USD | N4: USD | O4: USD | P4: USD | Q4: USD
B5: Scale | C5: Million | D5: Million | E5: Million | F5: Million | G5: Million | H5: Million | I5: Million | J5: Million | K5: Million | L5: Million | M5: Million | N5: Million | O5: Million | P5: Million | Q5: Million
B6: Subscription Services Revenue | C6: 180.8 | D6: 241.3 | E6: 327.9 | F6: 384.6 | G6: 410.5 | H6: =G6*(1+H7) -> 439.235 | I6: =H6*(1+I7) -> 474.3738 | J6: =I6*(1+J7) -> 512.3237 | K6: =J6*(1+K7) -> 548.18636 | L6: =K6*(1+L7) -> 583.81848 | M6: =L6*(1+M7) -> 618.84759 | N6: =M6*(1+N7) -> 643.60149 | O6: =N6*(1+O7) -> 667.41474 | ... Q6: =P6*(1+Q7) -> 708.73439
B7: Year-over-year growth(%) | D7: =D6/C6 - 1 -> 0.33462389 | E7: =E6/D6 - 1 -> 0.35888935 | F7: =F6/E6 - 1 -> 0.17291857 | G7: =G6/F6 - 1 -> 0.067342694 | H7: 0.07 | I7: 0.08 | J7: 0.08 | K7: 0.07 | L7: 0.065 | M7: 0.06 | N7: 0.04 | O7: 0.037 | P7: 0.035 | Q7: 0.026
B8: Professional Services, Software Licenses & Other | C8: 20.1 | D8: 29.8 | E8: 40.5 | F8: 47.3 | G8: 38.3 | H8: =G8*(1+H9) -> 36.385 | I8: =H8*(1+I9) -> 37.1127 | J8: =I8*(1+J9) -> 38.226081 | K8: =J8*(1+K9) -> 39.372863 | L8: =K8*(1+L9) -> 40.554049 | M8: =L8*(1+M9) -> 41.770671 | N8: =M8*(1+N9) -> 43.023791 | O8: =N8*(1+O9) -> 44.314505 | ... Q8: =P8*(1+Q9) -> 47.013258
B9: Year-over-year growth(%) | D9: =D8/C8 - 1 -> 0.48258706 | E9: =E8/D8 - 1 -> 0.3590604 | F9: =F8/E8 - 1 -> 0.16790123 | G9: =G8/F8 - 1 -> -0.19027484 | H9: -0.05 | I9: 0.02 | J9: 0.03 | K9: 0.03 | L9: 0.03 | M9: 0.03 | N9: 0.03 | O9: 0.03 | P9: 0.03 | Q9: 0.03
B10: Total Revenue | C10: =C8+C6 -> 200.9 | D10: =D8+D6 -> 271.1 | E10: =E8+E6 -> 368.4 | F10: =F8+F6 -> 431.9 | G10: =G8+G6 -> 448.8 | H10: =H8+H6 -> 475.62 | I10: =I8+I6 -> 511.4865 | J10: =J8+J6 -> 550.54979 | ... Q10: =Q8+Q6 -> 755.74765
B11: Year-over-year Growth | D11: =D10/C10 - 1 -> 0.34942758 | E11: =E10/D10 - 1 -> 0.35890815 | F11: =F10/E10 - 1 -> 0.17236699 | G11: =G10/F10 - 1 -> 0.039129428 | H11: =H10/G10 - 1 -> 0.059759358 | I11: =I10/H10 - 1 -> 0.075409991 | J11: =J10/I10 - 1 -> 0.076372074 | K11: =K10/J10 - 1 -> 0.067222698 | ... Q11: =Q10/P10 - 1 -> 0.026247924

Sheet DCF Valuation
B1: Everbridge DCF
B2: ($mm)
B5: Discount Rate | C5: 0.105 | D5: =C5 -> 0.105 | E5: =D5 -> 0.105 | F5: =E5 -> 0.105 | G5: =F5 -> 0.105 | H5: =G5 -> 0.105 | I5: =H5 -> 0.105 | J5: =I5 -> 0.105 | K5: =J5 -> 0.105 | L5: =K5 -> 0.105 | N5: Enterprise Value Calculation
B6: Tax Rate | C6: ='Consolidated Financials'!H48 -> 0.21 | D6: ='Consolidated Financials'!I48 -> 0.21 | E6: ='Consolidated Financials'!J48 -> 0.21 | F6: ='Consolidated Financials'!K48 -> 0.21 | G6: ='Consolidated Financials'!L48 -> 0.21 | H6: ='Consolidated Financials'!M48 -> 0.21 | I6: ='Consolidated Financials'!N48 -> 0.21 | J6: ='Consolidated Financials'!O48 -> 0.21 | ... L6: ='Consolidated Financials'!Q48 -> 0.21 | N6: FCF 2033 | O6: =L21 -> 108.77103
N7: Terminal Growth | O7: 0.026
N8: Discount Rate | O8: =C5 -> 0.105
B9: Currency | C9: USD | D9: USD | E9: USD | F9: USD | G9: USD | H9: USD | I9: USD | J9: USD | K9: USD | L9: USD | N9: Terminal Value @ 2033E | O9: =O6*(1+O7)/(O8-O7) -> 1412.6466
B10: Scale | C10: Million | D10: Million | E10: Million | F10: Million | G10: Million | H10: Million | I10: Million | J10: Million | K10: Million | L10: Million | N10: Discount Period | O10: 10
B11: Revenue | C11: ='Consolidated Financials'!H7 -> 475.62 | D11: ='Consolidated Financials'!I7 -> 511.4865 | E11: ='Consolidated Financials'!J7 -> 550.54979 | F11: ='Consolidated Financials'!K7 -> 587.55923 | G11: ='Consolidated Financials'!L7 -> 624.37253 | H11: ='Consolidated Financials'!M7 -> 660.61826 | I11: ='Consolidated Financials'!N7 -> 686.62528 | J11: ='Consolidated Financials'!O7 -> 711.72925 | ... L11: ='Consolidated Financials'!Q7 -> 755.74765 | N11: Discount Factor | O11: =1/(1+L5)^O10 -> 0.36844886
B12: YoY Growth | C12: ='Consolidated Financials'!H8 -> 0.059787695 | D12: ='Consolidated Financials'!I8 -> 0.075409991 | E12: ='Consolidated Financials'!J8 -> 0.076372074 | F12: ='Consolidated Financials'!K8 -> 0.067222698 | G12: ='Consolidated Financials'!L8 -> 0.062654619 | H12: ='Consolidated Financials'!M8 -> 0.058051449 | I12: ='Consolidated Financials'!N8 -> 0.039367703 | J12: ='Consolidated Financials'!O8 -> 0.036561382 | ... L12: ='Consolidated Financials'!Q8 -> 0.026247924 | N12: Present Value of Terminal Value | O12: =O11*O9 -> 520.48803
B13: EBIT | C13: ='Consolidated Financials'!H19 -> -10.553171 | D13: ='Consolidated Financials'!I19 -> 10.594021 | E13: ='Consolidated Financials'!J19 -> 23.11216 | F13: ='Consolidated Financials'!K19 -> 41.751491 | G13: ='Consolidated Financials'!L19 -> 55.192575 | H13: ='Consolidated Financials'!M19 -> 64.469509 | I13: ='Consolidated Financials'!N19 -> 74.560404 | J13: ='Consolidated Financials'!O19 -> 82.26854 | ... L13: ='Consolidated Financials'!Q19 -> 100.20432 | N13: Warranted Enterprise Value | O13: =O12+SUM(C21:L21) -> 1227.5607
B14: EBIT Margin | C14: =C13/C11 -> -0.02218824 | D14: =D13/D11 -> 0.020712221 | E14: =E13/E11 -> 0.041980146 | F14: =F13/F11 -> 0.071059205 | G14: =G13/G11 -> 0.088396866 | H14: =H13/H11 -> 0.097589657 | I14: =I13/I11 -> 0.10858966 | J14: =J13/J11 -> 0.11558966 | ... L14: =L13/L11 -> 0.13258966
B16: Less; taxes | C16: ='Consolidated Financials'!H29 -> 0 | D16: ='Consolidated Financials'!I29 -> 0 | E16: ='Consolidated Financials'!J29 -> 0 | F16: ='Consolidated Financials'!K29 -> 0 | G16: ='Consolidated Financials'!L29 -> 0 | H16: ='Consolidated Financials'!M29 -> 0 | I16: ='Consolidated Financials'!N29 -> 0 | J16: ='Consolidated Financials'!O29 -> 0 | ... L16: ='Consolidated Financials'!Q29 -> 13.3664 | N16: Enterprise Value to Equity Value
B17: Less; capex | C17: ='Consolidated Financials'!H7*'Consolidated Financials'!H45 -> 23.05782 | D17: ='Consolidated Financials'!I7*'Consolidated Financials'!I45 -> 24.79661 | E17: ='Consolidated Financials'!J7*'Consolidated Financials'!J45 -> 25.87584 | F17: ='Consolidated Financials'!K7*'Consolidated Financials'!K45 -> 27.615284 | G17: ='Consolidated Financials'!L7*'Consolidated Financials'!L45 -> 28.721136 | H17: ='Consolidated Financials'!M7*'Consolidated Financials'!M45 -> 30.38844 | I17: ='Consolidated Financials'!N7*'Consolidated Financials'!N45 -> 31.584763 | J17: ='Consolidated Financials'!O7*'Consolidated Financials'!O45 -> 32.027816 | ... L17: ='Consolidated Financials'!Q7*'Consolidated Financials'!Q45 -> 33.252897 | N17: Warranted Enterprise Value | O17: =O13 -> 1227.5607
N18: Minus Net Debt | O18: 237.2
B19: Plus: D&A | C19: ='Consolidated Financials'!H14 -> 34.439807 | D19: ='Consolidated Financials'!I14 -> 37.036913 | E19: ='Consolidated Financials'!J14 -> 39.865499 | F19: ='Consolidated Financials'!K14 -> 42.545365 | G19: ='Consolidated Financials'!L14 -> 45.211029 | H19: ='Consolidated Financials'!M14 -> 47.835595 | I19: ='Consolidated Financials'!N14 -> 49.718772 | J19: ='Consolidated Financials'!O14 -> 51.536559 | ... L19: ='Consolidated Financials'!Q14 -> 54.723947 | N19: Minus Preffered Equity | O19: 0
B20: Less: changes in net working capital | C20: =C11*'Consolidated Financials'!H46-'Consolidated Financials'!G7*'Consolidated Financials'!G46 -> -14.61449 | D20: =D11*'Consolidated Financials'!I46-C11*'Consolidated Financials'!H46 -> -0.85737297 | E20: =E11*'Consolidated Financials'!J46-D11*'Consolidated Financials'!I46 -> -0.93379072 | F20: =F11*'Consolidated Financials'!K46-E11*'Consolidated Financials'!J46 -> -0.88469449 | G20: =G11*'Consolidated Financials'!L46-F11*'Consolidated Financials'!K46 -> -0.8800058 | H20: =H11*'Consolidated Financials'!M46-G11*'Consolidated Financials'!L46 -> -0.8664383 | I20: =I11*'Consolidated Financials'!N46-H11*'Consolidated Financials'!M46 -> -0.62168651 | J20: =J11*'Consolidated Financials'!O46-I11*'Consolidated Financials'!N46 -> -0.60009938 | K20: =K11*'Consolidated Financials'!P46-J11*'Consolidated Financials'!O46 -> -0.59017856 | L20: =L11*'Consolidated Financials'!Q46-K11*'Consolidated Financials'!P46 -> -0.46206201 | N20: Equity Value | O20: =O17-O18 -> 990.36074
B21: Unlevered Free Cash Flow | C21: =C13-C16-C17+C19-C20 -> 15.443307 | D21: =D13-D16-D17+D19-D20 -> 23.691698 | E21: =E13-E16-E17+E19-E20 -> 38.03561 | F21: =F13-F16-F17+F19-F20 -> 57.566267 | G21: =G13-G16-G17+G19-G20 -> 72.562473 | H21: =H13-H16-H17+H19-H20 -> 82.783102 | I21: =I13-I16-I17+I19-I20 -> 93.316099 | J21: =J13-J16-J17+J19-J20 -> 102.37738 | ... L21: =L13-L16-L17+L19-L20 -> 108.77103 | N21: Diluted Shares | O21: 41
N22: Implied Share Price | O22: =O20/O21 -> 24.15514
B23: Discount Period | C23: 1 | D23: =C23+1 -> 2 | E23: =D23+1 -> 3 | F23: =E23+1 -> 4 | G23: =F23+1 -> 5 | H23: =G23+1 -> 6 | I23: =H23+1 -> 7 | J23: =I23+1 -> 8 | K23: =J23+1 -> 9 | L23: =K23+1 -> 10
B24: PV of Free Cash Flow | C24: =C21/(1+C5)^C23 -> 13.975843 | D24: =D21/(1+D5)^D23 -> 19.403122 | E24: =E21/(1+E5)^E23 -> 28.19055 | F24: =F21/(1+F5)^F23 -> 38.611703 | G24: =G21/(1+G5)^G23 -> 44.045413 | H24: =H21/(1+H5)^H23 -> 45.47451 | I24: =I21/(1+I5)^I23 -> 46.3896 | J24: =J21/(1+J5)^J23 -> 46.058076 | ... L24: =L21/(1+L5)^L23 -> 40.076564

Sheet LBO Assumptions
B2: Everbridge LBO Assumptions
B3: ($MM)
B5: Assumptions
B6: Offer Price / Share | C6: 35 | D6: Final offer price
B7: Diluted Shares Outstanding | C7: 41 | D7: Approx. diluted shares
B8: Existing Debt | C8: 359.7 | D8: 2023 current + long-term debt
B9: Cash Available | C9: 122.4 | D9: 2023 cash & equivalents
B10: Transaction Fees (% EV) | C10: 0.02 | D10: Base assumption
B11: Financing Fees (% New Debt) | C11: 0.02 | D11: Base assumption
B12: Entry EBITDA (Normalized) | C12: ='Consolidated Financials'!I21 -> 47.630934 | D12: 2025ebitda
B13: Entry Debt / EBITDA | C13: 6 | D13: Base leverage assumption
B14: Hold Period (Years) | C14: 5 | D14: Base hold period
B16: Operating & Financing Assumptions
B17: Metric | C17: 2025E | D17: 2026E | E17: 2027E | F17: 2028E | G17: 2029E | H17: Linked from Consolidated Financials
B18: Revenue | C18: ='Consolidated Financials'!I7 -> 511.4865 | D18: ='Consolidated Financials'!J7 -> 550.54979 | E18: ='Consolidated Financials'!K7 -> 587.55923 | F18: ='Consolidated Financials'!L7 -> 624.37253 | G18: ='Consolidated Financials'!M7 -> 660.61826
B19: EBITDA | C19: ='Consolidated Financials'!I21 -> 47.630934 | D19: ='Consolidated Financials'!J21 -> 62.977659 | E19: ='Consolidated Financials'!K21 -> 84.296857 | F19: ='Consolidated Financials'!L21 -> 100.4036 | G19: ='Consolidated Financials'!M21 -> 112.3051
B20: EBITDA Margin | C20: ='Consolidated Financials'!I22 -> 0.093122564 | D20: ='Consolidated Financials'!J22 -> 0.11439049 | E20: ='Consolidated Financials'!K22 -> 0.14346955 | F20: ='Consolidated Financials'!L22 -> 0.16080721 | G20: ='Consolidated Financials'!M22 -> 0.17
B21: D&A | C21: ='Consolidated Financials'!H14 -> 34.439807 | D21: ='Consolidated Financials'!I14 -> 37.036913 | E21: ='Consolidated Financials'!J14 -> 39.865499 | F21: ='Consolidated Financials'!K14 -> 42.545365 | G21: ='Consolidated Financials'!L14 -> 45.211029
B22: CapEx (% Revenue) | C22: ='Consolidated Financials'!I45*C18 -> 24.79661 | D22: ='Consolidated Financials'!J45*D18 -> 25.87584 | E22: ='Consolidated Financials'!K45*E18 -> 27.615284 | F22: ='Consolidated Financials'!L45*F18 -> 28.721136 | G22: ='Consolidated Financials'!M45*G18 -> 30.38844
B23: Change in NWC | C23: ='DCF Valuation'!D20 -> -0.85737297 | D23: ='DCF Valuation'!E20 -> -0.93379072 | E23: ='DCF Valuation'!F20 -> -0.88469449 | F23: ='DCF Valuation'!G20 -> -0.8800058 | G23: ='DCF Valuation'!H20 -> -0.8664383
B24: Cash Tax Rate | C24: - | D24: - | E24: - | F24: - | G24: -
B25: Interest Rate | C25: 0.09 | D25: 0.09 | E25: 0.09 | F25: 0.09 | G25: 0.09
B27: Mandatory Amortization (% Initial Debt) | C27: 0.01
B28: Cash Sweep | C28: 1
B29: Exit EBITDA Multiple | C29: 12
B30: Exit Fees (% Exit EV) | C30: 0.01

Sheet LBO Model
B1: Everbridge LBO Model | J1: 6 | K1: IRR Sensitivity
B2: ($MM) | J2: 12 | K2: Exit Multiple / Entry Leverage | L2: 4 | M2: =L2+1 -> 5 | N2: =M2+1 -> 6 | O2: =N2+1 -> 7 | P2: =O2+1 -> 8
K3: 10 | L3: -0.071956958 | M3: -0.078979946 | N3: -0.085456748 | O3: -0.092542704 | P3: -0.10033396
K4: =K3+1 -> 11 | L4: -0.054398387 | M4: -0.060397415 | N4: -0.06581779 | O4: -0.071715857 | P4: -0.078160933
B5: Sources& Uses | E5: Sources | H5: Uses | K5: =K4+1 -> 12 | L5: -0.038054713 | M5: -0.04317829 | N5: -0.047703616 | O5: -0.052605979 | P5: -0.057936332
K6: =K5+1 -> 13 | L6: -0.022751746 | M6: -0.02711626 | N6: -0.030871233 | O6: -0.03492409 | P6: -0.039312708
B7: Equity Value | C7: ='LBO Assumptions'!C6*'LBO Assumptions'!C7 -> 1435 | E7: New Debt | F7: ='LBO Assumptions'!C12*'LBO Assumptions'!C13 -> 285.78561 | H7: Purchase EV | I7: =C8 -> 1794.7 | K7: =K6+1 -> 14 | L7: -0.0083512996 | M7: -0.012049836 | N7: -0.015133023 | O7: -0.01845045 | P7: -0.022030376
B8: Enterprise Value | C8: =C7+'LBO Assumptions'!C8 -> 1794.7 | E8: Sponsor Equity | H8: Transaction Fees | I8: =I7*'LBO Assumptions'!C10 -> 35.894 | K8: =K7+1 -> 15 | L8: 0.005258218 | M8: 0.0021499182 | N8: -0.00034089511 | O8: -0.0030138062 | P8: -0.0058897993
B9: Entry EBITDA | C9: ='LBO Assumptions'!C12 -> 47.630934 | H9: Financing Fees | I9: =F7*'LBO Assumptions'!C11 -> 5.7157121 | K9: =K8+1 -> 16 | L9: 0.018168307 | M9: 0.015587695 | N9: 0.013624228 | O9: 0.011522075 | P9: 0.0092658849
B10: EV as Multiple of EBITDA | C10: =C8/C9 -> 37.679294
E11: Sponsor Equity | F11: =I11-F7 -> 1550.5241 | H11: Total Uses | I11: =SUM(I7:I9) -> 1836.3097
C15: Forecast
C16: 46022 | D16: =C16+365 -> 46387 | E16: =D16+365 -> 46752 | F16: =E16+366 -> 47118 | G16: =F16+365 -> 47483
B18: Revenue | C18: ='LBO Assumptions'!C18 -> 511.4865 | D18: ='LBO Assumptions'!D18 -> 550.54979 | E18: ='LBO Assumptions'!E18 -> 587.55923 | F18: ='LBO Assumptions'!F18 -> 624.37253 | G18: ='LBO Assumptions'!G18 -> 660.61826
B19: EBITDA | C19: ='LBO Assumptions'!C19 -> 47.630934 | D19: ='LBO Assumptions'!D19 -> 62.977659 | E19: ='LBO Assumptions'!E19 -> 84.296857 | F19: ='LBO Assumptions'!F19 -> 100.4036 | G19: ='LBO Assumptions'!G19 -> 112.3051
B20: EBITDA Margin | C20: ='LBO Assumptions'!C20 -> 0.093122564 | D20: ='LBO Assumptions'!D20 -> 0.11439049 | E20: ='LBO Assumptions'!E20 -> 0.14346955 | F20: ='LBO Assumptions'!F20 -> 0.16080721 | G20: ='LBO Assumptions'!G20 -> 0.17
B21: D&A | C21: ='LBO Assumptions'!C21 -> 34.439807 | D21: ='LBO Assumptions'!D21 -> 37.036913 | E21: ='LBO Assumptions'!E21 -> 39.865499 | F21: ='LBO Assumptions'!F21 -> 42.545365 | G21: ='LBO Assumptions'!G21 -> 45.211029
B22: CapEx | C22: ='LBO Assumptions'!C22 -> 24.79661 | D22: ='LBO Assumptions'!D22 -> 25.87584 | E22: ='LBO Assumptions'!E22 -> 27.615284 | F22: ='LBO Assumptions'!F22 -> 28.721136 | G22: ='LBO Assumptions'!G22 -> 30.38844
B23: Change in NWC | C23: ='LBO Assumptions'!C23 -> -0.85737297 | D23: ='LBO Assumptions'!D23 -> -0.93379072 | E23: ='LBO Assumptions'!E23 -> -0.88469449 | F23: ='LBO Assumptions'!F23 -> -0.8800058 | G23: ='LBO Assumptions'!G23 -> -0.8664383
B24: Cash Tax Rate | C24: ='LBO Assumptions'!C24 -> - | D24: ='LBO Assumptions'!D24 -> - | E24: ='LBO Assumptions'!E24 -> - | F24: ='LBO Assumptions'!F24 -> - | G24: ='LBO Assumptions'!G24 -> -
B25: Interest Rate | C25: ='LBO Assumptions'!C25 -> 0.09 | D25: ='LBO Assumptions'!D25 -> 0.09 | E25: ='LBO Assumptions'!E25 -> 0.09 | F25: ='LBO Assumptions'!F25 -> 0.09 | G25: ='LBO Assumptions'!G25 -> 0.09
B26: Cash Interest | C26: =C29*C25 -> 25.720705 | D26: =D29*D25 -> 25.463498 | E26: =E29*E25 -> 24.332007 | F26: =F29*F25 -> 21.340924 | G26: =G29*G25 -> 16.730985
B27: Levered Free Cash Flow | C27: =(C18*C20)-C26-C22-C23 -> -2.029007 | D27: =(D18*D20)-D26-D22-D23 -> 12.572112 | E27: =(E18*E20)-E26-E22-E23 -> 33.23426 | F27: =(F18*F20)-F26-F22-F23 -> 51.221549 | G27: =(G18*G20)-G26-G22-G23 -> 66.052117
B29: Beginning Debt | C29: =F7 -> 285.78561 | D29: =C32 -> 282.92775 | E29: =D32 -> 270.35564 | F29: =E32 -> 237.12138 | G29: =F32 -> 185.89983
B30: Mandatory Amoritization | C30: =$F$7*'LBO Assumptions'!$C$27 -> 2.8578561 | D30: =$F$7*'LBO Assumptions'!$C$27 -> 2.8578561 | E30: =$F$7*'LBO Assumptions'!$C$27 -> 2.8578561 | F30: =$F$7*'LBO Assumptions'!$C$27 -> 2.8578561 | G30: =$F$7*'LBO Assumptions'!$C$27 -> 2.8578561
B31: cash sweep paydown | C31: =MAX(C27-C30,0) -> 0 | D31: =MAX(D27-D30,0) -> 9.7142564 | E31: =MAX(E27-E30,0) -> 30.376404 | F31: =MAX(F27-F30,0) -> 48.363693 | G31: =MAX(G27-G30,0) -> 63.194261
B32: Ending Debt | C32: =C29-C30-C31 -> 282.92775 | D32: =D29-D30-D31 -> 270.35564 | E32: =E29-E30-E31 -> 237.12138 | F32: =F29-F30-F31 -> 185.89983 | G32: =G29-G30-G31 -> 119.84771
B34: Exit Enterprise value | C34: =G19*'LBO Assumptions'!C29 -> 1347.6612
B35: Exit Equity Value | C35: =C34-G32-('LBO Assumptions'!C30*C34) -> 1214.3369
B37: IRR | C37: =(C35/F11)^(1/5)-1 -> -0.047703616
B38: MOIC | C38: =C35/F11 -> 0.78317836

Sheet raw financials
A1: Everbridge Inc (29978A10)
A2: Income Statement - Annual (As Originally Reported)
B3: 5 | C3: 4 | D3: 3 | E3: 2 | F3: 1
A4: FYE December | B4: 43830 | C4: 44196 | D4: 44561 | E4: 44926 | F4: 45291
A5: Currency | B5: USD | C5: USD | D5: USD | E5: USD | F5: USD
A6: Scale | B6: Million | C6: Million | D6: Million | E6: Million | F6: Million
A7: Total Revenue | B7: 200.882 | C7: 271.141 | D7: 368.433 | E7: 431.892 | F7: 448.788
A8: Cost of Revenue, Total | B8: 63.535 | C8: 83.028 | D8: 114.216 | E8: 133.981 | F8: 130.673
A9: Gross Profit | B9: 137.347 | C9: 188.113 | D9: 254.217 | E9: 297.911 | F9: 318.115
A10: Selling/General/Admin. Expenses, Total | B10: 124.816 | C10: 179.818 | D10: 217.869 | E10: 234.794 | F10: 217.39
A11: Research & Development | B11: 49.522 | C11: 61.915 | D11: 80.937 | E11: 94.039 | F11: 91.173
A12: Depreciation/Amortization | B12: 10.2 | C12: 18.6 | D12: 31.7 | E12: 35.7 | F12: 33.2
A13: Interest Exp.(Inc.), Net-Operating, Total
A14: Unusual Expense (Income) | B14: 1.4 | C14: 0.4 | D14: -7.2 | E14: -1.7 | F14: 25.1
A15: Other Operating Expenses, Total
A16: Total Operating Expense | B16: 249.5 | C16: 343.8 | D16: 437.5 | E16: 496.8 | F16: 497.5
A17: Operating Income | B17: -48.634 | C17: -72.66 | D17: -69.068 | E17: -64.941 | F17: -48.723
A18: Interest Inc.(Exp.),Net-Non-Op., Total | B18: -3 | C18: -22.1 | D18: -35.6 | E18: 0.6 | F18: 4.3
A19: Gain (Loss) on Sale of Assets | F19: 0.3
A20: Other, Net | B20: -0.2 | C20: -0.9 | D20: -2.7 | E20: 0.8 | F20: 0.5
A21: Net Income Before Taxes | B21: -51.825 | C21: -95.663 | D21: -107.375 | E21: -63.572 | F21: -43.597
A22: Provision for Income Taxes | B22: 0.425 | C22: -2.267 | D22: -12.579 | E22: -2.398 | F22: 3.708
A23: Net Income | B23: -52.25 | C23: -93.396 | D23: -94.796 | E23: -61.174 | F23: -47.305
A24: Preferred Dividends
A25: Basic EPS Excluding Extraordinary Items | B25: -1.58 | C25: -2.7 | D25: -2.5 | E25: -1.54 | F25: -1.16
A26: Basic EPS Including Extraordinary Items | B26: -1.58 | C26: -2.7 | D26: -2.5 | E26: -1.54 | F26: -1.16
A27: Normalized Basic EPS | B27: -1.55 | C27: -2.69 | D27: -2.62 | E27: -1.56 | F27: -0.77
A28: Basic Weighted Average Shares | B28: 33 | C28: 35 | D28: 38 | E28: 40 | F28: 41
A29: Diluted EPS Excluding ExtraOrd Items | B29: -1.58 | C29: -2.7 | D29: -2.5 | E29: -1.54 | F29: -1.16
A30: Diluted EPS Including ExtraOrd Items | B30: -1.58 | C30: -2.7 | D30: -2.5 | E30: -1.54 | F30: -1.16
A31: Normalized Diluted EPS | B31: -1.55 | C31: -2.69 | D31: -2.62 | E31: -1.56 | F31: -0.77
A32: Diluted Weighted Average Shares | B32: 33 | C32: 35 | D32: 38 | E32: 40 | F32: 41
A33: Dividends Per Share
A34: Number of Employees | B34: 948 | C34: 1344 | D34: 1952 | E34: 1713 | F34: 1593
A37: Everbridge Inc (29978A10)
A38: Balance Sheet - Annual (As Originally Reported)
A39: FYE December | B39: 43830 | C39: 44196 | D39: 44561 | E39: 44926 | F39: 45291
A40: Currency | B40: USD | C40: USD | D40: USD | E40: USD | F40: USD
A41: Scale | B41: Million | C41: Million | D41: Million | E41: Million | F41: Million
A42: Cash & Equivalents | B42: 531.575 | C42: 467.171 | D42: 488.035 | E42: 198.725 | F42: 122.44
...
