Workbook
Name _90346E10___AllReports: 'SLCA Raw'!$A$1:$G$166

Sheet Table of Contents
B2: TABLE OF CONTENTS
B4: =HYPERLINK("#'Main Page & Assumptions'!A1", "Main Page & Assumptions") -> Main Page & Assumptions
B5: =HYPERLINK("#'Summary'!A1", "Summary") -> Summary
B7: DCFs
B8: =HYPERLINK("#'Carveout DCFs'!A1", "Carveout DCFs") -> Carveout DCFs
B9: =HYPERLINK("#'Standalone DCFs'!A1", "Standalone DCFs") -> Standalone DCFs
B11: Supporting
B12: =HYPERLINK('Revenue Build'!A1,"Revenue Build") -> Revenue Build
B13: =HYPERLINK('ISP Carve Out Costs'!A1,"ISP Carve Out Costs") -> ISP Carve Out Costs
B14: =HYPERLINK('SLCA Financials (memo)'!A2,"SLCA Financials") -> SLCA Financials
B15: =HYPERLINK('Individual Cash Flow'!A1,"Individual Cash Flow") -> Individual Cash Flow
B16: =HYPERLINK('Public Comps'!A1,"Public Comps") -> Public Comps
B17: =HYPERLINK('Site By Site Assignments'!A1, "Site By Site Assignments") -> Site By Site Assignments

Sheet Main Page & Assumptions
A1: =HYPERLINK("#'Table of Contents'!A1","<--------") -> <--------
B2: Transaction Assumptions
B4: Transaction Toggle
B5: Scenario Toggle | D5: 2
B8: Operating Assumptions | E8: 1 | J8: 2 | O8: 3
E9: Downside | J9: Base | O9: Upside
E10: 2024 | F10: =E10+1 -> 2025 | G10: =F10+1 -> 2026 | H10: =G10+1 -> 2027 | I10: =H10+1 -> 2028 | J10: 2024 | K10: =J10+1 -> 2025 | L10: =K10+1 -> 2026 | M10: =L10+1 -> 2027 | N10: =M10+1 -> 2028 | O10: 2024 | P10: =O10+1 -> 2025 | Q10: =P10+1 -> 2026 | R10: =Q10+1 -> 2027 | S10: =R10+1 -> 2028
B11: OG Selling Price Growth | E11: -0.02 | F11: 0 | G11: 0.005 | H11: 0.007 | I11: 0.01 | J11: 0.01 | K11: 0.01 | L11: 0.01 | M11: 0.013 | N11: 0.015 | O11: 0.025 | P11: 0.025 | Q11: 0.03 | R11: 0.03 | S11: 0.03
B12: OG Sales Volume Gorwth | E12: -0.05 | F12: -0.02 | G12: 0 | H12: 0.01 | I12: 0.01 | J12: 0.02 | K12: 0.02 | L12: =K12 -> 0.02 | M12: =L12 -> 0.02 | N12: =M12 -> 0.02 | O12: 0.06 | P12: 0.05 | Q12: 0.04 | R12: 0.03 | S12: 0.025
B13: OG Segment Cost of Sales | E13: =52.5 -> 52.5 | F13: =E13*1.035 -> 54.3375 | G13: =F13*1.035 -> 56.239312 | H13: =G13*1.035 -> 58.207688 | I13: =H13*1.035 -> 60.244958 | J13: 50.4 | K13: =J13*1.03 -> 51.912 | L13: =K13*1.03 -> 53.46936 | M13: =L13*1.03 -> 55.073441 | N13: =M13*1.03 -> 56.725644 | O13: 49.3 | P13: =O13*1.025 -> 50.5325 | Q13: =P13*1.025 -> 51.795812 | R13: =Q13*1.025 -> 53.090708 | S13: =R13*1.025 -> 54.417976
B14: ISP Selling Price Growth | E14: 0 | F14: 0.01 | G14: 0.015 | H14: 0.015 | I14: 0.015 | J14: 0.02 | K14: 0.02 | L14: 0.02 | M14: 0.02 | N14: 0.02 | O14: 0.035 | P14: 0.035 | Q14: 0.03 | R14: 0.03 | S14: 0.025
B15: ISP Sales Volume Gorwth | E15: -0.02 | F15: 0 | G15: 0.005 | H15: 0.01 | I15: 0.01 | J15: 0.02 | K15: 0.018 | L15: 0.015 | M15: 0.013 | N15: 0.012 | O15: 0.04 | P15: 0.035 | Q15: 0.03 | R15: 0.025 | S15: 0.02
B16: ISP Segment Cost of Sales | E16: 91 | F16: =E16*1.03 -> 93.73 | G16: =F16*1.03 -> 96.5419 | H16: =G16*1.03 -> 99.438157 | I16: =H16*1.03 -> 102.4213 | J16: =86*1.03 -> 88.58 | K16: =J16*1.03 -> 91.2374 | L16: =K16*1.03 -> 93.974522 | M16: =L16*1.03 -> 96.793758 | N16: =M16*1.03 -> 99.69757 | O16: 87 | P16: =O16*1.02 -> 88.74 | Q16: =P16*1.02 -> 90.5148 | R16: =Q16*1.02 -> 92.325096 | S16: =R16*1.02 -> 94.171598
B17: CapEx % Revenue | E17: 0.055 | F17: =$E$17 -> 0.055 | G17: =$E$17 -> 0.055 | H17: =$E$17 -> 0.055 | I17: =$E$17 -> 0.055 | J17: 0.05 | K17: =$J$17 -> 0.05 | L17: =$J$17 -> 0.05 | M17: =$J$17 -> 0.05 | N17: =$J$17 -> 0.05 | O17: 0.045 | P17: =$O$17 -> 0.045 | Q17: =$O$17 -> 0.045 | R17: =$O$17 -> 0.045 | S17: =$O$17 -> 0.045
B18: Tax Rate | E18: 0.265 | F18: =$E$18 -> 0.265 | G18: =$E$18 -> 0.265 | H18: =$E$18 -> 0.265 | I18: =$E$18 -> 0.265 | J18: =$E$18 -> 0.265 | K18: =$E$18 -> 0.265 | L18: =$E$18 -> 0.265 | M18: =$E$18 -> 0.265 | ... S18: =$E$18 -> 0.265
B20: Carveout Assumptions
B21: See ISP Carve Out Costs
B22: Capex Split (O&G) | D22: 0.5
B24: DCF Assumptions
C25: ISP | D25: O&G
B26: WACC | C26: 0.11 | D26: 0.135
D27: Standalone SLCA
B28: WACC | D28: 0.125
B30: Multiple Assumptions
C31: ISP | D31: O&G
B32: Base | C32: 7.7 | D32: 3.3
B33: Low | C33: 7.3 | D33: 3
B34: High | C34: 8.3 | D34: 3.5
B35: Standalone SLCA
B36: Median | D36: 4.5
B37: Low | D37: 4.3
B38: High | D38: 4.8
B40: Transaction Assumptions
B42: Apollo Offer/Share | D42: 15.5
B43: Diluted Shares Outstanding | D43: 79
B44: Net Debt | D44: 622

Sheet Summary
A1: =HYPERLINK("#'Table of Contents'!A1","<--------") -> <--------
B2: Summary
B4: Sum-Of-Parts | C4: O&G | D4: ISP | E4: Total
B5: Equity Value | C5: ='Carveout DCFs'!C19 -> 481.72421 | D5: ='Carveout DCFs'!C39 -> 733.84829 | E5: =C5+D5 -> 1215.5725
B6: SLCA Standalone Shares | E6: ='Standalone DCF'!C35 -> 79
B7: Diluted Share Price | E7: =E5/E6 -> 15.386994
B10: Standalone | E10: Standalone Total
B11: Equity Value | E11: ='Standalone DCF'!C34 -> 1208.755
B12: SLCA Standalone Shares | E12: ='Standalone DCF'!C35 -> 79
B13: Diluted Share Price | E13: =E11/E12 -> 15.300697
B15: Conclusion: | C15: Value-Neutral

Sheet Revenue Build
A1: =HYPERLINK("#'Table of Contents'!A1","<--------") -> <--------
B2: (NOT in $mm ($000))
B3: U.S. Silica
B4: O&G and I&P Sales Build
C5: Actual | I5: Forecast
C6: 43465 | D6: =EDATE(C6,12) -> 43830 | E6: =EDATE(D6,12) -> 44196 | F6: =EDATE(E6,12) -> 44561 | G6: =EDATE(F6,12) -> 44926 | H6: =EDATE(G6,12) -> 45291 | I6: =EDATE(H6,12) -> 45657 | J6: =EDATE(I6,12) -> 46022 | K6: =EDATE(J6,12) -> 46387 | ... M6: =EDATE(L6,12) -> 47118
B7: Total Revenue | C7: ='SLCA Financials (memo)'!D35*1000 -> 1577298 | D7: ='SLCA Financials (memo)'!E35*1000 -> 1474477 | E7: ='SLCA Financials (memo)'!F35*1000 -> 845885 | F7: ='SLCA Financials (memo)'!G35*1000 -> 1103879 | G7: ='SLCA Financials (memo)'!H35*1000 -> 1525147 | H7: ='SLCA Financials (memo)'!I35*1000 -> 1552022 | I7: =I12+I34 -> 1604624.1 | J7: =J12+J34 -> 1657818.9 | K7: =K12+K34 -> 1710958 | L7: =L12+L34 -> 1767864.4 | M7: =M12+M34 -> 1828297.7
B8: YoY Growth | D8: =D7/C7-1 -> -0.065188062 | E8: =E7/D7-1 -> -0.42631523 | F8: =F7/E7-1 -> 0.30499891 | G8: =G7/F7-1 -> 0.38162516 | H8: =H7/G7-1 -> 0.017621252 | I8: =I7/H7-1 -> 0.033892621 | J8: =J7/I7-1 -> 0.03315092 | K8: =K7/J7-1 -> 0.032053624 | ... M8: =M7/L7-1 -> 0.034184327
B10: O&G
B12: Sales ($000) | C12: 1182991 | D12: 1010521 | E12: 414897 | F12: 615448 | G12: 961667 | H12: 994276 | I12: =I13*I14 -> 1024340.1 | J12: =J13*J14 -> 1055275.1 | K12: =K13*K14 -> 1087144.4 | L12: =L13*L14 -> 1123302.9 | M12: =M13*M14 -> 1162955.5
B13: Tons Sold (000s) | C13: 14242 | D13: 15054 | E13: 7496 | F13: 11610 | G13: 13654 | H13: 13368 | I13: =H13*(1+I24) -> 13635.36 | J13: =I13*(1+J24) -> 13908.067 | K13: =J13*(1+K24) -> 14186.229 | L13: =K13*(1+L24) -> 14469.953 | M13: =L13*(1+M24) -> 14759.352
B14: Average Selling Price ($/ton) | C14: 83.06 | D14: 67.13 | E14: 55.35 | F14: 53.01 | G14: 70.43 | H14: 74.38 | I14: =H14*(1+I23) -> 75.1238 | J14: =I14*(1+J23) -> 75.875038 | K14: =J14*(1+K23) -> 76.633788 | L14: =K14*(1+L23) -> 77.630028 | M14: =L14*(1+M23) -> 78.794478
B15: Segment Contribution Margin ($000) | C15: 357846 | D15: 248594 | E15: 142041 | F15: 160052 | G15: 301837 | H15: 361998 | I15: =I12-(I27*I13) -> 337117.91 | J15: =J12-(J27*J13) -> 333279.54 | K15: =K12-(K27*K13) -> 328615.88 | L15: =L12-(L27*L13) -> 326392.75 | M15: =M12-(M27*M13) -> 325721.69
B17: calculated metrics/ drivers
B19: Contribution Margin % | C19: =C15/C12 -> 0.30249258 | D19: =D15/D12 -> 0.24600577 | E19: =E15/E12 -> 0.34235244 | F19: =F15/F12 -> 0.26005771 | G19: =G15/G12 -> 0.31386852 | H19: =H15/H12 -> 0.36408201 | I19: =I15/I12 -> 0.32910742 | J19: =J15/J12 -> 0.31582242 | ... M19: =M15/M12 -> 0.28008097
B20: % Total Revenue | C20: =C$12/C$7 -> 0.75001109 | D20: =D$12/D$7 -> 0.68534199 | E20: =E$12/E$7 -> 0.49048866 | F20: =F$12/F$7 -> 0.55753212 | G20: =G$12/G$7 -> 0.63054053 | H20: =H$12/H$7 -> 0.64063267 | I20: =I$12/I$7 -> 0.63836762 | J20: =J$12/J$7 -> 0.63654429 | ... M20: =M$12/M$7 -> 0.63608649
B22: Segment Revenue Growth | D22: =D12/C12 -1 -> -0.14579147 | E22: =E12/D12 -1 -> -0.58942268 | F22: =F12/E12 -1 -> 0.48337539 | G22: =G12/F12 -1 -> 0.56254793 | H22: =H12/G12 -1 -> 0.033908827 | I22: =I12/H12-1 -> 0.030237135 | J22: =J12/I12-1 -> 0.0302 | K22: =K12/J12-1 -> 0.0302 | L22: =L12/K12-1 -> 0.03326 | M22: =M12/L12-1 -> 0.0353
B23: Selling Price Growth | D23: =D14/C14 -1 -> -0.19178907 | E23: =E14/D14 -1 -> -0.17548041 | F23: =F14/E14 -1 -> -0.042276423 | G23: =G14/F14 -1 -> 0.32861724 | H23: =H14/G14 -1 -> 0.056084055 | I23: =CHOOSE('Main Page & Assumptions'!$D$5,'Main Page & Assumptions'!E11,'Main Page & Assumptions'!J11,'Main Page & Assumptions'!O11) -> 0.01 | J23: =CHOOSE('Main Page & Assumptions'!$D$5,'Main Page & Assumptions'!F11,'Main Page & Assumptions'!K11,'Main Page & Assumptions'!P11) -> 0.01 | K23: =CHOOSE('Main Page & Assumptions'!$D$5,'Main Page & Assumptions'!G11,'Main Page & Assumptions'!L11,'Main Page & Assumptions'!Q11) -> 0.01 | L23: =CHOOSE('Main Page & Assumptions'!$D$5,'Main Page & Assumptions'!H11,'Main Page & Assumptions'!M11,'Main Page & Assumptions'!R11) -> 0.013 | M23: =CHOOSE('Main Page & Assumptions'!$D$5,'Main Page & Assumptions'!I11,'Main Page & Assumptions'!N11,'Main Page & Assumptions'!S11) -> 0.015
B24: Sales Volume Growth | D24: =D13/C13-1 -> 0.057014464 | E24: =E13/D13-1 -> -0.50205925 | F24: =F13/E13-1 -> 0.54882604 | G24: =G13/F13-1 -> 0.17605512 | H24: =H13/G13-1 -> -0.020946243 | I24: =CHOOSE('Main Page & Assumptions'!$D$5,'Main Page & Assumptions'!E12,'Main Page & Assumptions'!J12,'Main Page & Assumptions'!O12) -> 0.02 | J24: =CHOOSE('Main Page & Assumptions'!$D$5,'Main Page & Assumptions'!F12,'Main Page & Assumptions'!K12,'Main Page & Assumptions'!P12) -> 0.02 | K24: =CHOOSE('Main Page & Assumptions'!$D$5,'Main Page & Assumptions'!G12,'Main Page & Assumptions'!L12,'Main Page & Assumptions'!Q12) -> 0.02 | L24: =CHOOSE('Main Page & Assumptions'!$D$5,'Main Page & Assumptions'!H12,'Main Page & Assumptions'!M12,'Main Page & Assumptions'!R12) -> 0.02 | M24: =CHOOSE('Main Page & Assumptions'!$D$5,'Main Page & Assumptions'!I12,'Main Page & Assumptions'!N12,'Main Page & Assumptions'!S12) -> 0.02
B26: Segment Cost of Sales ($000) | C26: =C12-C15 -> 825145 | D26: =D12-D15 -> 761927 | E26: =E12-E15 -> 272856 | F26: =F12-F15 -> 455396 | G26: =G12-G15 -> 659830 | H26: =H12-H15 -> 632278 | I26: =I12-I15 -> 687222.14 | J26: =J12-J15 -> 721995.58 | ... M26: =M12-M15 -> 837233.76
B27: Segment Cost of Sales / Ton ($/ton) | C27: =C26/C13 -> 57.937439 | D27: =D26/D13 -> 50.612927 | E27: =E26/E13 -> 36.400213 | F27: =F26/F13 -> 39.224462 | G27: =G26/G13 -> 48.325033 | H27: =H26/H13 -> 47.297876 | I27: =CHOOSE('Main Page & Assumptions'!$D$5,'Main Page & Assumptions'!E13,'Main Page & Assumptions'!J13,'Main Page & Assumptions'!O13) -> 50.4 | J27: =CHOOSE('Main Page & Assumptions'!$D$5,'Main Page & Assumptions'!F13,'Main Page & Assumptions'!K13,'Main Page & Assumptions'!P13) -> 51.912 | K27: =CHOOSE('Main Page & Assumptions'!$D$5,'Main Page & Assumptions'!G13,'Main Page & Assumptions'!L13,'Main Page & Assumptions'!Q13) -> 53.46936 | L27: =CHOOSE('Main Page & Assumptions'!$D$5,'Main Page & Assumptions'!H13,'Main Page & Assumptions'!M13,'Main Page & Assumptions'!R13) -> 55.073441 | M27: =CHOOSE('Main Page & Assumptions'!$D$5,'Main Page & Assumptions'!I13,'Main Page & Assumptions'!N13,'Main Page & Assumptions'!S13) -> 56.725644
B28: Contribution Margin / Ton ($/ton) | C28: =C$15/C$13 -> 25.126106 | D28: =D$15/D$13 -> 16.513485 | E28: =E$15/E$13 -> 18.948906 | F28: =F$15/F$13 -> 13.785702 | G28: =G$15/G$13 -> 22.106123 | H28: =H$15/H$13 -> 27.079443 | I28: =I$15/I$13 -> 24.7238 | J28: =J$15/J$13 -> 23.963038 | ... M28: =M$15/M$13 -> 22.068834
B32: ISP
B34: Sales ($000) | C34: 394307 | D34: 463956 | E34: 430988 | F34: 488431 | G34: 563480 | H34: 557746 | I34: =I35*I36 -> 580284.04 | J34: =J35*J36 -> 602543.73 | K34: =K35*K36 -> 623813.53 | L34: =L35*L36 -> 644561.56 | M34: =M35*M36 -> 665342.23
B35: Tons Sold (000s) | C35: 3817 | D35: 3734 | E35: 3634 | F35: 4227 | G35: 4362 | H35: 4010 | I35: =H35*(1+I46) -> 4090.2 | J35: =I35*(1+J46) -> 4163.8236 | K35: =J35*(1+K46) -> 4226.281 | L35: =K35*(1+L46) -> 4281.2226 | M35: =L35*(1+M46) -> 4332.5973
B36: Average Selling Price ($/ton) | C36: 103.3 | D36: 124.25 | E36: 118.6 | F36: 115.55 | G36: 129.18 | H36: 139.09 | I36: =H36*(1+I45) -> 141.8718 | J36: =I36*(1+J45) -> 144.70924 | K36: =J36*(1+K45) -> 147.60342 | L36: =K36*(1+L45) -> 150.55549 | M36: =L36*(1+M45) -> 153.5666
B37: Segment Contribution Margin ($000) | C37: 155084 | D37: 178215 | E37: 159176 | F37: 168499 | G37: 170280 | H37: 187665 | I37: =I34-(I49*I35) -> 217974.12 | J37: =J34-(J49*J35) -> 222647.29 | K37: =K34-(K49*K35) -> 226650.79 | L37: =L34-(L49*L35) -> 230165.94 | M37: =M34-(M49*M35) -> 233392.81
B39: calculated metrics / drivers
B41: Contribution Margin % | C41: =C37/C34 -> 0.39330775 | D41: =D37/D34 -> 0.38412048 | E41: =E37/E34 -> 0.36932815 | F41: =F37/F34 -> 0.34498015 | G41: =G37/G34 -> 0.30219351 | H41: =H37/H34 -> 0.33647036 | I41: =I37/I34 -> 0.37563349 | J41: =J37/J34 -> 0.36951225 | ... M41: =M37/M34 -> 0.3507861
B42: % Total Revenue | C42: =C$34/C$7 -> 0.24998891 | D42: =D$34/D$7 -> 0.31465801 | E42: =E$34/E$7 -> 0.50951134 | F42: =F$34/F$7 -> 0.44246788 | G42: =G$34/G$7 -> 0.36945947 | H42: =H$34/H$7 -> 0.35936733 | I42: =I$34/I$7 -> 0.36163238 | J42: =J$34/J$7 -> 0.36345571 | ... M42: =M$34/M$7 -> 0.36391351
B44: Segment Revenue Growth | D44: =D34/C34 -1 -> 0.17663648 | E44: =E34/D34 -1 -> -0.071058462 | F44: =F34/E34 -1 -> 0.13328213 | G44: =G34/F34 -1 -> 0.15365323 | H44: =H34/G34 -1 -> -0.010176049 | I44: =I34/H34-1 -> 0.04040914 | J44: =J34/I34-1 -> 0.03836 | K44: =K34/J34-1 -> 0.0353 | L44: =L34/K34-1 -> 0.03326 | M44: =M34/L34-1 -> 0.03224
B45: Selling Price Growth | D45: =D36/C36 -1 -> 0.20280736 | E45: =E36/D36 -1 -> -0.045472837 | F45: =F36/E36 -1 -> -0.025716695 | G45: =G36/F36 -1 -> 0.11795759 | H45: =H36/G36 -1 -> 0.076714662 | I45: =CHOOSE('Main Page & Assumptions'!$D$5,'Main Page & Assumptions'!E14,'Main Page & Assumptions'!J14,'Main Page & Assumptions'!O14) -> 0.02 | J45: =CHOOSE('Main Page & Assumptions'!$D$5,'Main Page & Assumptions'!F14,'Main Page & Assumptions'!K14,'Main Page & Assumptions'!P14) -> 0.02 | K45: =CHOOSE('Main Page & Assumptions'!$D$5,'Main Page & Assumptions'!G14,'Main Page & Assumptions'!L14,'Main Page & Assumptions'!Q14) -> 0.02 | L45: =CHOOSE('Main Page & Assumptions'!$D$5,'Main Page & Assumptions'!H14,'Main Page & Assumptions'!M14,'Main Page & Assumptions'!R14) -> 0.02 | M45: =CHOOSE('Main Page & Assumptions'!$D$5,'Main Page & Assumptions'!I14,'Main Page & Assumptions'!N14,'Main Page & Assumptions'!S14) -> 0.02
B46: Sales Volume Growth | D46: =D35/C35-1 -> -0.021744826 | E46: =E35/D35-1 -> -0.026780932 | F46: =F35/E35-1 -> 0.16318107 | G46: =G35/F35-1 -> 0.031937544 | H46: =H35/G35-1 -> -0.080696928 | I46: =CHOOSE('Main Page & Assumptions'!$D$5,'Main Page & Assumptions'!E15,'Main Page & Assumptions'!J15,'Main Page & Assumptions'!O15) -> 0.02 | J46: =CHOOSE('Main Page & Assumptions'!$D$5,'Main Page & Assumptions'!F15,'Main Page & Assumptions'!K15,'Main Page & Assumptions'!P15) -> 0.018 | K46: =CHOOSE('Main Page & Assumptions'!$D$5,'Main Page & Assumptions'!G15,'Main Page & Assumptions'!L15,'Main Page & Assumptions'!Q15) -> 0.015 | L46: =CHOOSE('Main Page & Assumptions'!$D$5,'Main Page & Assumptions'!H15,'Main Page & Assumptions'!M15,'Main Page & Assumptions'!R15) -> 0.013 | M46: =CHOOSE('Main Page & Assumptions'!$D$5,'Main Page & Assumptions'!I15,'Main Page & Assumptions'!N15,'Main Page & Assumptions'!S15) -> 0.012
B48: Segment Cost of Sales ($000) | C48: =C34-C37 -> 239223 | D48: =D34-D37 -> 285741 | E48: =E34-E37 -> 271812 | F48: =F34-F37 -> 319932 | G48: =G34-G37 -> 393200 | H48: =H34-H37 -> 370081 | I48: =I34-I37 -> 362309.92 | J48: =J34-J37 -> 379896.44 | ... M48: =M34-M37 -> 431949.42
B49: Segment Cost of Sales / Ton ($/ton) | C49: =C48/C35 -> 62.673042 | D49: =D48/D35 -> 76.524103 | E49: =E48/E35 -> 74.796918 | F49: =F48/F35 -> 75.687722 | G49: =G48/G35 -> 90.142137 | H49: =H48/H35 -> 92.289526 | I49: =CHOOSE('Main Page & Assumptions'!$D$5,'Main Page & Assumptions'!E16,'Main Page & Assumptions'!J16,'Main Page & Assumptions'!O16) -> 88.58 | J49: =CHOOSE('Main Page & Assumptions'!$D$5,'Main Page & Assumptions'!F16,'Main Page & Assumptions'!K16,'Main Page & Assumptions'!P16) -> 91.2374 | K49: =CHOOSE('Main Page & Assumptions'!$D$5,'Main Page & Assumptions'!G16,'Main Page & Assumptions'!L16,'Main Page & Assumptions'!Q16) -> 93.974522 | L49: =CHOOSE('Main Page & Assumptions'!$D$5,'Main Page & Assumptions'!H16,'Main Page & Assumptions'!M16,'Main Page & Assumptions'!R16) -> 96.793758 | M49: =CHOOSE('Main Page & Assumptions'!$D$5,'Main Page & Assumptions'!I16,'Main Page & Assumptions'!N16,'Main Page & Assumptions'!S16) -> 99.69757
B50: Contribution Margin / Ton ($/ton) | C50: =C37/C35 -> 40.629814 | D50: =D37/D35 -> 47.727638 | E50: =E37/E35 -> 43.801871 | F50: =F37/F35 -> 39.86255 | G50: =G37/G35 -> 39.037139 | H50: =H37/H35 -> 46.799252 | I50: =I37/I35 -> 53.2918 | J50: =J37/J35 -> 53.471836 | ... M50: =M37/M35 -> 53.869029
B55: segment contribution check | C55: =C42+C20 -> 1 | D55: =D42+D20 -> 1 | E55: =E42+E20 -> 1 | F55: =F42+F20 -> 1 | G55: =G42+G20 -> 1 | H55: =H42+H20 -> 1 | I55: =I42+I20 -> 1 | J55: =J42+J20 -> 1 | ... M55: =M42+M20 -> 1
D76: =122.289/D7 * 1000 -> 0.082937204 | H76: =65.47/'Revenue Build'!H7*1000 -> 0.04218368

Sheet ISP Carve Out Costs
A1: =HYPERLINK("#'Table of Contents'!A1","<--------") -> <--------
B2: Carve Out Adjustments (ISP)
B3: ($mm)
C4: Predicted
B5: FYE December | C5: 2024 | D5: =C5+1 -> 2025 | E5: =D5+1 -> 2026 | F5: =E5+1 -> 2027 | G5: =F5+1 -> 2028
B6: 1. PROJECTED SEGMENT EBITDA
B7: Reported EBITDA | C7: ='Individual Cash Flow'!I37 -> 143.86485 | D7: ='Individual Cash Flow'!J37 -> 148.87549 | E7: ='Individual Cash Flow'!K37 -> 151.33485 | F7: ='Individual Cash Flow'!L37 -> 152.36827 | G7: ='Individual Cash Flow'!M37 -> 153.10951
B9: 2. LESS RUN-RATE ADJUSTMENTS
B10: Corporate Functions to be Replaced | C10: =SUM(C11:C16) -> 5 | D10: =SUM(D11:D16) -> 5 | E10: =SUM(E11:E16) -> 5 | F10: =SUM(F11:F16) -> 5 | G10: =SUM(G11:G16) -> 5
B11: Finance/Accounting | C11: 1.2 | D11: 1.2 | E11: 1.2 | F11: 1.2 | G11: 1.2
B12: HR / Payroll | C12: 0.7 | D12: 0.7 | E12: 0.7 | F12: 0.7 | G12: 0.7
B13: IT / Systems | C13: 1.5 | D13: 1.5 | E13: 1.5 | F13: 1.5 | G13: 1.5
B14: Legal / Compliance | C14: 0.6 | D14: 0.6 | E14: 0.6 | F14: 0.6 | G14: 0.6
B15: Treasury | C15: 1 | D15: 1 | E15: 1 | F15: 1 | G15: 1
B16: other | C16: 0 | D16: 0 | E16: 0 | F16: 0 | G16: 0
B17: Total Run-Rate Adjustments | C17: =C10 -> 5 | D17: =D10 -> 5 | E17: =E10 -> 5 | F17: =F10 -> 5 | G17: =G10 -> 5
B19: 3. STANDALONE ADJUSTED EBITDA
B20: Adjusted Ebitda | C20: =C7+C17 -> 148.86485 | D20: =D7+D17 -> 153.87549 | E20: =E7+E17 -> 156.33485 | F20: =F7+F17 -> 157.36827 | G20: =G7+G17 -> 158.10951
B21: EBITDA Margin | C21: =C20/'[1]H.B. Fuller BAS Operating'!F7 -> 0.16644103 | D21: =D20/'[1]H.B. Fuller BAS Operating'!G7 -> 0.16542621 | E21: =E20/'[1]H.B. Fuller BAS Operating'!H7 -> 0.16238665 | F21: =F20/'[1]H.B. Fuller BAS Operating'!I7 -> 0.15793244 | G21: =G20/'[1]H.B. Fuller BAS Operating'!J7 -> 0.1540547
B23: 4. ONE TIME SEPERATION COSTS
B24: IT / Systems | C24: 8 | D24: 4 | E24: 0 | F24: 0 | G24: 0
B25: Legal | C25: 4 | D25: 1 | E25: 0 | F25: 0 | G25: 0
B26: People / HR | C26: 2 | D26: 1 | E26: 0 | F26: 0 | G26: 0
B27: Facilities | C27: 1 | D27: 0 | E27: 0 | F27: 0 | G27: 0
B28: Branding / Rebrand | C28: 0 | D28: 0 | E28: 0 | F28: 0 | G28: 0
B29: Other | C29: 2 | D29: 1 | E29: 0 | F29: 0 | G29: 0
B30: Total One-Time Seperation Costs | C30: =SUM(C24:C29) -> 17 | D30: =SUM(D24:D29) -> 7 | E30: =SUM(E24:E29) -> 0 | F30: =SUM(F24:F29) -> 0 | G30: =SUM(G24:G29) -> 0

Sheet SLCA Financials (memo)
B1: =HYPERLINK("#'Table of Contents'!A1", "<---------") -> <---------
C2: SLCA (memo)
C3: Consolidated Financials($mm)
J4: Forecast
C5: FYE December | D5: ='SLCA Raw'!B3 -> 43465 | E5: =EDATE(D5,12) -> 43830 | F5: =EDATE(E5,12) -> 44196 | G5: =EDATE(F5,12) -> 44561 | H5: =EDATE(G5,12) -> 44926 | I5: =EDATE(H5,12) -> 45291 | J5: =EDATE(I5,12) -> 45657 | K5: =EDATE(J5,12) -> 46022 | L5: =EDATE(K5,12) -> 46387 | ... N5: =EDATE(M5,12) -> 47118
D6: USD | E6: USD | F6: USD | G6: USD | H6: USD | I6: USD | J6: USD | K6: USD | L6: USD | M6: USD | N6: USD
C7: Revenue Drivers
A8: Revenue Growth | C8: Revenue Growth | E8: =E35/D35 - 1 -> -0.065188062 | F8: =F35/E35 - 1 -> -0.42631523 | G8: =G35/F35 - 1 -> 0.30499891 | H8: =H35/G35 - 1 -> 0.38162516 | I8: =I35/H35 - 1 -> 0.017621252 | J8: =J35/I35-1 -> 0.033892621 | K8: =K35/J35-1 -> 0.03315092 | L8: =L35/K35-1 -> 0.032053624 | M8: =M35/L35-1 -> 0.03326 | N8: =N35/M35-1 -> 0.034184327
A9: Gross Margin | C9: Gross Margin | D9: =D38/D35 -> 0.26258133 | E9: =E38/E35 -> 0.23139323 | F9: =F38/F35 -> 0.35154069 | G9: =G38/G35 -> 0.30988994 | H9: =H38/H35 -> 0.32359766 | I9: =I38/I35 -> 0.36664622 | J9: =AVERAGE(G9:I9) -> 0.33337794 | K9: =AVERAGE(H9:J9) -> 0.34120727 | L9: =AVERAGE(I9:K9) -> 0.34707714 | M9: =AVERAGE(J9:L9) -> 0.34055412 | N9: =AVERAGE(K9:M9) -> 0.34294618
A10: SG&A % Revenue | C10: SG&A % Revenue | D10: =D39/D35 -> 0.093178968 | E10: =E39/E35 -> 0.10230611 | F10: =F39/F35 -> 0.17817907 | G10: =G39/G35 -> 0.13843274 | H10: =H39/H35 -> 0.11960421 | I10: =I39/I35 -> 0.10080076 | J10: =AVERAGE($G$10:$I$10) -> 0.11961257 | K10: =J10 -> 0.11961257 | L10: =K10 -> 0.11961257 | M10: =L10 -> 0.11961257 | N10: =M10 -> 0.11961257
A11: R&D % Revenue | C11: R&D % Revenue | D11: =D40/D35 -> 0 | E11: =E40/E35 -> 0 | F11: =F40/F35 -> 0 | G11: =G40/G35 -> 0 | H11: =H40/H35 -> 0 | I11: =I40/I35 -> 0 | J11: =I11 -> 0 | K11: =J11 -> 0 | L11: =K11 -> 0 | M11: =L11 -> 0 | N11: =M11 -> 0
A12: Other Operating Expenses % Revenue | C12: Other Operating Expenses % Revenue | D12: =D$43/D$35 -> 0 | E12: =E$43/E$35 -> 0 | F12: =F$43/F$35 -> 0 | G12: =G$43/G$35 -> 0 | H12: =H$43/H$35 -> 0 | I12: =I$43/I$35 -> 0 | J12: =I12 -> 0 | K12: 0 | L12: 0 | M12: 0 | N12: 0
A13: Gain (Loss) on Asset Sales | C13: Gain (Loss) on Asset Sales | D13: =D$48 -> 0 | E13: =E$48 -> 0 | F13: =F$48 -> 0.3 | G13: =G$48 -> 0 | H13: =H$48 -> 0 | I13: =I$48 -> 16.8 | J13: 0 | K13: 0 | L13: 0 | M13: 0 | N13: 0
A15: Days Inventory (DOH) | C15: Working Capital Drivers
A16: Days Receivable (DSO) | C16: DSO | D16: =IFERROR( INDEX('SLCA Raw'!$B$120:$K$163, MATCH($A16,'SLCA Raw'!$A$120:$A$163,0), MATCH(D$33,'SLCA Raw'!$B$116:$K$116,0) ),"") -> 0 | E16: =IFERROR( INDEX('SLCA Raw'!$B$120:$K$163, MATCH($A16,'SLCA Raw'!$A$120:$A$163,0), MATCH(E$33,'SLCA Raw'!$B$116:$K$116,0) ),"") -> 0 | F16: =IFERROR( INDEX('SLCA Raw'!$B$120:$K$163, MATCH($A16,'SLCA Raw'!$A$120:$A$163,0), MATCH(F$33,'SLCA Raw'!$B$116:$K$116,0) ),"") -> 0 | G16: =IFERROR( INDEX('SLCA Raw'!$B$120:$K$163, MATCH($A16,'SLCA Raw'!$A$120:$A$163,0), MATCH(G$33,'SLCA Raw'!$B$116:$K$116,0) ),"") -> 0 | H16: =IFERROR( INDEX('SLCA Raw'!$B$120:$K$163, MATCH($A16,'SLCA Raw'!$A$120:$A$163,0), MATCH(H$33,'SLCA Raw'!$B$116:$K$116,0) ),"") -> 0 | I16: =IFERROR( INDEX('SLCA Raw'!$B$120:$K$163, MATCH($A16,'SLCA Raw'!$A$120:$A$163,0), MATCH(I$33,'SLCA Raw'!$B$116:$K$116,0) ),"") -> 0 | J16: 49 | K16: =J16 -> 49 | L16: =K16 -> 49 | M16: =L16 -> 49 | N16: =M16 -> 49
A17: Days Inventory (DOH) | C17: DOH | D17: =IFERROR( INDEX('SLCA Raw'!$B$120:$K$163, MATCH($A17,'SLCA Raw'!$A$120:$A$163,0), MATCH(D$33,'SLCA Raw'!$B$116:$K$116,0) ),"") -> 51 | E17: =IFERROR( INDEX('SLCA Raw'!$B$120:$K$163, MATCH($A17,'SLCA Raw'!$A$120:$A$163,0), MATCH(E$33,'SLCA Raw'!$B$116:$K$116,0) ),"") -> 40 | F17: =IFERROR( INDEX('SLCA Raw'!$B$120:$K$163, MATCH($A17,'SLCA Raw'!$A$120:$A$163,0), MATCH(F$33,'SLCA Raw'!$B$116:$K$116,0) ),"") -> 68 | G17: =IFERROR( INDEX('SLCA Raw'!$B$120:$K$163, MATCH($A17,'SLCA Raw'!$A$120:$A$163,0), MATCH(G$33,'SLCA Raw'!$B$116:$K$116,0) ),"") -> 55 | H17: =IFERROR( INDEX('SLCA Raw'!$B$120:$K$163, MATCH($A17,'SLCA Raw'!$A$120:$A$163,0), MATCH(H$33,'SLCA Raw'!$B$116:$K$116,0) ),"") -> 52 | I17: =IFERROR( INDEX('SLCA Raw'!$B$120:$K$163, MATCH($A17,'SLCA Raw'!$A$120:$A$163,0), MATCH(I$33,'SLCA Raw'!$B$116:$K$116,0) ),"") -> 55 | J17: =AVERAGE(G$17:I$17) -> 54 | K17: =J17 -> 54 | L17: =K17 -> 54 | M17: =L17 -> 54 | N17: =M17 -> 54
A18: Days Payable (DP) | C18: DPO | D18: =IFERROR( INDEX('SLCA Raw'!$B$120:$K$163, MATCH($A18,'SLCA Raw'!$A$120:$A$163,0), MATCH(D$33,'SLCA Raw'!$B$116:$K$116,0) ),"") -> 56 | E18: =IFERROR( INDEX('SLCA Raw'!$B$120:$K$163, MATCH($A18,'SLCA Raw'!$A$120:$A$163,0), MATCH(E$33,'SLCA Raw'!$B$116:$K$116,0) ),"") -> 58 | F18: =IFERROR( INDEX('SLCA Raw'!$B$120:$K$163, MATCH($A18,'SLCA Raw'!$A$120:$A$163,0), MATCH(F$33,'SLCA Raw'!$B$116:$K$116,0) ),"") -> 59 | G18: =IFERROR( INDEX('SLCA Raw'!$B$120:$K$163, MATCH($A18,'SLCA Raw'!$A$120:$A$163,0), MATCH(G$33,'SLCA Raw'!$B$116:$K$116,0) ),"") -> 64 | H18: =IFERROR( INDEX('SLCA Raw'!$B$120:$K$163, MATCH($A18,'SLCA Raw'!$A$120:$A$163,0), MATCH(H$33,'SLCA Raw'!$B$116:$K$116,0) ),"") -> 65 | I18: =IFERROR( INDEX('SLCA Raw'!$B$120:$K$163, MATCH($A18,'SLCA Raw'!$A$120:$A$163,0), MATCH(I$33,'SLCA Raw'!$B$116:$K$116,0) ),"") -> 46 | J18: =AVERAGE(G$18:I$18) -> 58.333333 | K18: =J18 -> 58.333333 | L18: =K18 -> 58.333333 | M18: =L18 -> 58.333333 | N18: =M18 -> 58.333333
A19: Other Balance Sheet Drivers | C19: Prepaids % Revenue | D19: =D$67/D$35 -> 0.011411921 | E19: =E$67/E$35 -> 0.010986947 | F19: =F$67/F$35 -> 0.027308677 | G19: =G$67/G$35 -> 0.016306135 | H19: =H$67/H$35 -> 0.013244625 | I19: =I$67/I$35 -> 0.012693119 | J19: =AVERAGE(G$19:I$19) -> 0.014081293 | K19: =J19 -> 0.014081293 | L19: =K19 -> 0.014081293 | M19: =L19 -> 0.014081293 | N19: =M19 -> 0.014081293
A20: Prepaids % Revenue | C20: Other Current Assets % Revenue | D20: =D$68/D$35 -> 0 | E20: =E$68/E$35 -> 0 | F20: =F$68/F$35 -> 0 | G20: =G$68/G$35 -> 0 | H20: =H$68/H$35 -> 0 | I20: =I$68/I$35 -> 0 | J20: =I20 -> 0 | K20: =J20 -> 0 | L20: =K20 -> 0 | M20: =L20 -> 0 | N20: =M20 -> 0
A21: Other Current Assets % Revenue | C21: Accrued Expenses % Revenue | D21: =D$82/D$35 -> 0.023838235 | E21: =E$82/E$35 -> 0.06388706 | F21: =F$82/F$35 -> 0.052016527 | G21: =G$82/G$35 -> 0.043120668 | H21: =H$82/H$35 -> 0.033504967 | I21: =I$82/I$35 -> 0.026159423 | J21: =AVERAGE(G$21:I$21) -> 0.034261686 | K21: =J21 -> 0.034261686 | L21: =K21 -> 0.034261686 | M21: =L21 -> 0.034261686 | N21: =M21 -> 0.034261686
A22: Accrued Expenses % Revenue | C22: Other Current Liabilities % Revenue | D22: =D$85/D$35 -> 0.020034261 | E22: =E$85/E$35 -> 0.010240919 | F22: =F$85/F$35 -> 0.015959616 | G22: =G$85/G$35 -> 0.0048918405 | H22: =H$85/H$35 -> 0.012261113 | I22: =I$85/I$35 -> 0.0034149 | J22: =AVERAGE(G$22:I$22) -> 0.0068559512 | K22: =J22 -> 0.0068559512 | L22: =K22 -> 0.0068559512 | M22: =L22 -> 0.0068559512 | N22: =M22 -> 0.0068559512
A24: Other Current Liabilities % Revenue | C24: Other Balance Sheet Drivers
A25: Other Long-Term Assets % Revenue | C25: Other Long-Term Assets % Revenue | D25: =D$77/D$35 -> 0.01160212 | E25: =E$77/E$35 -> 0.010986947 | F25: =F$77/F$35 -> 0.011585499 | G25: =G$77/G$35 -> 0.0064318644 | H25: =H$77/H$35 -> 0.0062944752 | I25: =I$77/I$35 -> 0.0080540095 | J25: =AVERAGE($G$25:$I$25) -> 0.006926783 | K25: =J25 -> 0.006926783 | L25: =K25 -> 0.006926783 | M25: =L25 -> 0.006926783 | N25: =M25 -> 0.006926783
A26: Other Long-Term Liabilities % Revenue | C26: Other Long-Term Liabilities % Revenue | D26: =D$92/D$35 -> 0.12901811 | E26: =E$92/E$35 -> 0.16866998 | F26: =F$92/F$35 -> 0.21066693 | G26: =G$92/G$35 -> 0.14648345 | H26: =H$92/H$35 -> 0.089040597 | I26: =I$92/I$35 -> 0.084470452 | J26: =AVERAGE(G$26:I$26) -> 0.10666483 | K26: =J26 -> 0.10666483 | L26: =K26 -> 0.10666483 | M26: =L26 -> 0.10666483 | N26: =M26 -> 0.10666483
A28: Tax Rate | C28: Tax Rate | D28: =CHOOSE('Main Page & Assumptions'!D5,'Main Page & Assumptions'!E18,'Main Page & Assumptions'!J18,'Main Page & Assumptions'!O18) -> 0.265 | E28: =$D$28 -> 0.265 | F28: =$D$28 -> 0.265 | G28: =$D$28 -> 0.265 | H28: =$D$28 -> 0.265 | I28: =$D$28 -> 0.265 | J28: =$D$28 -> 0.265 | K28: =$D$28 -> 0.265 | L28: =$D$28 -> 0.265 | ... N28: =$D$28 -> 0.265
C31: Income Statement
J32: Forecast
C33: FYE December | D33: =$D$5 -> 43465 | E33: =EDATE(D33,12) -> 43830 | F33: =EDATE(E33,12) -> 44196 | G33: =EDATE(F33,12) -> 44561 | H33: =EDATE(G33,12) -> 44926 | I33: =EDATE(H33,12) -> 45291 | J33: =EDATE(I33,12) -> 45657 | K33: =EDATE(J33,12) -> 46022 | L33: =EDATE(K33,12) -> 46387 | ... N33: =EDATE(M33,12) -> 47118
D34: USD | E34: USD | F34: USD | G34: USD | H34: USD | I34: USD | J34: USD | K34: USD | L34: USD | M34: USD | N34: USD
A35: Total Revenue | C35: Revenue | D35: =IFERROR( INDEX('SLCA Raw'!$B$6:$K$33, MATCH(TRIM($A35),'SLCA Raw'!$M$6:$M$33,0), MATCH(D$33,'SLCA Raw'!$B$3:$K$3,0) ),"") -> 1577.298 | E35: =IFERROR( INDEX('SLCA Raw'!$B$6:$K$33, MATCH(TRIM($A35),'SLCA Raw'!$M$6:$M$33,0), MATCH(E$33,'SLCA Raw'!$B$3:$K$3,0) ),"") -> 1474.477 | F35: =IFERROR( INDEX('SLCA Raw'!$B$6:$K$33, MATCH(TRIM($A35),'SLCA Raw'!$M$6:$M$33,0), MATCH(F$33,'SLCA Raw'!$B$3:$K$3,0) ),"") -> 845.885 | G35: =IFERROR( INDEX('SLCA Raw'!$B$6:$K$33, MATCH(TRIM($A35),'SLCA Raw'!$M$6:$M$33,0), MATCH(G$33,'SLCA Raw'!$B$3:$K$3,0) ),"") -> 1103.879 | H35: =IFERROR( INDEX('SLCA Raw'!$B$6:$K$33, MATCH(TRIM($A35),'SLCA Raw'!$M$6:$M$33,0), MATCH(H$33,'SLCA Raw'!$B$3:$K$3,0) ),"") -> 1525.147 | I35: =IFERROR( INDEX('SLCA Raw'!$B$6:$K$33, MATCH(TRIM($A35),'SLCA Raw'!$M$6:$M$33,0), MATCH(I$33,'SLCA Raw'!$B$3:$K$3,0) ),"") -> 1552.022 | J35: ='Revenue Build'!I7/1000 -> 1604.6241 | K35: ='Revenue Build'!J7/1000 -> 1657.8189 | L35: ='Revenue Build'!K7/1000 -> 1710.958 | M35: ='Revenue Build'!L7/1000 -> 1767.8644 | N35: ='Revenue Build'!M7/1000 -> 1828.2977
A37: Cost of Revenue, Total | C37: Cost of Revenue | D37: =IFERROR( INDEX('SLCA Raw'!$B$6:$K$33, MATCH(TRIM($A37),'SLCA Raw'!$M$6:$M$33,0), MATCH(D$33,'SLCA Raw'!$B$3:$K$3,0) ),"") -> 1163.129 | E37: =IFERROR( INDEX('SLCA Raw'!$B$6:$K$33, MATCH(TRIM($A37),'SLCA Raw'!$M$6:$M$33,0), MATCH(E$33,'SLCA Raw'!$B$3:$K$3,0) ),"") -> 1133.293 | F37: =IFERROR( INDEX('SLCA Raw'!$B$6:$K$33, MATCH(TRIM($A37),'SLCA Raw'!$M$6:$M$33,0), MATCH(F$33,'SLCA Raw'!$B$3:$K$3,0) ),"") -> 548.522 | G37: =IFERROR( INDEX('SLCA Raw'!$B$6:$K$33, MATCH(TRIM($A37),'SLCA Raw'!$M$6:$M$33,0), MATCH(G$33,'SLCA Raw'!$B$3:$K$3,0) ),"") -> 761.798 | H37: =IFERROR( INDEX('SLCA Raw'!$B$6:$K$33, MATCH(TRIM($A37),'SLCA Raw'!$M$6:$M$33,0), MATCH(H$33,'SLCA Raw'!$B$3:$K$3,0) ),"") -> 1031.613 | I37: =IFERROR( INDEX('SLCA Raw'!$B$6:$K$33, MATCH(TRIM($A37),'SLCA Raw'!$M$6:$M$33,0), MATCH(I$33,'SLCA Raw'!$B$3:$K$3,0) ),"") -> 982.979 | J37: =J35*(1-J$9) -> 1069.6778 | K37: =K35*(1-K$9) -> 1092.159 | L37: =L35*(1-L$9) -> 1117.1236 | M37: =M35*(1-M$9) -> 1165.8109 | N37: =N35*(1-N$9) -> 1201.29
A38: Gross Profit | C38: Gross Profit | D38: =IFERROR( INDEX('SLCA Raw'!$B$6:$K$33, MATCH(TRIM($A38),'SLCA Raw'!$M$6:$M$33,0), MATCH(D$33,'SLCA Raw'!$B$3:$K$3,0) ),"") -> 414.169 | E38: =IFERROR( INDEX('SLCA Raw'!$B$6:$K$33, MATCH(TRIM($A38),'SLCA Raw'!$M$6:$M$33,0), MATCH(E$33,'SLCA Raw'!$B$3:$K$3,0) ),"") -> 341.184 | F38: =IFERROR( INDEX('SLCA Raw'!$B$6:$K$33, MATCH(TRIM($A38),'SLCA Raw'!$M$6:$M$33,0), MATCH(F$33,'SLCA Raw'!$B$3:$K$3,0) ),"") -> 297.363 | G38: =IFERROR( INDEX('SLCA Raw'!$B$6:$K$33, MATCH(TRIM($A38),'SLCA Raw'!$M$6:$M$33,0), MATCH(G$33,'SLCA Raw'!$B$3:$K$3,0) ),"") -> 342.081 | H38: =IFERROR( INDEX('SLCA Raw'!$B$6:$K$33, MATCH(TRIM($A38),'SLCA Raw'!$M$6:$M$33,0), MATCH(H$33,'SLCA Raw'!$B$3:$K$3,0) ),"") -> 493.534 | I38: =IFERROR( INDEX('SLCA Raw'!$B$6:$K$33, MATCH(TRIM($A38),'SLCA Raw'!$M$6:$M$33,0), MATCH(I$33,'SLCA Raw'!$B$3:$K$3,0) ),"") -> 569.043 | J38: =J$35-J$37 -> 534.94628 | K38: =K$35-K$37 -> 565.65985 | L38: =L$35-L$37 -> 593.8344 | M38: =M$35-M$37 -> 602.05351 | N38: =N$35-N$37 -> 627.0077
A39: Selling/General/Admin. Expenses, Total | C39: SG&A | D39: =IFERROR( INDEX('SLCA Raw'!$B$6:$K$33, MATCH(TRIM($A39),'SLCA Raw'!$M$6:$M$33,0), MATCH(D$33,'SLCA Raw'!$B$3:$K$3,0) ),"") -> 146.971 | E39: =IFERROR( INDEX('SLCA Raw'!$B$6:$K$33, MATCH(TRIM($A39),'SLCA Raw'!$M$6:$M$33,0), MATCH(E$33,'SLCA Raw'!$B$3:$K$3,0) ),"") -> 150.848 | F39: =IFERROR( INDEX('SLCA Raw'!$B$6:$K$33, MATCH(TRIM($A39),'SLCA Raw'!$M$6:$M$33,0), MATCH(F$33,'SLCA Raw'!$B$3:$K$3,0) ),"") -> 150.719 | G39: =IFERROR( INDEX('SLCA Raw'!$B$6:$K$33, MATCH(TRIM($A39),'SLCA Raw'!$M$6:$M$33,0), MATCH(G$33,'SLCA Raw'!$B$3:$K$3,0) ),"") -> 152.813 | H39: =IFERROR( INDEX('SLCA Raw'!$B$6:$K$33, MATCH(TRIM($A39),'SLCA Raw'!$M$6:$M$33,0), MATCH(H$33,'SLCA Raw'!$B$3:$K$3,0) ),"") -> 182.414 | I39: =IFERROR( INDEX('SLCA Raw'!$B$6:$K$33, MATCH(TRIM($A39),'SLCA Raw'!$M$6:$M$33,0), MATCH(I$33,'SLCA Raw'!$B$3:$K$3,0) ),"") -> 156.445 | J39: =J$35*J$10 -> 191.93321 | K39: =K$35*K$10 -> 198.29598 | L39: =L$35*L$10 -> 204.65208 | M39: =M$35*M$10 -> 211.45881 | N39: =N$35*N$10 -> 218.68739
A40: Research & Development | C40: R&D | D40: =IFERROR( INDEX('SLCA Raw'!$B$6:$K$33, MATCH(TRIM($A40),'SLCA Raw'!$M$6:$M$33,0), MATCH(D$33,'SLCA Raw'!$B$3:$K$3,0) ),"") -> 0 | E40: =IFERROR( INDEX('SLCA Raw'!$B$6:$K$33, MATCH(TRIM($A40),'SLCA Raw'!$M$6:$M$33,0), MATCH(E$33,'SLCA Raw'!$B$3:$K$3,0) ),"") -> 0 | F40: =IFERROR( INDEX('SLCA Raw'!$B$6:$K$33, MATCH(TRIM($A40),'SLCA Raw'!$M$6:$M$33,0), MATCH(F$33,'SLCA Raw'!$B$3:$K$3,0) ),"") -> 0 | G40: =IFERROR( INDEX('SLCA Raw'!$B$6:$K$33, MATCH(TRIM($A40),'SLCA Raw'!$M$6:$M$33,0), MATCH(G$33,'SLCA Raw'!$B$3:$K$3,0) ),"") -> 0 | H40: =IFERROR( INDEX('SLCA Raw'!$B$6:$K$33, MATCH(TRIM($A40),'SLCA Raw'!$M$6:$M$33,0), MATCH(H$33,'SLCA Raw'!$B$3:$K$3,0) ),"") -> 0 | I40: =IFERROR( INDEX('SLCA Raw'!$B$6:$K$33, MATCH(TRIM($A40),'SLCA Raw'!$M$6:$M$33,0), MATCH(I$33,'SLCA Raw'!$B$3:$K$3,0) ),"") -> 0 | J40: =J$35*J$11 -> 0 | K40: =K$35*K$11 -> 0 | L40: =L$35*L$11 -> 0 | M40: =M$35*M$11 -> 0 | N40: =N$35*N$11 -> 0
A41: Depreciation/Amortization | C41: D&A | D41: =IFERROR( INDEX('SLCA Raw'!$B$6:$K$33, MATCH(TRIM($A41),'SLCA Raw'!$M$6:$M$33,0), MATCH(D$33,'SLCA Raw'!$B$3:$K$3,0) ),"") -> 148.8 | E41: =IFERROR( INDEX('SLCA Raw'!$B$6:$K$33, MATCH(TRIM($A41),'SLCA Raw'!$M$6:$M$33,0), MATCH(E$33,'SLCA Raw'!$B$3:$K$3,0) ),"") -> 179.4 | F41: =IFERROR( INDEX('SLCA Raw'!$B$6:$K$33, MATCH(TRIM($A41),'SLCA Raw'!$M$6:$M$33,0), MATCH(F$33,'SLCA Raw'!$B$3:$K$3,0) ),"") -> 155.6 | G41: =IFERROR( INDEX('SLCA Raw'!$B$6:$K$33, MATCH(TRIM($A41),'SLCA Raw'!$M$6:$M$33,0), MATCH(G$33,'SLCA Raw'!$B$3:$K$3,0) ),"") -> 161.1 | H41: =IFERROR( INDEX('SLCA Raw'!$B$6:$K$33, MATCH(TRIM($A41),'SLCA Raw'!$M$6:$M$33,0), MATCH(H$33,'SLCA Raw'!$B$3:$K$3,0) ),"") -> 140.2 | I41: =IFERROR( INDEX('SLCA Raw'!$B$6:$K$33, MATCH(TRIM($A41),'SLCA Raw'!$M$6:$M$33,0), MATCH(I$33,'SLCA Raw'!$B$3:$K$3,0) ),"") -> 137.3 | J41: =SUM('Individual Cash Flow'!I13+'Individual Cash Flow'!I39) -> 146.23333 | K41: =SUM('Individual Cash Flow'!J13+'Individual Cash Flow'!J39) -> 146.23333 | L41: =SUM('Individual Cash Flow'!K13+'Individual Cash Flow'!K39) -> 146.23333 | M41: =SUM('Individual Cash Flow'!L13+'Individual Cash Flow'!L39) -> 146.23333 | N41: =SUM('Individual Cash Flow'!M13+'Individual Cash Flow'!M39) -> 146.23333
A42: Unusual Expense (Income) | C42: Unusual Expense (Income) | D42: =IFERROR( INDEX('SLCA Raw'!$B$6:$K$33, MATCH(TRIM($A42),'SLCA Raw'!$M$6:$M$33,0), MATCH(D$33,'SLCA Raw'!$B$3:$K$3,0) ),"") -> 281.9 | E42: =IFERROR( INDEX('SLCA Raw'!$B$6:$K$33, MATCH(TRIM($A42),'SLCA Raw'!$M$6:$M$33,0), MATCH(E$33,'SLCA Raw'!$B$3:$K$3,0) ),"") -> 363.8 | F42: =IFERROR( INDEX('SLCA Raw'!$B$6:$K$33, MATCH(TRIM($A42),'SLCA Raw'!$M$6:$M$33,0), MATCH(F$33,'SLCA Raw'!$B$3:$K$3,0) ),"") -> 110.7 | G42: =IFERROR( INDEX('SLCA Raw'!$B$6:$K$33, MATCH(TRIM($A42),'SLCA Raw'!$M$6:$M$33,0), MATCH(G$33,'SLCA Raw'!$B$3:$K$3,0) ),"") -> 0.2 | H42: =IFERROR( INDEX('SLCA Raw'!$B$6:$K$33, MATCH(TRIM($A42),'SLCA Raw'!$M$6:$M$33,0), MATCH(H$33,'SLCA Raw'!$B$3:$K$3,0) ),"") -> 0 | I42: =IFERROR( INDEX('SLCA Raw'!$B$6:$K$33, MATCH(TRIM($A42),'SLCA Raw'!$M$6:$M$33,0), MATCH(I$33,'SLCA Raw'!$B$3:$K$3,0) ),"") -> 8.5 | J42: 0 | K42: 0 | L42: 0 | M42: 0 | N42: 0
A43: Other Operating Expenses, Total | C43: Other Operating Expenses | D43: =IFERROR( INDEX('SLCA Raw'!$B$6:$K$33, MATCH(TRIM($A43),'SLCA Raw'!$M$6:$M$33,0), MATCH(D$33,'SLCA Raw'!$B$3:$K$3,0) ),"") -> 0 | E43: =IFERROR( INDEX('SLCA Raw'!$B$6:$K$33, MATCH(TRIM($A43),'SLCA Raw'!$M$6:$M$33,0), MATCH(E$33,'SLCA Raw'!$B$3:$K$3,0) ),"") -> 0 | F43: =IFERROR( INDEX('SLCA Raw'!$B$6:$K$33, MATCH(TRIM($A43),'SLCA Raw'!$M$6:$M$33,0), MATCH(F$33,'SLCA Raw'!$B$3:$K$3,0) ),"") -> 0 | G43: =IFERROR( INDEX('SLCA Raw'!$B$6:$K$33, MATCH(TRIM($A43),'SLCA Raw'!$M$6:$M$33,0), MATCH(G$33,'SLCA Raw'!$B$3:$K$3,0) ),"") -> 0 | H43: =IFERROR( INDEX('SLCA Raw'!$B$6:$K$33, MATCH(TRIM($A43),'SLCA Raw'!$M$6:$M$33,0), MATCH(H$33,'SLCA Raw'!$B$3:$K$3,0) ),"") -> 0 | I43: =IFERROR( INDEX('SLCA Raw'!$B$6:$K$33, MATCH(TRIM($A43),'SLCA Raw'!$M$6:$M$33,0), MATCH(I$33,'SLCA Raw'!$B$3:$K$3,0) ),"") -> 0 | J43: =J$12*J$35 -> 0 | K43: =K$12*K$35 -> 0 | L43: =L$12*L$35 -> 0 | M43: =M$12*M$35 -> 0 | N43: =N$12*N$35 -> 0
A44: Total Operating Expense | C44: Total Operating Costs & Expenses | D44: =IFERROR( INDEX('SLCA Raw'!$B$6:$K$33, MATCH(TRIM($A44),'SLCA Raw'!$M$6:$M$33,0), MATCH(D$33,'SLCA Raw'!$B$3:$K$3,0) ),"") -> 1740.8 | E44: =IFERROR( INDEX('SLCA Raw'!$B$6:$K$33, MATCH(TRIM($A44),'SLCA Raw'!$M$6:$M$33,0), MATCH(E$33,'SLCA Raw'!$B$3:$K$3,0) ),"") -> 1827.4 | F44: =IFERROR( INDEX('SLCA Raw'!$B$6:$K$33, MATCH(TRIM($A44),'SLCA Raw'!$M$6:$M$33,0), MATCH(F$33,'SLCA Raw'!$B$3:$K$3,0) ),"") -> 965.5 | G44: =IFERROR( INDEX('SLCA Raw'!$B$6:$K$33, MATCH(TRIM($A44),'SLCA Raw'!$M$6:$M$33,0), MATCH(G$33,'SLCA Raw'!$B$3:$K$3,0) ),"") -> 1075.9 | H44: =IFERROR( INDEX('SLCA Raw'!$B$6:$K$33, MATCH(TRIM($A44),'SLCA Raw'!$M$6:$M$33,0), MATCH(H$33,'SLCA Raw'!$B$3:$K$3,0) ),"") -> 1354.2 | I44: =IFERROR( INDEX('SLCA Raw'!$B$6:$K$33, MATCH(TRIM($A44),'SLCA Raw'!$M$6:$M$33,0), MATCH(I$33,'SLCA Raw'!$B$3:$K$3,0) ),"") -> 1285.2 | J44: =SUM(J$39:J$43)+J37 -> 1407.8444 | K44: =SUM(K$39:K$43)+K37 -> 1436.6883 | L44: =SUM(L$39:L$43)+L37 -> 1468.009 | M44: =SUM(M$39:M$43)+M37 -> 1523.5031 | N44: =SUM(N$39:N$43)+N37 -> 1566.2107
A45: Operating Income | C45: Operating Income | D45: =IFERROR( INDEX('SLCA Raw'!$B$6:$K$33, MATCH(TRIM($A45),'SLCA Raw'!$M$6:$M$33,0), MATCH(D$33,'SLCA Raw'!$B$3:$K$3,0) ),"") -> -163.533 | E45: =IFERROR( INDEX('SLCA Raw'!$B$6:$K$33, MATCH(TRIM($A45),'SLCA Raw'!$M$6:$M$33,0), MATCH(E$33,'SLCA Raw'!$B$3:$K$3,0) ),"") -> -352.955 | F45: =IFERROR( INDEX('SLCA Raw'!$B$6:$K$33, MATCH(TRIM($A45),'SLCA Raw'!$M$6:$M$33,0), MATCH(F$33,'SLCA Raw'!$B$3:$K$3,0) ),"") -> -119.612 | G45: =IFERROR( INDEX('SLCA Raw'!$B$6:$K$33, MATCH(TRIM($A45),'SLCA Raw'!$M$6:$M$33,0), MATCH(G$33,'SLCA Raw'!$B$3:$K$3,0) ),"") -> 27.935 | H45: =IFERROR( INDEX('SLCA Raw'!$B$6:$K$33, MATCH(TRIM($A45),'SLCA Raw'!$M$6:$M$33,0), MATCH(H$33,'SLCA Raw'!$B$3:$K$3,0) ),"") -> 170.954 | I45: =IFERROR( INDEX('SLCA Raw'!$B$6:$K$33, MATCH(TRIM($A45),'SLCA Raw'!$M$6:$M$33,0), MATCH(I$33,'SLCA Raw'!$B$3:$K$3,0) ),"") -> 266.839 | J45: =J$35-J$44 -> 196.77973 | K45: =K$35-K$44 -> 221.13054 | L45: =L$35-L$44 -> 242.94899 | M45: =M$35-M$44 -> 244.36137 | N45: =N$35-N$44 -> 262.08698
A47: Interest Inc.(Exp.),Net-Non-Op., Total | C47: Interest Expense, Net | D47: =IFERROR( INDEX('SLCA Raw'!$B$6:$K$33, MATCH(TRIM($A47),'SLCA Raw'!$M$6:$M$33,0), MATCH(D$33,'SLCA Raw'!$B$3:$K$3,0) ),"") -> -70.6 | E47: =IFERROR( INDEX('SLCA Raw'!$B$6:$K$33, MATCH(TRIM($A47),'SLCA Raw'!$M$6:$M$33,0), MATCH(E$33,'SLCA Raw'!$B$3:$K$3,0) ),"") -> -95.5 | F47: =IFERROR( INDEX('SLCA Raw'!$B$6:$K$33, MATCH(TRIM($A47),'SLCA Raw'!$M$6:$M$33,0), MATCH(F$33,'SLCA Raw'!$B$3:$K$3,0) ),"") -> -79.9 | G47: =IFERROR( INDEX('SLCA Raw'!$B$6:$K$33, MATCH(TRIM($A47),'SLCA Raw'!$M$6:$M$33,0), MATCH(G$33,'SLCA Raw'!$B$3:$K$3,0) ),"") -> -71.2 | H47: =IFERROR( INDEX('SLCA Raw'!$B$6:$K$33, MATCH(TRIM($A47),'SLCA Raw'!$M$6:$M$33,0), MATCH(H$33,'SLCA Raw'!$B$3:$K$3,0) ),"") -> -77.6 | I47: =IFERROR( INDEX('SLCA Raw'!$B$6:$K$33, MATCH(TRIM($A47),'SLCA Raw'!$M$6:$M$33,0), MATCH(I$33,'SLCA Raw'!$B$3:$K$3,0) ),"") -> -101.7
...

Sheet Individual Cash Flow
A1: =HYPERLINK("#'Table of Contents'!A1", "<---------") -> <---------
B3: Individual Cash Flow Schedules($mm)
B4: O&G
C5: actual | I5: predicted
C6: 43465 | D6: =EDATE(C6,12) -> 43830 | E6: =EDATE(D6,12) -> 44196 | F6: =EDATE(E6,12) -> 44561 | G6: =EDATE(F6,12) -> 44926 | H6: =EDATE(G6,12) -> 45291 | I6: =EDATE(H6,12) -> 45657 | J6: =EDATE(I6,12) -> 46022 | K6: =EDATE(J6,12) -> 46387 | ... M6: =EDATE(L6,12) -> 47118
B7: Segment Contribution Margin | C7: ='Revenue Build'!C15/1000 -> 357.846 | D7: ='Revenue Build'!D15/1000 -> 248.594 | E7: ='Revenue Build'!E15/1000 -> 142.041 | F7: ='Revenue Build'!F15/1000 -> 160.052 | G7: ='Revenue Build'!G15/1000 -> 301.837 | H7: ='Revenue Build'!H15/1000 -> 361.998 | I7: ='Revenue Build'!I15/1000 -> 337.11791 | J7: ='Revenue Build'!J15/1000 -> 333.27954 | ... M7: ='Revenue Build'!M15/1000 -> 325.72169
B9: Allocated Operating Expense | C9: ='Revenue Build'!C20*(SUM('SLCA Financials (memo)'!D39:D40)+SUM('SLCA Financials (memo)'!D42:D43)) -> 321.65801 | D9: ='Revenue Build'!D20*(SUM('SLCA Financials (memo)'!E39:E40)+SUM('SLCA Financials (memo)'!E42:E43)) -> 352.70988 | E9: ='Revenue Build'!E20*(SUM('SLCA Financials (memo)'!F39:F40)+SUM('SLCA Financials (memo)'!F42:F43)) -> 128.22305 | F9: ='Revenue Build'!F20*(SUM('SLCA Financials (memo)'!G39:G40)+SUM('SLCA Financials (memo)'!G42:G43)) -> 85.309662 | G9: ='Revenue Build'!G20*(SUM('SLCA Financials (memo)'!H39:H40)+SUM('SLCA Financials (memo)'!H42:H43)) -> 115.01942 | H9: ='Revenue Build'!H20*(SUM('SLCA Financials (memo)'!I39:I40)+SUM('SLCA Financials (memo)'!I42:I43)) -> 105.66916 | I9: ='Revenue Build'!I20*(SUM('SLCA Financials (memo)'!J39:J40)+SUM('SLCA Financials (memo)'!J42:J43)) -> 122.52395 | J9: ='Revenue Build'!J20*(SUM('SLCA Financials (memo)'!K39:K40)+SUM('SLCA Financials (memo)'!K42:K43)) -> 126.22417 | ... M9: ='Revenue Build'!M20*(SUM('SLCA Financials (memo)'!N39:N40)+SUM('SLCA Financials (memo)'!N42:N43)) -> 139.10409 | N9: (read writeup)
B11: EBITDA | C11: =C7-C9 -> 36.187992 | D11: =D7-D9 -> -104.11588 | E11: =E7-E9 -> 13.817945 | F11: =F7-F9 -> 74.742338 | G11: =G7-G9 -> 186.81758 | H11: =H7-H9 -> 256.32884 | I11: =I7-I9 -> 214.59396 | J11: =J7-J9 -> 207.05537 | ... M11: =M7-M9 -> 186.6176
B13: D&A | C13: 102.7 | D13: 123.8 | E13: 107.3 | F13: 111.2 | G13: 96.7 | H13: 94.7 | I13: =AVERAGE($F$13:$H$13) -> 100.86667 | J13: =AVERAGE($F$13:$H$13) -> 100.86667 | K13: =AVERAGE($F$13:$H$13) -> 100.86667 | L13: =AVERAGE($F$13:$H$13) -> 100.86667 | M13: =AVERAGE($F$13:$H$13) -> 100.86667 | N13: (read writeup)
B15: EBIT | C15: =C11-C13 -> -66.512008 | D15: =D11-D13 -> -227.91588 | E15: =E11-E13 -> -93.482055 | F15: =F11-F13 -> -36.457662 | G15: =G11-G13 -> 90.117579 | H15: =H11-H13 -> 161.62884 | I15: =I11-I13 -> 113.7273 | J15: =J11-J13 -> 106.1887 | ... M15: =M11-M13 -> 85.750934
B17: Less: Run Rate Adjustments
B18: Less: Seperation Costs
B20: Less: Taxes | C20: =MAX(0,C15*'SLCA Financials (memo)'!D28) -> 0 | D20: =MAX(0,D15*'SLCA Financials (memo)'!E28) -> 0 | E20: =MAX(0,E15*'SLCA Financials (memo)'!F28) -> 0 | F20: =MAX(0,F15*'SLCA Financials (memo)'!G28) -> 0 | G20: =MAX(0,G15*'SLCA Financials (memo)'!H28) -> 23.881159 | H20: =MAX(0,H15*'SLCA Financials (memo)'!I28) -> 42.831644 | I20: =MAX(0,I15*'SLCA Financials (memo)'!J28) -> 30.137734 | J20: =MAX(0,J15*'SLCA Financials (memo)'!K28) -> 28.140007 | ... M20: =MAX(0,M15*'SLCA Financials (memo)'!N28) -> 22.723998
B21: Plus: D&A | C21: =C13 -> 102.7 | D21: =D13 -> 123.8 | E21: =E13 -> 107.3 | F21: =F13 -> 111.2 | G21: =G13 -> 96.7 | H21: =H13 -> 94.7 | I21: =I13 -> 100.86667 | J21: =J13 -> 100.86667 | ... M21: =M13 -> 100.86667
B22: Less: Capex | C22: 150.4 | D22: 52.4 | E22: 15.3 | F22: 13.4 | G22: 23.5 | H22: 28.8 | I22: =CHOOSE('Main Page & Assumptions'!$D$5,'Main Page & Assumptions'!E17,'Main Page & Assumptions'!J17,'Main Page & Assumptions'!O17)*'Revenue Build'!I7*('Main Page & Assumptions'!$D$22)/1000 -> 40.115602 | J22: =CHOOSE('Main Page & Assumptions'!$D$5,'Main Page & Assumptions'!F17,'Main Page & Assumptions'!K17,'Main Page & Assumptions'!P17)*'Revenue Build'!J7*('Main Page & Assumptions'!$D$22)/1000 -> 41.445471 | K22: =CHOOSE('Main Page & Assumptions'!$D$5,'Main Page & Assumptions'!G17,'Main Page & Assumptions'!L17,'Main Page & Assumptions'!Q17)*'Revenue Build'!K7*('Main Page & Assumptions'!$D$22)/1000 -> 42.773949 | L22: =CHOOSE('Main Page & Assumptions'!$D$5,'Main Page & Assumptions'!H17,'Main Page & Assumptions'!M17,'Main Page & Assumptions'!R17)*'Revenue Build'!L7*('Main Page & Assumptions'!$D$22)/1000 -> 44.196611 | M22: =CHOOSE('Main Page & Assumptions'!$D$5,'Main Page & Assumptions'!I17,'Main Page & Assumptions'!N17,'Main Page & Assumptions'!S17)*'Revenue Build'!M7*('Main Page & Assumptions'!$D$22)/1000 -> 45.707442 | N22: (read writeup)
B23: NWC | C23: 119.5 | D23: 34.9 | E23: 92.9 | F23: 82.5 | G23: 88.6 | H23: 120.3 | I23: =0.00012*'Revenue Build'!I12 -> 122.92081 | J23: =0.00012*'Revenue Build'!J12 -> 126.63302 | K23: =0.00012*'Revenue Build'!K12 -> 130.45733 | L23: =0.00012*'Revenue Build'!L12 -> 134.79634 | M23: =0.00012*'Revenue Build'!M12 -> 139.55465 | N23: (read writeup)
B24: Less: Change NWC | D24: =D23-C23 -> -84.6 | E24: =E23-D23 -> 58 | F24: =F23-E23 -> -10.4 | G24: =G23-F23 -> 6.1 | H24: =H23-G23 -> 31.7 | I24: =I23-H23 -> 2.6208069 | J24: =J23-I23 -> 3.7122084 | K24: =K23-J23 -> 3.8243171 | ... M24: =M23-L23 -> 4.7583109
B26: UFCF | D26: =D15-D20-D22-D24 -> -195.71588 | E26: =E15-E20-E22-E24 -> -166.78205 | F26: =F15-F20-F22-F24 -> -39.457662 | G26: =G15-G20-G22-G24 -> 36.636421 | H26: =H15-H20-H22-H24 -> 58.2972 | I26: =I15-I20-I22-I24+I21 -> 141.71982 | J26: =J15-J20-J22-J24+J21 -> 133.75768 | K26: =K15-K20-K22-K24+K21 -> 126.0875 | L26: =L15-L20-L22-L24+L21 -> 119.33728 | M26: =M15-M20-M22-M24+M21 -> 113.42785
B28: ISP
C29: actual | I29: predicted
C30: 43465 | D30: =EDATE(C30,12) -> 43830 | E30: =EDATE(D30,12) -> 44196 | F30: =EDATE(E30,12) -> 44561 | G30: =EDATE(F30,12) -> 44926 | H30: =EDATE(G30,12) -> 45291 | I30: =EDATE(H30,12) -> 45657 | J30: =EDATE(I30,12) -> 46022 | K30: =EDATE(J30,12) -> 46387 | ... M30: =EDATE(L30,12) -> 47118
B31: Segment Contribution Margin | C31: ='Revenue Build'!C37/1000 -> 155.084 | D31: ='Revenue Build'!D37/1000 -> 178.215 | E31: ='Revenue Build'!E37/1000 -> 159.176 | F31: ='Revenue Build'!F37/1000 -> 168.499 | G31: ='Revenue Build'!G37/1000 -> 170.28 | H31: ='Revenue Build'!H37/1000 -> 187.665 | I31: ='Revenue Build'!I37/1000 -> 217.97412 | J31: ='Revenue Build'!J37/1000 -> 222.64729 | ... M31: ='Revenue Build'!M37/1000 -> 233.39281
B33: Allocated Operating Expense | C33: =(1-'Revenue Build'!C20)*(SUM('SLCA Financials (memo)'!D39:D40)+SUM('SLCA Financials (memo)'!D42:D43)) -> 107.21299 | D33: =(1-'Revenue Build'!D20)*(SUM('SLCA Financials (memo)'!E39:E40)+SUM('SLCA Financials (memo)'!E42:E43)) -> 161.93812 | E33: =(1-'Revenue Build'!E20)*(SUM('SLCA Financials (memo)'!F39:F40)+SUM('SLCA Financials (memo)'!F42:F43)) -> 133.19595 | F33: =(1-'Revenue Build'!F20)*(SUM('SLCA Financials (memo)'!G39:G40)+SUM('SLCA Financials (memo)'!G42:G43)) -> 67.703338 | G33: =(1-'Revenue Build'!G20)*(SUM('SLCA Financials (memo)'!H39:H40)+SUM('SLCA Financials (memo)'!H42:H43)) -> 67.394579 | H33: =(1-'Revenue Build'!H20)*(SUM('SLCA Financials (memo)'!I39:I40)+SUM('SLCA Financials (memo)'!I42:I43)) -> 59.275844 | I33: =(1-'Revenue Build'!I20)*(SUM('SLCA Financials (memo)'!J39:J40)+SUM('SLCA Financials (memo)'!J42:J43)) -> 69.409266 | J33: =(1-'Revenue Build'!J20)*(SUM('SLCA Financials (memo)'!K39:K40)+SUM('SLCA Financials (memo)'!K42:K43)) -> 72.071805 | ... M33: =(1-'Revenue Build'!M20)*(SUM('SLCA Financials (memo)'!N39:N40)+SUM('SLCA Financials (memo)'!N42:N43)) -> 79.583295
B34: Less: Run Rate Adjustments | I34: ='ISP Carve Out Costs'!C12 -> 0.7 | J34: ='ISP Carve Out Costs'!D12 -> 0.7 | K34: ='ISP Carve Out Costs'!E12 -> 0.7 | L34: ='ISP Carve Out Costs'!F12 -> 0.7 | M34: ='ISP Carve Out Costs'!G12 -> 0.7
B35: Less: Seperation Costs | I35: ='ISP Carve Out Costs'!C25 -> 4 | J35: ='ISP Carve Out Costs'!D25 -> 1 | K35: ='ISP Carve Out Costs'!E25 -> 0 | L35: ='ISP Carve Out Costs'!F25 -> 0 | M35: ='ISP Carve Out Costs'!G25 -> 0
B37: EBITDA | C37: =C31-C33 -> 47.871008 | D37: =D31-D33 -> 16.276884 | E37: =E31-E33 -> 25.980055 | F37: =F31-F33 -> 100.79566 | G37: =G31-G33 -> 102.88542 | H37: =H31-H33 -> 128.38916 | I37: =I31-I33-SUM(I34:I35) -> 143.86485 | J37: =J31-J33-SUM(J34:J35) -> 148.87549 | K37: =K31-K33-SUM(K34:K35) -> 151.33485 | L37: =L31-L33-SUM(L34:L35) -> 152.36827 | M37: =M31-M33-SUM(M34:M35) -> 153.10951
B39: D&A | C39: 46.1 | D39: 55.6 | E39: 48.2 | F39: 50 | G39: 43.5 | H39: 42.6 | I39: =AVERAGE($F$39:$H$39) -> 45.366667 | J39: =AVERAGE($F$39:$H$39) -> 45.366667 | K39: =AVERAGE($F$39:$H$39) -> 45.366667 | L39: =AVERAGE($F$39:$H$39) -> 45.366667 | M39: =AVERAGE($F$39:$H$39) -> 45.366667
B41: EBIT | C41: =C37-C39 -> 1.7710083 | D41: =D37-D39 -> -39.323116 | E41: =E37-E39 -> -22.219945 | F41: =F37-F39 -> 50.795662 | G41: =G37-G39 -> 59.385421 | H41: =H37-H39 -> 85.789156 | I41: =I37-I39 -> 98.498188 | J41: =J37-J39 -> 103.50882 | ... M41: =M37-M39 -> 107.74284
B43: Less: Taxes | C43: =MAX(0,C41*'SLCA Financials (memo)'!D28) -> 0.4693172 | D43: =MAX(0,D41*'SLCA Financials (memo)'!E28) -> 0 | E43: =MAX(0,E41*'SLCA Financials (memo)'!F28) -> 0 | F43: =MAX(0,F41*'SLCA Financials (memo)'!G28) -> 13.460851 | G43: =MAX(0,G41*'SLCA Financials (memo)'!H28) -> 15.737136 | H43: =MAX(0,H41*'SLCA Financials (memo)'!I28) -> 22.734126 | I43: =MAX(0,I41*'SLCA Financials (memo)'!J28) -> 26.10202 | J43: =MAX(0,J41*'SLCA Financials (memo)'!K28) -> 27.429837 | ... M43: =MAX(0,M41*'SLCA Financials (memo)'!N28) -> 28.551854
B44: Plus D&A | C44: =C39 -> 46.1 | D44: =D39 -> 55.6 | E44: =E39 -> 48.2 | F44: =F39 -> 50 | G44: =G39 -> 43.5 | H44: =H39 -> 42.6 | I44: =I39 -> 45.366667 | J44: =J39 -> 45.366667 | ... M44: =M39 -> 45.366667
B45: Less: Capex | C45: 189.4 | D45: 66 | E45: 19.2 | F45: 16.9 | G45: 29.6 | H45: 36.3 | I45: =CHOOSE('Main Page & Assumptions'!$D$5,'Main Page & Assumptions'!E17,'Main Page & Assumptions'!J17,'Main Page & Assumptions'!O17)*'Revenue Build'!I7*(1-'Main Page & Assumptions'!$D$22)/1000 -> 40.115602 | J45: =CHOOSE('Main Page & Assumptions'!$D$5,'Main Page & Assumptions'!F17,'Main Page & Assumptions'!K17,'Main Page & Assumptions'!P17)*'Revenue Build'!J7*(1-'Main Page & Assumptions'!$D$22)/1000 -> 41.445471 | K45: =CHOOSE('Main Page & Assumptions'!$D$5,'Main Page & Assumptions'!G17,'Main Page & Assumptions'!L17,'Main Page & Assumptions'!Q17)*'Revenue Build'!K7*(1-'Main Page & Assumptions'!$D$22)/1000 -> 42.773949 | L45: =CHOOSE('Main Page & Assumptions'!$D$5,'Main Page & Assumptions'!H17,'Main Page & Assumptions'!M17,'Main Page & Assumptions'!R17)*'Revenue Build'!L7*(1-'Main Page & Assumptions'!$D$22)/1000 -> 44.196611 | M45: =CHOOSE('Main Page & Assumptions'!$D$5,'Main Page & Assumptions'!I17,'Main Page & Assumptions'!N17,'Main Page & Assumptions'!S17)*'Revenue Build'!M7*(1-'Main Page & Assumptions'!$D$22)/1000 -> 45.707442
B46: NWC | C46: 41.7 | D46: 23.6 | E46: 96.8 | F46: 68.3 | G46: 51.5 | H46: 67.5 | I46: =0.00012*'Revenue Build'!I34 -> 69.634084 | J46: =0.00012*'Revenue Build'!J34 -> 72.305248 | K46: =0.00012*'Revenue Build'!K34 -> 74.857623 | L46: =0.00012*'Revenue Build'!L34 -> 77.347388 | M46: =0.00012*'Revenue Build'!M34 -> 79.841067
B47: Less: Change NWC | D47: =D46-C46 -> -18.1 | E47: =E46-D46 -> 73.2 | F47: =F46-E46 -> -28.5 | G47: =G46-F46 -> -16.8 | H47: =H46-G46 -> 16 | I47: =I46-H46 -> 2.1340844 | J47: =J46-I46 -> 2.6711635 | K47: =K46-J46 -> 2.5523752 | ... M47: =M46-L46 -> 2.4936798
B49: UFCF | D49: =D41-D43-D45-D47 -> -87.223116 | E49: =E41-E43-E45-E47 -> -114.61995 | F49: =F41-F43-F45-F47 -> 48.934812 | G49: =G41-G43-G45-G47 -> 30.848284 | H49: =H41-H43-H45-H47 -> 10.75503 | I49: =I41-I43-I45-I47+I44 -> 75.513148 | J49: =J41-J43-J45-J47+J44 -> 77.329015 | K49: =K41-K43-K45-K47+K44 -> 77.926959 | L49: =L41-L43-L45-L47+L44 -> 77.326473 | M49: =M41-M43-M45-M47+M44 -> 76.356536
P57: Year | Q57: 2018 | R57: 2019 | S57: 2020 | T57: 2021 | U57: 2022 | V57: 2023
P58: O&G D&A | Q58: 102.7 | R58: 123.8 | S58: 107.3 | T58: 111.2 | U58: 96.7 | V58: 94.7
P59: ISP D&A | Q59: 46.1 | R59: 55.6 | S59: 48.2 | T59: 50 | U59: 43.5 | V59: 42.6
P61: Total D&A | Q61: ='SLCA Financials (memo)'!D41 -> 148.8 | R61: ='SLCA Financials (memo)'!E41 -> 179.4 | S61: ='SLCA Financials (memo)'!F41 -> 155.6 | T61: ='SLCA Financials (memo)'!G41 -> 161.1 | U61: ='SLCA Financials (memo)'!H41 -> 140.2 | V61: ='SLCA Financials (memo)'!I41 -> 137.3
P63: O&G Capex | Q63: 150.4 | R63: 52.4 | S63: 15.3 | T63: 13.4 | U63: 23.5 | V63: 28.8
P64: ISP Capex | Q64: 189.4 | R64: 66 | S64: 19.2 | T64: 16.9 | U64: 29.6 | V64: 36.3
...

Sheet Carveout DCFs
A1: =HYPERLINK("#'Table of Contents'!A1", "<---------") -> <---------
B2: O&G
C3: 2024 | D3: 2025 | E3: 2026 | F3: 2027 | G3: 2028
B5: Discount Rate | C5: ='Main Page & Assumptions'!$D$26 -> 0.135 | D5: ='Main Page & Assumptions'!$D$26 -> 0.135 | E5: ='Main Page & Assumptions'!$D$26 -> 0.135 | F5: ='Main Page & Assumptions'!$D$26 -> 0.135 | G5: ='Main Page & Assumptions'!$D$26 -> 0.135
B7: UFCF | C7: ='Individual Cash Flow'!I26 -> 141.71982 | D7: ='Individual Cash Flow'!J26 -> 133.75768 | E7: ='Individual Cash Flow'!K26 -> 126.0875 | F7: ='Individual Cash Flow'!L26 -> 119.33728 | G7: ='Individual Cash Flow'!M26 -> 113.42785
B8: Discount Period | C8: 1 | D8: 2 | E8: 3 | F8: 4 | G8: 5
B10: Present Value of Free Cash Flow | C10: =C7/(1+C5)^C8 -> 124.86328 | D10: =D7/(1+D5)^D8 -> 103.831 | E10: =E7/(1+E5)^E8 -> 86.235178 | F10: =F7/(1+F5)^F8 -> 71.910562 | G10: =G7/(1+G5)^G8 -> 60.219951
B12: Combined Cash Flows | C12: =SUM(C10:G10) -> 447.05997
B13: Selected Exit Multiple | C13: =CHOOSE('Main Page & Assumptions'!D5,'Main Page & Assumptions'!D33,'Main Page & Assumptions'!D32,'Main Page & Assumptions'!D34) -> 3.3
B14: Terminal Value | C14: ='Individual Cash Flow'!H11*C13 -> 845.88519
B15: Present Value of Terminal Value | C15: =C14/(1+C5)^G8 -> 449.08868
B17: Warranted Enterprise Value | C17: =C15+C12 -> 896.14865
B18: Net Debt | C18: ='Main Page & Assumptions'!D44*('Individual Cash Flow'!H11/('Individual Cash Flow'!H11+'Individual Cash Flow'!H37)) -> 414.42444
B19: Equity Value | C19: =C17-C18 -> 481.72421
B22: ISP
C23: 2024 | D23: 2025 | E23: 2026 | F23: 2027 | G23: 2028
B25: Discount Rate | C25: ='Main Page & Assumptions'!$C$26 -> 0.11 | D25: ='Main Page & Assumptions'!$C$26 -> 0.11 | E25: ='Main Page & Assumptions'!$C$26 -> 0.11 | F25: ='Main Page & Assumptions'!$C$26 -> 0.11 | G25: ='Main Page & Assumptions'!$C$26 -> 0.11
B27: UFCF | C27: ='Individual Cash Flow'!I49 -> 75.513148 | D27: ='Individual Cash Flow'!J49 -> 77.329015 | E27: ='Individual Cash Flow'!K49 -> 77.926959 | F27: ='Individual Cash Flow'!L49 -> 77.326473 | G27: ='Individual Cash Flow'!M49 -> 76.356536
B28: Discount Period | C28: 1 | D28: 2 | E28: 3 | F28: 4 | G28: 5
B30: Present Value of Free Cash Flow | C30: =C27/(1+C25)^C28 -> 68.029863 | D30: =D27/(1+D25)^D28 -> 62.761963 | E30: =E27/(1+E25)^E28 -> 56.979521 | F30: =F27/(1+F25)^F28 -> 50.937343 | G30: =G27/(1+G25)^G28 -> 45.313888
B32: Combined Cash Flows | C32: =SUM(C30:G30) -> 284.02258
B33: Selected Exit Multiple | C33: =CHOOSE('Main Page & Assumptions'!D5,'Main Page & Assumptions'!C33,'Main Page & Assumptions'!C32,'Main Page & Assumptions'!C34) -> 7.7
B34: Terminal Value | C34: ='Individual Cash Flow'!I37*C33 -> 1107.7594
B35: Present Value of Terminal Value | C35: =C34/(1+C25)^G28 -> 657.40127
B37: Warranted Enterprise Value | C37: =C35+C32 -> 941.42385
B38: Net Debt | C38: ='Main Page & Assumptions'!D44*('Individual Cash Flow'!H37/('Individual Cash Flow'!H11+'Individual Cash Flow'!H37)) -> 207.57556
B39: Equity Value | C39: =C37-C38 -> 733.84829

Sheet Standalone DCF
A1: =HYPERLINK("#'Table of Contents'!A1", "<---------") -> <---------
B3: SLCA DCF
C4: Actual | I4: Forecast
C5: 43465 | D5: 43830 | E5: 44196 | F5: 44561 | G5: 44926 | H5: 45291 | I5: 45657 | J5: 46022 | K5: 46387 | L5: 46752 | M5: 47118
B7: Discount Rate | C7: ='Main Page & Assumptions'!D28 -> 0.125 | D7: =C7 -> 0.125 | E7: =D7 -> 0.125 | F7: =E7 -> 0.125 | G7: =F7 -> 0.125 | H7: =G7 -> 0.125 | I7: =H7 -> 0.125 | J7: =I7 -> 0.125 | K7: =J7 -> 0.125 | ... M7: =L7 -> 0.125
B9: EBITDA | C9: ='SLCA Financials (memo)'!D140 -> 369.7 | D9: ='SLCA Financials (memo)'!E140 -> 239.2 | E9: ='SLCA Financials (memo)'!F140 -> 161.7 | F9: ='SLCA Financials (memo)'!G140 -> 201 | G9: ='SLCA Financials (memo)'!H140 -> 327.7 | H9: ='SLCA Financials (memo)'!I140 -> 412.6 | I9: ='SLCA Financials (memo)'!J140 -> 343.01306 | J9: ='SLCA Financials (memo)'!K140 -> 367.36388 | ... M9: ='SLCA Financials (memo)'!N140 -> 408.32032
B11: D&A | C11: ='SLCA Financials (memo)'!D41 -> 148.8 | D11: ='SLCA Financials (memo)'!E41 -> 179.4 | E11: ='SLCA Financials (memo)'!F41 -> 155.6 | F11: ='SLCA Financials (memo)'!G41 -> 161.1 | G11: ='SLCA Financials (memo)'!H41 -> 140.2 | H11: ='SLCA Financials (memo)'!I41 -> 137.3 | I11: ='SLCA Financials (memo)'!J41 -> 146.23333 | J11: ='SLCA Financials (memo)'!K41 -> 146.23333 | ... M11: ='SLCA Financials (memo)'!N41 -> 146.23333
B13: EBIT | C13: =C9-C11 -> 220.9 | D13: =D9-D11 -> 59.8 | E13: =E9-E11 -> 6.1 | F13: =F9-F11 -> 39.9 | G13: =G9-G11 -> 187.5 | H13: =H9-H11 -> 275.3 | I13: =I9-I11 -> 196.77973 | J13: =J9-J11 -> 221.13054 | ... M13: =M9-M11 -> 262.08698
B15: Less: Taxes | C15: =C13*('SLCA Financials (memo)'!D28) -> 58.5385 | D15: =D13*('SLCA Financials (memo)'!E28) -> 15.847 | E15: =E13*('SLCA Financials (memo)'!F28) -> 1.6165 | F15: =F13*('SLCA Financials (memo)'!G28) -> 10.5735 | G15: =G13*('SLCA Financials (memo)'!H28) -> 49.6875 | H15: =H13*('SLCA Financials (memo)'!I28) -> 72.9545 | I15: =I13*('SLCA Financials (memo)'!J28) -> 52.146628 | J15: =J13*('SLCA Financials (memo)'!K28) -> 58.599594 | ... M15: =M13*('SLCA Financials (memo)'!N28) -> 69.453051
B16: Plus: D&A | C16: =C11 -> 148.8 | D16: =D11 -> 179.4 | E16: =E11 -> 155.6 | F16: =F11 -> 161.1 | G16: =G11 -> 140.2 | H16: =H11 -> 137.3 | I16: =I11 -> 146.23333 | J16: =J11 -> 146.23333 | ... M16: =M11 -> 146.23333
B17: Less: Capex | C17: ='SLCA Financials (memo)'!D121*-1 -> 349.861 | D17: ='SLCA Financials (memo)'!E121*-1 -> 122.289 | E17: ='SLCA Financials (memo)'!F121*-1 -> 34.917 | F17: ='SLCA Financials (memo)'!G121*-1 -> 30.517 | G17: ='SLCA Financials (memo)'!H121*-1 -> 53.562 | H17: ='SLCA Financials (memo)'!I121*-1 -> 65.47 | I17: ='SLCA Financials (memo)'!J121*-1 -> 80.231205 | J17: ='SLCA Financials (memo)'!K121*-1 -> 82.890943 | ... M17: ='SLCA Financials (memo)'!N121*-1 -> 91.414884
B18: NWC | C18: ='SLCA Financials (memo)'!D115 -> 149.769 | D18: ='SLCA Financials (memo)'!E115 -> 33.016 | E18: ='SLCA Financials (memo)'!F115 -> 187.282 | F18: ='SLCA Financials (memo)'!G115 -> 148.978 | G18: ='SLCA Financials (memo)'!H115 -> 124.102 | H18: ='SLCA Financials (memo)'!I115 -> 185.479 | I18: ='SLCA Financials (memo)'!J115 -> 159.33275 | J18: ='SLCA Financials (memo)'!K115 -> 166.59141 | ... M18: ='SLCA Financials (memo)'!N115 -> 181.75033
B19: Less: Change NWC | C19: ='SLCA Financials (memo)'!D116 -> 135.156 | D19: ='SLCA Financials (memo)'!E116 -> 83.298 | E19: ='SLCA Financials (memo)'!F116 -> -75.171 | F19: ='SLCA Financials (memo)'!G116 -> 30.387 | G19: ='SLCA Financials (memo)'!H116 -> 5.981 | H19: ='SLCA Financials (memo)'!I116 -> -64.144 | I19: ='SLCA Financials (memo)'!J116 -> 26.146252 | J19: ='SLCA Financials (memo)'!K116 -> -7.2586655 | ... M19: ='SLCA Financials (memo)'!N116 -> -6.0578507
