Workbook

Sheet Cantaloupe Raw
B1: Cantaloupe Inc (USTT)
B2: Income Statement - Annual (As Originally Reported)
C3: Actuals | H3: Forecast(see revenue build)
B4: FYE June | C4: 44377 | D4: 44742 | E4: 45107 | F4: 45473 | G4: 45838 | H4: 46203 | I4: 46568 | J4: 46934 | K4: 47299 | L4: 47664
B5: Currency | C5: USD | D5: USD | E5: USD | F5: USD | G5: USD | H5: USD | I5: USD | J5: USD | K5: USD | L5: USD
B6: Scale | C6: Million | D6: Million | E6: Million | F6: Million | G6: Million | H6: Million | I6: Million | J6: Million | K6: Million | L6: Million
B7: Total Revenue | C7: 166.939 | D7: 205.202 | E7: 243.641 | F7: 268.596 | G7: 302.548 | H7: ='Revenue Build'!I15 -> 339.132 | I7: ='Revenue Build'!J15 -> 371.70749 | J7: ='Revenue Build'!K15 -> 401.70948 | K7: ='Revenue Build'!L15 -> 428.32071 | L7: ='Revenue Build'!M15 -> 449.4371
B8: Year-over-year growth | C8: - | D8: =D7/C7 -1 -> 0.22920348 | E8: =E7/D7 -1 -> 0.18732274 | F8: =F7/E7 -1 -> 0.10242529 | G8: =G7/F7 -1 -> 0.12640546 | H8: =H7/G7 -1 -> 0.12091966 | I8: =I7/H7 -1 -> 0.096055474 | J8: =J7/I7 -1 -> 0.080713993 | K8: =K7/J7 -1 -> 0.066244974 | L8: =L7/K7 -1 -> 0.049300411
B10: Cost of Revenue, Total | C10: 112.913 | D10: 141.007 | E10: 162.405 | F10: 165.945 | G10: 178.724 | H10: =H7*H30 -> 199.07048 | I10: =I7*I30 -> 217.44888 | J10: =J7*J30 -> 232.9915 | K10: =K7*K30 -> 246.28441 | L10: =L7*L30 -> 256.17915
B11: Gross Profit | C11: 54.026 | D11: 64.195 | E11: 81.236 | F11: 102.651 | G11: 123.824 | H11: =H7-H10 -> 140.06152 | I11: =I7-I10 -> 154.25861 | J11: =J7-J10 -> 168.71798 | K11: =K7-K10 -> 182.0363 | L11: =L7-L10 -> 193.25795
B12: Selling/General/Admin. Expenses, Total | C12: 54.724 | D12: 35.927 | E12: 45.853 | F12: 58.705 | G12: 64.25 | H12: =H$7*H31 -> 71.21772 | I12: =I$7*I31 -> 77.315157 | J12: =J$7*J31 -> 82.350443 | K12: =K$7*K31 -> 86.520784 | L12: =L$7*L31 -> 89.88742
B13: Research & Development | C13: 3.9 | D13: 25.377 | E13: 24.226 | F13: 19.532 | G13: 20.349 | H13: =H$7*H32 -> 22.04358 | I13: =I$7*I32 -> 23.789279 | J13: =J$7*J32 -> 25.307697 | K13: =K$7*K32 -> 26.555884 | L13: =L$7*L32 -> 27.415663
B14: Depreciation/Amortization | C14: 4.1 | D14: 4.4 | E14: 7.6 | F14: 10.6 | G14: 15.9 | H14: =H$7*H33 -> 18.313128 | I14: =I$7*I33 -> 19.700497 | J14: =J$7*J33 -> 20.888893 | K14: =K$7*K33 -> 21.844356 | L14: =L$7*L33 -> 22.471855
B15: Interest Exp.(Inc.), Net-Operating, Total
B16: Unusual Expense (Income) | C16: -3.1 | D16: 1.2 | E16: 2.8 | F16: -0.3 | G16: 1 | H16: =H7*H34 -> -0.065038682 | I16: =I7*I34 -> -0.071286003 | J16: =J7*J34 -> -0.077039781 | K16: =K7*K34 -> -0.08214328 | L16: =L7*L34 -> -0.086192977
B17: Other Operating Expenses, Total
B18: Total Operating Expense | C18: 172.6 | D18: 207.9 | E18: 242.9 | F18: 254.4 | G18: 280.2 | H18: 280.2 | I18: =SUM(I12:I14)+I10 -> 338.25381 | J18: =SUM(J12:J14)+J10 -> 361.53853 | K18: =SUM(K12:K14)+K10 -> 381.20544 | L18: =SUM(L12:L14)+L10 -> 395.95409
B19: Operating Income | C19: -5.64 | D19: -2.657 | E19: 0.76 | F19: 14.169 | G19: 22.33 | H19: =H7-H18 -> 58.932 | I19: =I7-I18 -> 33.453674 | J19: =J7-J18 -> 40.170948 | K19: =K7-K18 -> 47.115279 | L19: =L7-L18 -> 53.483015
B21: Operating Margin | C21: =C19/C7 -> -0.033784796 | D21: =D19/D7 -> -0.012948217 | E21: =E19/E7 -> 0.0031193436 | F21: =F19/F7 -> 0.052752089 | G21: =G19/G7 -> 0.07380647 | H21: =H19/H7 -> 0.17377304 | I21: =I19/I7 -> 0.09 | J21: =J19/J7 -> 0.1 | ... L21: =L19/L7 -> 0.119
B22: EBITDA | C22: =C19+C14 -> -1.54 | D22: =D19+D14 -> 1.743 | E22: =E19+E14 -> 8.36 | F22: =F19+F14 -> 24.769 | G22: =G19+G14 -> 38.23 | H22: =H19+H14 -> 77.245128 | I22: =I19+I14 -> 53.15417 | J22: =J19+J14 -> 61.059841 | ... L22: =L19+L14 -> 75.95487
B23: EBITDA Margin | C23: =C22/C7 -> -0.0092249265 | D23: =D22/D7 -> 0.0084940693 | E23: =E22/E7 -> 0.03431278 | F23: =F22/F7 -> 0.092216563 | G23: =G22/G7 -> 0.12636011 | H23: =H22/H7 -> 0.22777304 | I23: =I22/I7 -> 0.143 | J23: =J22/J7 -> 0.152 | ... L23: =L22/L7 -> 0.169
B25: Key Model Drivers
B27: Revenue Drivers | C27: see revenue build model
B29: Cost Drivers
B30: Cost of revenue (% Revenue) | C30: =C10/C7 -> 0.67637281 | D30: =D10/D7 -> 0.68716192 | E30: =E10/E7 -> 0.666575 | F30: =F10/F7 -> 0.61782379 | G30: =G10/G7 -> 0.5907294 | H30: 0.587 | I30: 0.585 | J30: 0.58 | K30: 0.575 | L30: 0.57
B31: SG&A (% of Revenue) | C31: =C12/C$7 -> 0.32780836 | D31: =D12/D$7 -> 0.17508114 | E31: =E12/E$7 -> 0.18819903 | F31: =F12/F$7 -> 0.21856245 | G31: =G12/G$7 -> 0.212363 | H31: 0.21 | I31: 0.208 | J31: 0.205 | K31: 0.202 | L31: 0.2
B32: R&D (% of Revenue) | C32: =C13/C$7 -> 0.023361827 | D32: =D13/D$7 -> 0.12366839 | E32: =E13/E$7 -> 0.099433182 | F32: =F13/F$7 -> 0.072718879 | G32: =G13/G$7 -> 0.067258749 | H32: 0.065 | I32: 0.064 | J32: 0.063 | K32: 0.062 | L32: 0.061
B33: D&A (% of Revenue) | C33: =C14/C$7 -> 0.024559869 | D33: =D14/D$7 -> 0.021442286 | E33: =E14/E$7 -> 0.031193436 | F33: =F14/F$7 -> 0.039464475 | G33: =G14/G$7 -> 0.052553644 | H33: 0.054 | I33: 0.053 | J33: 0.052 | K33: 0.051 | L33: 0.05
B34: Unusual Expense (% of Revenue) | C34: =C16/C7 -> -0.018569657 | D34: =D16/D7 -> 0.0058478962 | E34: =E16/E7 -> 0.011492319 | F34: =F16/F7 -> -0.0011169191 | G34: =G16/G7 -> 0.0033052607 | H34: =-AVERAGE($C$34:$G$34) -> -0.00019177984 | I34: =-AVERAGE($C$34:$G$34) -> -0.00019177984 | J34: =-AVERAGE($C$34:$G$34) -> -0.00019177984 | K34: =-AVERAGE($C$34:$G$34) -> -0.00019177984 | L34: =-AVERAGE($C$34:$G$34) -> -0.00019177984
B36: Cash Flow Drivers
B37: CapEx(% of revenue) | C37: =ABS(C123/C7) -> 0.01101001 | D37: =ABS(D123/D7) -> 0.045126266 | E37: =ABS(E123/E7) -> 0.066290156 | F37: =ABS(F123/F7) -> 0.055603955 | G37: =ABS(G123/G7) -> 0.056199347 | H37: 0.055 | I37: 0.053 | J37: 0.051 | K37: 0.049 | L37: 0.048
B38: NWC (% of revenue) | C38: =C121/C7 -> -0.021828333 | D38: =D121/D7 -> -0.10956521 | E38: =E121/E7 -> -0.026498003 | F38: =F121/F7 -> -0.029132973 | G38: =G121/G7 -> -0.08527903 | H38: =AVERAGE($C$38:$G$38) -> -0.05446071 | I38: =AVERAGE($C$38:$G$38) -> -0.05446071 | J38: =AVERAGE($C$38:$G$38) -> -0.05446071 | K38: =AVERAGE($C$38:$G$38) -> -0.05446071 | L38: =AVERAGE($C$38:$G$38) -> -0.05446071
B44: Historical Items
B46: Interest Inc.(Exp.),Net-Non-Op., Total | C46: -2.9 | D46: 1.4 | E46: 0.2 | F46: -1 | G46: -1.2
B47: Gain (Loss) on Sale of Assets
B48: Other, Net | C48: 0.2 | D48: -0.2 | E48: -0.1 | F48: -0.2 | G48: 1.1
B49: Net Income Before Taxes | C49: -8.335 | D49: -1.517 | E49: 0.814 | F49: 12.978 | G49: 22.181
B50: Provision for Income Taxes | C50: 0.37 | D50: 0.186 | E50: 0.181 | F50: 0.985 | G50: -42.352
B51: Net Income | C51: -8.705 | D51: -1.703 | E51: 0.633 | F51: 11.993 | G51: 64.533
B52: Preferred Dividends | C52: -0.668 | D52: -0.668 | E52: -0.623 | F52: -0.578 | G52: -0.578
...

Sheet Revenue Build
B1: Revenue Build
D2: Actuals | I2: Forecast
B3: FYE June | D3: 44377 | E3: 44742 | F3: 45107 | G3: 45473 | H3: 45838 | I3: 46203 | J3: 46568 | K3: 46934 | L3: 47299 | M3: 47664
B4: Currency | D4: USD | E4: USD | F4: USD | G4: USD | H4: USD | I4: USD | J4: USD | K4: USD | L4: USD | M4: USD
B5: Scale | D5: Million | E5: Million | F5: Million | G5: Million | H5: Million | I5: Million | J5: Million | K5: Million | L5: Million | M5: Million
B6: Transaction Fees | D6: 85.5 | E6: 110.7 | F6: 132.6 | G6: 156.2 | H6: 178.5 | I6: =H6*(1+I7) -> 199.92 | J6: =I6*(1+J7) -> 219.912 | K6: =J6*(1+K7) -> 237.50496 | L6: =K6*(1+L7) -> 251.75526 | M6: =L6*(1+M7) -> 261.82547
B7: Year-over-year Growth | E7: =E6/D6 -1 -> 0.29473684 | F7: =F6/E6 -1 -> 0.19783198 | G7: =G6/F6 -1 -> 0.17797888 | H7: =H6/G6 -1 -> 0.14276569 | I7: 0.12 | J7: 0.1 | K7: 0.08 | L7: 0.06 | M7: 0.04
B8: % of Total Revenue | D8: =D6/D15 -> 0.5122828 | E8: =E6/E15 -> 0.53921091 | F8: =F6/F15 -> 0.54433498 | G8: =G6/G15 -> 0.58153388 | H8: =H6/H15 -> 0.59008264 | I8: =I6/I15 -> 0.58950497 | J8: =J6/J15 -> 0.5916265 | K8: =K6/K15 -> 0.59123564 | ... M8: =M6/M15 -> 0.58256309
B9: Subscription Fees | D9: 53.7 | E9: 58.2 | F9: 67.6 | G9: 75.3 | H9: 84.7 | I9: =H9*(1+I10) -> 94.017 | J9: =I9*(1+J10) -> 103.88879 | K9: =J9*(1+K10) -> 114.38155 | L9: =K9*(1+L10) -> 125.2478 | M9: =L9*(1+M10) -> 135.26762
B10: Year-over-year Growth | E10: =E9/D9 -1 -> 0.083798883 | F10: =F9/E9 -1 -> 0.16151203 | G10: =G9/F9 -1 -> 0.11390533 | H10: =H9/G9 -1 -> 0.124834 | I10: 0.11 | J10: 0.105 | K10: 0.101 | L10: 0.095 | M10: 0.08
B11: % of Total Revenue | D11: =D9/D15 -> 0.32174955 | E11: =E9/E15 -> 0.28348758 | F11: =F9/F15 -> 0.27750411 | G11: =G9/G15 -> 0.28034252 | H11: =H9/H15 -> 0.28 | I11: =I9/I15 -> 0.27722834 | J11: =J9/J15 -> 0.2794907 | K11: =K9/K15 -> 0.284737 | ... M11: =M9/M15 -> 0.3009712
B12: Equipment sales | D12: 27.7 | E12: 36.4 | F12: 43.4 | G12: 37.1 | H12: 39.3 | I12: =H12*(1+I13) -> 45.195 | J12: =I12*(1+J13) -> 47.9067 | K12: =J12*(1+K13) -> 49.822968 | L12: =K12*(1+L13) -> 51.317657 | M12: =L12*(1+M13) -> 52.34401
B13: Year-over-year Growth | E13: =E12/D12 -1 -> 0.31407942 | F13: =F12/E12 -1 -> 0.19230769 | G13: =G12/F12 -1 -> -0.14516129 | H13: =H12/G12 -1 -> 0.059299191 | I13: 0.15 | J13: 0.06 | K13: 0.04 | L13: 0.03 | M13: 0.02
B14: % of Total Revenue | D14: =D12/D15 -> 0.16596765 | E14: =E12/E15 -> 0.17730151 | F14: =F12/F15 -> 0.17816092 | G14: =G12/G15 -> 0.1381236 | H14: =H12/H15 -> 0.12991736 | I14: =I12/I15 -> 0.13326669 | J14: =J12/J15 -> 0.1288828 | K14: =K12/K15 -> 0.12402736 | ... M14: =M12/M15 -> 0.11646571
B15: Total Revenue | D15: =SUM(D9+D12+D6) -> 166.9 | E15: =SUM(E9+E12+E6) -> 205.3 | F15: =SUM(F9+F12+F6) -> 243.6 | G15: =SUM(G9+G12+G6) -> 268.6 | H15: =SUM(H9+H12+H6) -> 302.5 | I15: =SUM(I9+I12+I6) -> 339.132 | J15: =SUM(J9+J12+J6) -> 371.70749 | K15: =SUM(K9+K12+K6) -> 401.70948 | ... M15: =SUM(M9+M12+M6) -> 449.4371
B16: Year-over-year Growth | E16: =E15/D15 - 1 -> 0.23007789 | F16: =F15/E15 - 1 -> 0.18655626 | G16: =G15/F15 - 1 -> 0.10262726 | H16: =H15/G15 - 1 -> 0.12620998 | I16: =I15/H15 - 1 -> 0.12109752 | J16: =J15/I15 - 1 -> 0.096055474 | K16: =K15/J15 - 1 -> 0.080713993 | L16: =L15/K15 - 1 -> 0.066244974 | M16: =M15/L15 - 1 -> 0.049300411

Sheet DCF
B1: Cantaloupe Inc DCF Valuation
G2: (in millions)
G4: 2026 | H4: 2027 | I4: 2028 | J4: 2029 | K4: 2030 | M4: Enterprise Value Calculation
B5: Tax Rate | G5: 0.21 | H5: =G5 -> 0.21 | I5: =H5 -> 0.21 | J5: =I5 -> 0.21 | K5: =J5 -> 0.21 | M5: Free Cash Flow - 2030 | N5: =K19 -> 67.62712
B6: Discount Rate | G6: 0.1 | H6: =G6 -> 0.1 | I6: =G6 -> 0.1 | J6: =G6 -> 0.1 | K6: =G6 -> 0.1 | M6: Growth Rate | N6: 0.03
M7: Discount Rate | N7: =K6 -> 0.1
G8: Forecast Period | M8: Terminal Value @ end of 2030 | N8: =N5*(1+N6)/(N7-N6) -> 995.08476
M9: Discount Period | N9: =K21+0.5 -> 5
G10: 2026 | H10: 2027 | I10: 2028 | J10: 2029 | K10: 2030 | M10: Discount Factor | N10: =1/(1+K6)^N9 -> 0.62092132
M11: Present Value of Terminal Value | N11: =N8*N10 -> 617.86935
B12: Operating Income | G12: ='Cantaloupe Raw'!H19 -> 58.932 | H12: ='Cantaloupe Raw'!I19 -> 33.453674 | I12: ='Cantaloupe Raw'!J19 -> 40.170948 | J12: ='Cantaloupe Raw'!K19 -> 47.115279 | K12: ='Cantaloupe Raw'!L19 -> 53.483015 | M12: Warranted Enterprise Value | N12: =N11+SUM(G23:K23) -> 850.59002
B14: Less: Taxes | G14: =G12*G5 -> 12.37572 | H14: =H12*H5 -> 7.0252715 | I14: =I12*I5 -> 8.4358991 | J14: =J12*J5 -> 9.8942085 | K14: =K12*K5 -> 11.231433
B15: Less: Capitalized Expenditures | G15: ='Cantaloupe Raw'!H7*'Cantaloupe Raw'!H37 -> 18.65226 | H15: ='Cantaloupe Raw'!I7*'Cantaloupe Raw'!I37 -> 19.700497 | I15: ='Cantaloupe Raw'!J7*'Cantaloupe Raw'!J37 -> 20.487183 | J15: ='Cantaloupe Raw'!K7*'Cantaloupe Raw'!K37 -> 20.987715 | K15: ='Cantaloupe Raw'!L7*'Cantaloupe Raw'!L37 -> 21.572981 | M15: Enterprise Value to Equity Value
M16: Enterprise value | N16: =N12 -> 850.59002
B17: Plus: D&A | G17: ='Cantaloupe Raw'!H14 -> 18.313128 | H17: ='Cantaloupe Raw'!I14 -> 19.700497 | I17: ='Cantaloupe Raw'!J14 -> 20.888893 | J17: ='Cantaloupe Raw'!K14 -> 21.844356 | K17: ='Cantaloupe Raw'!L14 -> 22.471855 | M17: Add: Cash | N17: ='Cantaloupe Raw'!G69 -> 51.146
B18: Less: Changes in Net Oprating Assets | G18: ='Cantaloupe Raw'!H38*'Cantaloupe Raw'!H7 -> -18.469369 | H18: ='Cantaloupe Raw'!I38*'Cantaloupe Raw'!I7 -> -20.243453 | I18: ='Cantaloupe Raw'!J38*'Cantaloupe Raw'!J7 -> -21.877383 | J18: ='Cantaloupe Raw'!K38*'Cantaloupe Raw'!K7 -> -23.32665 | K18: ='Cantaloupe Raw'!L38*'Cantaloupe Raw'!L7 -> -24.476663 | M18: Less: Total Debt | N18: ='Cantaloupe Raw'!G93 -> 36.7
B19: Free Cash Flow | G19: =G12-G14-G15+G17-G18 -> 64.686517 | H19: =H12-H14-H15+H17-H18 -> 46.671856 | I19: =I12-I14-I15+I17-I18 -> 54.014142 | J19: =J12-J14-J15+J17-J18 -> 61.404362 | K19: =K12-K14-K15+K17-K18 -> 67.62712 | M19: Less: Preferred Stock | N19: 23.3
M20: Implied Common Equity Value | N20: =N16-SUM(N18:N19)+N17 -> 841.73602
B21: Discount Period (mid period convention) | G21: 0.5 | H21: =G21+1 -> 1.5 | I21: =H21+1 -> 2.5 | J21: =I21+1 -> 3.5 | K21: =J21+1 -> 4.5 | M21: Diluted Shares | N21: ='Cantaloupe Raw'!G60 -> 75
B22: Discount Factor | G22: =1/(1+G6)^G21 -> 0.95346259 | H22: =1/(1+H6)^H21 -> 0.86678417 | I22: =1/(1+I6)^I21 -> 0.78798561 | J22: =1/(1+J6)^J21 -> 0.71635056 | K22: =1/(1+K6)^K21 -> 0.65122778 | M22: Implied Share Price | N22: =N20/N21 -> 11.223147
B23: Present Value of Free Cash Flows | G23: =G19*G22 -> 61.676174 | H23: =H19*H22 -> 40.454426 | I23: =I19*I22 -> 42.562366 | J23: =J19*J22 -> 43.987048 | K23: =K19*K22 -> 44.040659
