Workbook

Sheet Table of Contents
B2: Table of Contents
B4: =HYPERLINK("#'Assumptions Tab'!A1","Assumptions Tab") -> Assumptions Tab
B5: =HYPERLINK("#'Sources And Uses'!A1","Sources And Uses") -> Sources And Uses
B6: =HYPERLINK("#'H.B. Fuller Operating'!A1","H.B. Fuller BAS Operating") -> H.B. Fuller BAS Operating
B7: =HYPERLINK("#'Bas Carveout'!A1","BAS Carveout") -> BAS Carveout
B8: =HYPERLINK("#'Debt Schedule'!A1","Debt Schedule") -> Debt Schedule
B10: =HYPERLINK("#'LBO Returns Exit'!A1","LBO Returns Exit") -> LBO Returns Exit
B11: =HYPERLINK("#'Seller Impact'!A1","Seller Impact") -> Seller Impact
B13: =HYPERLINK("#'Comps'!A1","Precedent Transaction Analysis") -> Precedent Transaction Analysis

Sheet Assumptions Tab
A1: =HYPERLINK("#'Table of Contents'!A1","<--------") -> <--------
B2: Transaction Assumptions
B4: Transaction Toggle | F4: 1 = downside | G4: 2 = base | H4: 3 = upside
B5: Scenario Toggle | C5: 2
B8: Operating Assumptions | D8: 1 | J8: 2 | P8: 3
D9: Downside | J9: Base | P9: Upside
D10: 2026 | E10: 2027 | F10: 2028 | G10: 2029 | H10: 2030 | I10: 2031 | J10: 2026 | K10: 2027 | L10: 2028 | M10: 2029 | N10: 2030 | O10: 2031 | P10: 2026 | Q10: 2027 | R10: 2028 | S10: 2029 | T10: 2030 | U10: 2031
B11: Revenue Growth | D11: 0.01 | E11: 0.015 | F11: 0.02 | G11: 0.02 | H11: 0.02 | I11: 0.02 | J11: 0.04 | K11: 0.04 | L11: 0.035 | M11: 0.035 | N11: 0.03 | O11: 0.03 | P11: 0.06 | Q11: 0.05 | R11: 0.05 | S11: 0.04 | T11: 0.04 | U11: 0.035
B12: EBITDA Margin | D12: 0.14 | E12: 0.142 | F12: 0.145 | G12: 0.148 | H12: 0.15 | I12: 0.15 | J12: 0.16 | K12: 0.163 | L12: 0.166 | M12: 0.168 | N12: 0.17 | O12: 0.17 | P12: 0.17 | Q12: 0.173 | R12: 0.175 | S12: 0.178 | T12: 0.18 | U12: 0.18
B13: D&A as & of Revenue | D13: 0.055 | E13: 0.055 | F13: 0.055 | G13: 0.055 | H13: 0.055 | I13: 0.055 | J13: 0.06 | K13: 0.06 | L13: 0.06 | M13: 0.06 | N13: 0.06 | O13: 0.06 | P13: 0.065 | Q13: 0.065 | R13: 0.065 | S13: 0.065 | T13: 0.065 | U13: 0.065
B14: Capex as % of Revenue | D14: 0.025 | E14: 0.025 | F14: 0.025 | G14: 0.025 | H14: 0.025 | I14: 0.025 | J14: 0.03 | K14: 0.03 | L14: 0.03 | M14: 0.03 | N14: 0.03 | O14: 0.03 | P14: 0.035 | Q14: 0.035 | R14: 0.035 | S14: 0.035 | T14: 0.035 | U14: 0.035
B15: NWC as % of Revenue | D15: 0.18 | E15: 0.18 | F15: 0.18 | G15: 0.18 | H15: 0.18 | I15: 0.18 | J15: 0.165 | K15: 0.165 | L15: 0.165 | M15: 0.165 | N15: 0.165 | O15: 0.165 | P15: 0.15 | Q15: 0.15 | R15: 0.15 | S15: 0.15 | T15: 0.15 | U15: 0.15
B16: Tax Rate | D16: 0.265 | E16: =$D$16 -> 0.265 | F16: =$D$16 -> 0.265 | G16: =$D$16 -> 0.265 | H16: =$D$16 -> 0.265 | I16: =$D$16 -> 0.265 | J16: =$D$16 -> 0.265 | K16: =$D$16 -> 0.265 | L16: =$D$16 -> 0.265 | ... U16: =$D$16 -> 0.265
B18: Multiple (from Comps) | D18: =QUARTILE('Precedent Transactions'!C9:C12,1)*(1-$I$28) -> 9.444375 | J18: =MEDIAN('Precedent Transactions'!C9:C12)*(1-$I$28) -> 10.81125 | P18: =QUARTILE('Precedent Transactions'!C9:C12,3)*(1-$I$28) -> 11.679375
D24: Transaction Assumptions | G24: Other Assumptions | N24: SEC Filings notes: H1'26 BAS =4.7% YoY(6.2% increase Q2), Q2 Margins 16.9%,
D25: actual EV | F25: 1200 | G25: Minimum Cash | I25: 25 | J25: (3% annual revenue)
D26: Base EBITDA Multiple | F26: =F25/'H.B. Fuller BAS Operating'!F10 -> 10.033109 | G26: Seperation Costs | I26: =SUM('BAS Carveout'!C33:H33) -> 37.5
D27: Transaction Fees | F27: 0.01 | G27: Cash At Close | I27: =I25 -> 25 | J27: read writeup - carve out
D28: Holding Period | F28: 5 | G28: Precedent Discount | I28: 0.25 | J28: read writeup - carve out
D30: Manual Multiple Toggle | F30: 1 | G30: Target IRR | I30: 0.18
D31: Entry EBITDA Multiple | F31: ='LBO Returns Exit'!K3 -> 8.2
D32: Exit EBITDA Multiple | F32: ='LBO Returns Exit'!K4 -> 8.2

Sheet H.B. Fuller BAS Operating
A1: =HYPERLINK("#'Table of Contents'!A1","<--------") -> <--------
B2: ='Assumptions Tab'!C5 -> 2
B3: H.B. Fuller BAS
B4: Consolidated Financials
C5: Actual | F5: Predicted
B6: FYE December | C6: 2023 | D6: 2024 | E6: 2025 | F6: 2026 | G6: 2027 | H6: 2028 | I6: 2029 | J6: 2030 | K6: 2031
B7: Revenue | C7: 777.5 | D7: 856.5 | E7: 860 | F7: =E7*(1+F28) -> 894.4 | G7: =F7*(1+G28) -> 930.176 | H7: =G7*(1+H28) -> 962.73216 | I7: =H7*(1+I28) -> 996.42779 | J7: =I7*(1+J28) -> 1026.3206 | K7: =J7*(1+K28) -> 1057.1102
B8: Revenue Growth | D8: =D28 -> 0.102 | E8: =E28 -> 0.004 | F8: =F28 -> 0.04 | G8: =G28 -> 0.04 | H8: =H28 -> 0.035 | I8: =I28 -> 0.035 | J8: =J28 -> 0.03 | K8: =K28 -> 0.03
B9: Reported Adjusted EBITDA | C9: 107.1 | D9: 133.2 | E9: 137.7 | F9: =F7*F29 -> 143.104 | G9: =G7*G29 -> 151.61869 | H9: =H7*H29 -> 159.81354 | I9: =I7*I29 -> 167.39987 | J9: =J7*J29 -> 174.47451 | K9: =K7*K29 -> 179.70874
B10: Standalone Adjusted EBITDA | F10: ='BAS Carveout'!C23 -> 119.604 | G10: ='BAS Carveout'!D23 -> 132.61869 | H10: ='BAS Carveout'!E23 -> 146.31354 | I10: ='BAS Carveout'!F23 -> 158.89987 | J10: ='BAS Carveout'!G23 -> 170.47451 | K10: ='BAS Carveout'!H23 -> 177.20874 | L10: see writeup
B11: EBITDA Margin | C11: =C29 -> 0.138 | D11: =D29 -> 0.155 | E11: =E29 -> 0.156 | F11: ='BAS Carveout'!C24 -> 0.1337254 | G11: ='BAS Carveout'!D24 -> 0.14257376 | H11: ='BAS Carveout'!E24 -> 0.15197741 | I11: ='BAS Carveout'!F24 -> 0.15946953 | J11: ='BAS Carveout'!G24 -> 0.16610258 | K11: ='BAS Carveout'!H24 -> 0.16763506
B13: D&A | C13: 56 | D13: 49.9 | E13: 51.5 | F13: =F7*F30 -> 53.664 | G13: =G7*G30 -> 55.81056 | H13: =H7*H30 -> 57.76393 | I13: =I7*I30 -> 59.785667 | J13: =J7*J30 -> 61.579237 | K13: =K7*K30 -> 63.426614
B14: Memo: reported EBIT | C14: 51 | D14: 83.3 | E14: 82.5 | F14: =F9-F13 -> 89.44 | G14: =G9-G13 -> 95.808128 | H14: =H9-H13 -> 102.04961 | I14: =I9-I13 -> 107.6142 | J14: =J9-J13 -> 112.89527 | K14: =K9-K13 -> 116.28213
B15: Standalone EBIT | C15: 51 | D15: 83.3 | E15: 82.5 | F15: =F$10-F$13 -> 65.94 | G15: =G$10-G$13 -> 76.808128 | H15: =H$10-H$13 -> 88.549609 | I15: =I$10-I$13 -> 99.114201 | J15: =J$10-J$13 -> 108.89527 | K15: =K$10-K$13 -> 113.78213
B16: Capex | D16: 36.7 | E16: 18.4 | F16: =F7*F31 -> 26.832 | G16: =G7*G31 -> 27.90528 | H16: =H7*H31 -> 28.881965 | I16: =I7*I31 -> 29.892834 | J16: =J7*J31 -> 30.789619 | K16: =K7*K31 -> 31.713307
B17: NWC | C17: 128.3 | D17: 141.3 | E17: 141.9 | F17: =F32*F7 -> 147.576 | G17: =G32*G7 -> 153.47904 | H17: =H32*H7 -> 158.85081 | I17: =I32*I7 -> 164.41058 | J17: =J32*J7 -> 169.3429 | K17: =K32*K7 -> 174.42319
B18: Change in NWC | D18: 13 | E18: 0.6 | F18: 4.3 | G18: 5.8 | H18: 6.1 | I18: 5.5 | J18: 4.9 | K18: 5.1
B19: Cash Taxes | D19: 22.1 | E19: 21.9 | F19: 23.5 | G19: 25.6 | H19: 27.9 | I19: 29.6 | J19: 31.1 | K19: 32.1
B21: One- Time Costs | F21: ='BAS Carveout'!C$33 -> 33 | G21: ='BAS Carveout'!D$33 -> 4.5 | H21: ='BAS Carveout'!E$33 -> 0 | I21: ='BAS Carveout'!F$33 -> 0 | J21: ='BAS Carveout'!G$33 -> 0 | K21: ='BAS Carveout'!H$33 -> 0 | L21: see writeup
B23: Unlevered FCF | D23: =D15-D19+D13-D16-D18 -> 61.4 | E23: =E15-E19+E13-E16-E18 -> 93.1 | F23: =F15-F19+F13-F16-F18-F21 -> 31.972 | G23: =G15-G19+G13-G16-G18-G21 -> 68.813408 | H23: =H15-H19+H13-H16-H18-H21 -> 83.431574 | I23: =I15-I19+I13-I16-I18-I21 -> 93.907034 | J23: =J15-J19+J13-J16-J18-J21 -> 103.68489 | K23: =K15-K19+K13-K16-K18-K21 -> 108.29543
B26: Model Drivers
B28: Revenue Growth | D28: 0.102 | E28: 0.004 | F28: =CHOOSE($B$2,'Assumptions Tab'!D11,'Assumptions Tab'!J11,'Assumptions Tab'!P11) -> 0.04 | G28: =CHOOSE($B$2,'Assumptions Tab'!E11,'Assumptions Tab'!K11,'Assumptions Tab'!Q11) -> 0.04 | H28: =CHOOSE($B$2,'Assumptions Tab'!F11,'Assumptions Tab'!L11,'Assumptions Tab'!R11) -> 0.035 | I28: =CHOOSE($B$2,'Assumptions Tab'!G11,'Assumptions Tab'!M11,'Assumptions Tab'!S11) -> 0.035 | J28: =CHOOSE($B$2,'Assumptions Tab'!H11,'Assumptions Tab'!N11,'Assumptions Tab'!T11) -> 0.03 | K28: =CHOOSE($B$2,'Assumptions Tab'!I11,'Assumptions Tab'!O11,'Assumptions Tab'!U11) -> 0.03
B29: EBITDA Margin | C29: 0.138 | D29: 0.155 | E29: 0.156 | F29: =CHOOSE($B$2,'Assumptions Tab'!D12,'Assumptions Tab'!J12,'Assumptions Tab'!P12) -> 0.16 | G29: =CHOOSE($B$2,'Assumptions Tab'!E12,'Assumptions Tab'!K12,'Assumptions Tab'!Q12) -> 0.163 | H29: =CHOOSE($B$2,'Assumptions Tab'!F12,'Assumptions Tab'!L12,'Assumptions Tab'!R12) -> 0.166 | I29: =CHOOSE($B$2,'Assumptions Tab'!G12,'Assumptions Tab'!M12,'Assumptions Tab'!S12) -> 0.168 | J29: =CHOOSE($B$2,'Assumptions Tab'!H12,'Assumptions Tab'!N12,'Assumptions Tab'!T12) -> 0.17 | K29: =CHOOSE($B$2,'Assumptions Tab'!I12,'Assumptions Tab'!O12,'Assumptions Tab'!U12) -> 0.17
B30: D&A as % of revenue | C30: =C13/C7 -> 0.072025723 | D30: =D13/D7 -> 0.058260362 | E30: =E13/E7 -> 0.059883721 | F30: =CHOOSE($B$2,'Assumptions Tab'!D13,'Assumptions Tab'!J13,'Assumptions Tab'!P13) -> 0.06 | G30: =CHOOSE($B$2,'Assumptions Tab'!E13,'Assumptions Tab'!K13,'Assumptions Tab'!Q13) -> 0.06 | H30: =CHOOSE($B$2,'Assumptions Tab'!F13,'Assumptions Tab'!L13,'Assumptions Tab'!R13) -> 0.06 | I30: =CHOOSE($B$2,'Assumptions Tab'!G13,'Assumptions Tab'!M13,'Assumptions Tab'!S13) -> 0.06 | J30: =CHOOSE($B$2,'Assumptions Tab'!H13,'Assumptions Tab'!N13,'Assumptions Tab'!T13) -> 0.06 | K30: =CHOOSE($B$2,'Assumptions Tab'!I13,'Assumptions Tab'!O13,'Assumptions Tab'!U13) -> 0.06
B31: Capex as % of revenue | D31: =D16/D7 -> 0.042848803 | E31: =E16/E7 -> 0.021395349 | F31: =CHOOSE($B$2,'Assumptions Tab'!D14,'Assumptions Tab'!J14,'Assumptions Tab'!P14) -> 0.03 | G31: =CHOOSE($B$2,'Assumptions Tab'!E14,'Assumptions Tab'!K14,'Assumptions Tab'!Q14) -> 0.03 | H31: =CHOOSE($B$2,'Assumptions Tab'!F14,'Assumptions Tab'!L14,'Assumptions Tab'!R14) -> 0.03 | I31: =CHOOSE($B$2,'Assumptions Tab'!G14,'Assumptions Tab'!M14,'Assumptions Tab'!S14) -> 0.03 | J31: =CHOOSE($B$2,'Assumptions Tab'!H14,'Assumptions Tab'!N14,'Assumptions Tab'!T14) -> 0.03 | K31: =CHOOSE($B$2,'Assumptions Tab'!I14,'Assumptions Tab'!O14,'Assumptions Tab'!U14) -> 0.03
B32: NWC as % of revenue | C32: =C17/C7 -> 0.16501608 | D32: =D17/D7 -> 0.16497373 | E32: =E17/E7 -> 0.165 | F32: =CHOOSE($B$2,'Assumptions Tab'!D15,'Assumptions Tab'!J15,'Assumptions Tab'!P15) -> 0.165 | G32: =CHOOSE($B$2,'Assumptions Tab'!E15,'Assumptions Tab'!K15,'Assumptions Tab'!Q15) -> 0.165 | H32: =CHOOSE($B$2,'Assumptions Tab'!F15,'Assumptions Tab'!L15,'Assumptions Tab'!R15) -> 0.165 | I32: =CHOOSE($B$2,'Assumptions Tab'!G15,'Assumptions Tab'!M15,'Assumptions Tab'!S15) -> 0.165 | J32: =CHOOSE($B$2,'Assumptions Tab'!H15,'Assumptions Tab'!N15,'Assumptions Tab'!T15) -> 0.165 | K32: =CHOOSE($B$2,'Assumptions Tab'!I15,'Assumptions Tab'!O15,'Assumptions Tab'!U15) -> 0.165
B33: Tax Rate | C33: 0.265 | D33: =C33 -> 0.265 | E33: =D33 -> 0.265 | F33: =CHOOSE($B$2,'Assumptions Tab'!D16,'Assumptions Tab'!J16,'Assumptions Tab'!P16) -> 0.265 | G33: =CHOOSE($B$2,'Assumptions Tab'!E16,'Assumptions Tab'!K16,'Assumptions Tab'!Q16) -> 0.265 | H33: =CHOOSE($B$2,'Assumptions Tab'!F16,'Assumptions Tab'!L16,'Assumptions Tab'!R16) -> 0.265 | I33: =CHOOSE($B$2,'Assumptions Tab'!G16,'Assumptions Tab'!M16,'Assumptions Tab'!S16) -> 0.265 | J33: =CHOOSE($B$2,'Assumptions Tab'!H16,'Assumptions Tab'!N16,'Assumptions Tab'!T16) -> 0.265 | K33: =CHOOSE($B$2,'Assumptions Tab'!I16,'Assumptions Tab'!O16,'Assumptions Tab'!U16) -> 0.265

Sheet BAS Carveout
A1: =HYPERLINK("#'Table of Contents'!A1","<--------") -> <--------
B2: Carve Out Adjustments
B3: ($mm)
C4: Predicted
B5: FYE December | C5: 2026 | D5: 2027 | E5: 2028 | F5: 2029 | G5: 2030 | H5: 2031
B6: 1. PROJECTED SEGMENT EBITDA
B7: Reported EBITDA | C7: ='H.B. Fuller BAS Operating'!F$9 -> 143.104 | D7: ='H.B. Fuller BAS Operating'!G$9 -> 151.61869 | E7: ='H.B. Fuller BAS Operating'!H$9 -> 159.81354 | F7: ='H.B. Fuller BAS Operating'!I$9 -> 167.39987 | G7: ='H.B. Fuller BAS Operating'!J$9 -> 174.47451 | H7: ='H.B. Fuller BAS Operating'!K$9 -> 179.70874
B9: 2. LESS RUN-RATE ADJUSTMENTS
B10: Corporate Functions to be Replaced | C10: =SUM(C11:C16) -> -18.5 | D10: =SUM(D11:D16) -> -18.5 | E10: =SUM(E11:E16) -> -18.5 | F10: =SUM(F11:F16) -> -18.5 | G10: =SUM(G11:G16) -> -18.5 | H10: =SUM(H11:H16) -> -18.5
B11: Finance/Accounting | C11: -4 | D11: -4 | E11: -4 | F11: -4 | G11: -4 | H11: -4
B12: HR / Payroll | C12: -3 | D12: -3 | E12: -3 | F12: -3 | G12: -3 | H12: -3
B13: IT / Systems | C13: -6.5 | D13: -6.5 | E13: -6.5 | F13: -6.5 | G13: -6.5 | H13: -6.5
B14: Legal / Compliance | C14: -2 | D14: -2 | E14: -2 | F14: -2 | G14: -2 | H14: -2
B15: Treasury | C15: -1 | D15: -1 | E15: -1 | F15: -1 | G15: -1 | H15: -1
B16: other | C16: -2 | D16: -2 | E16: -2 | F16: -2 | G16: -2 | H16: -2
B17: TSA Costs | C17: -5.5 | D17: -4 | E17: -2.5 | F17: -1 | G17: 0 | H17: 0
B18: Dis-Synergy Costs | C18: -7.5 | D18: -6.5 | E18: -4.5 | F18: -3 | G18: -1.5 | H18: 0
B19: Cost Savings | C19: 8 | D19: 10 | E19: 12 | F19: 14 | G19: 16 | H19: 16
B20: Total Run-Rate Adjustments | C20: =C10+C17+C18+C19 -> -23.5 | D20: =D10+D17+D18+D19 -> -19 | E20: =E10+E17+E18+E19 -> -13.5 | F20: =F10+F17+F18+F19 -> -8.5 | G20: =G10+G17+G18+G19 -> -4 | H20: =H10+H17+H18+H19 -> -2.5
B22: 3. STANDALONE ADJUSTED EBITDA
B23: Adjusted Ebitda | C23: =C7+C20 -> 119.604 | D23: =D7+D20 -> 132.61869 | E23: =E7+E20 -> 146.31354 | F23: =F7+F20 -> 158.89987 | G23: =G7+G20 -> 170.47451 | H23: =H7+H20 -> 177.20874
B24: EBITDA Margin | C24: =C23/'H.B. Fuller BAS Operating'!F7 -> 0.1337254 | D24: =D23/'H.B. Fuller BAS Operating'!G7 -> 0.14257376 | E24: =E23/'H.B. Fuller BAS Operating'!H7 -> 0.15197741 | F24: =F23/'H.B. Fuller BAS Operating'!I7 -> 0.15946953 | G24: =G23/'H.B. Fuller BAS Operating'!J7 -> 0.16610258 | H24: =H23/'H.B. Fuller BAS Operating'!K7 -> 0.16763506
B26: 4. ONE TIME SEPERATION COSTS
B27: IT / Systems | C27: 15 | D27: 2.5 | E27: 0 | F27: 0 | G27: 0 | H27: 0
B28: Legal | C28: 5 | D28: 0.5 | E28: 0 | F28: 0 | G28: 0 | H28: 0
B29: People / HR | C29: 6 | D29: 1 | E29: 0 | F29: 0 | G29: 0 | H29: 0
B30: Facilities | C30: 3 | D30: 0.5 | E30: 0 | F30: 0 | G30: 0 | H30: 0
B31: Branding / Rebrand | C31: 2 | D31: 0 | E31: 0 | F31: 0 | G31: 0 | H31: 0
B32: Other | C32: 2 | D32: 0 | E32: 0 | F32: 0 | G32: 0 | H32: 0
B33: Total One-Time Seperation Costs | C33: =SUM(C27:C32) -> 33 | D33: =SUM(D27:D32) -> 4.5 | E33: =SUM(E27:E32) -> 0 | F33: =SUM(F27:F32) -> 0 | G33: =SUM(G27:G32) -> 0 | H33: =SUM(H27:H32) -> 0

Sheet Sources And Uses
A1: =HYPERLINK("#'Table of Contents'!A1","<--------") -> <--------
B4: Sources and Uses($mm)
B5: Purchase Price
B6: Entry EBITDA | C6: ='H.B. Fuller BAS Operating'!F10 -> 119.604
B7: Entry Multiple | C7: =C9/C6 -> 10.033109
B9: Enterprise Value | C9: ='Assumptions Tab'!F25 -> 1200
B11: Uses
B12: Purchase of BAS | C12: =C9 -> 1200
B13: Transaction Fees | C13: =C12*'Assumptions Tab'!F27 -> 12
B14: Seperation Costs | C14: ='Assumptions Tab'!I26 -> 37.5
B15: Minimum Cash | C15: ='Assumptions Tab'!I25 -> 25
B17: Total Uses | C17: =SUM(C12:C15) -> 1274.5
B20: Sources
B21: Senior Debt | C21: ='Debt Schedule'!D5 -> 556.1586
B22: Junior Debt | C22: ='Debt Schedule'!D6 -> 149.505
B23: Debt / Total Cap | C23: =SUM(C21:C22)/SUM(C21+C22+C24) -> 0.55367878
B24: Sponsor Equity | C24: =C17-SUM(C21:C22) -> 568.8364
B26: Total Sources | C26: =SUM(C21:C24)-C23 -> 1274.5
B27: Sources - Uses | C27: =C17-C26 -> 0
B30: Sponsor Equity % | C30: =C24/C26 -> 0.44632122
B31: Debt / EBITDA | C31: =SUM(C21:C22)/C6 -> 5.9

Sheet Debt Schedule
A1: =HYPERLINK("#'Table of Contents'!A1","<--------") -> <--------
B2: Debt Schedule ($MM)
B3: Debt Assumptions
B4: Instrument | C4: Debt Type | D4: Initial Balance | E4: Interest Rate | F4: Mandatory Amoritization(%)
B5: Senior Debt | C5: Senior | D5: ='H.B. Fuller BAS Operating'!F10*4.65 -> 556.1586 | E5: 0.07 | F5: 0.02
B6: Junior / Mezz | C6: Mezzanine | D6: ='H.B. Fuller BAS Operating'!F10*1.25 -> 149.505 | E6: 0.1 | F6: 0
B7: Revolver | C7: Revolver | D7: 0 | E7: 0.065 | F7: 0
B9: Other Assupmtions
B10: Mininmum Cash | C10: ='Assumptions Tab'!I25 -> 25
B11: Cash Sweep % | C11: 1
B12: Revolver Commitment
B13: Revolver Margin
B15: Debt Schedule
C16: 2026 | D16: =C16+1 -> 2027 | E16: =D16+1 -> 2028 | F16: =E16+1 -> 2029 | G16: =F16+1 -> 2030 | H16: =G16+1 -> 2031
B17: Senior Term Loan
B18: Beginning Balance | C18: =$D$5 -> 556.1586 | D18: =C22 -> 545.03543 | E18: =D22 -> 533.91226 | F18: =E22 -> 499.80068 | G18: =F22 -> 444.70702 | H18: =G22 -> 375.97895
B19: New Borrowing | C19: 0 | D19: 0 | E19: 0 | F19: 0 | G19: 0 | H19: 0
B20: Mandatory Repayment | C20: =MIN(C18+C19,$D$5*N($F$5)) -> 11.123172 | D20: =MIN(D18+D19,$D$5*N($F$5)) -> 11.123172 | E20: =MIN(E18+E19,$D$5*N($F$5)) -> 11.123172 | F20: =MIN(F18+F19,$D$5*N($F$5)) -> 11.123172 | G20: =MIN(G18+G19,$D$5*N($F$5)) -> 11.123172 | H20: =MIN(H18+H19,$D$5*N($F$5)) -> 11.123172
B21: Cash Sweep | C21: =MIN(C18+C19-C20,MAX(0,C51*$C$11-C39)) -> 0 | D21: =MIN(D18+D19-D20,MAX(0,D51*$C$11-D39)) -> 0 | E21: =MIN(E18+E19-E20,MAX(0,E51*$C$11-E39)) -> 22.988403 | F21: =MIN(F18+F19-F20,MAX(0,F51*$C$11-F39)) -> 43.970487 | G21: =MIN(G18+G19-G20,MAX(0,G51*$C$11-G39)) -> 57.604895 | H21: =MIN(H18+H19-H20,MAX(0,H51*$C$11-H39)) -> 67.026406
B22: Ending Bal | C22: =C18+C19-C20-C21 -> 545.03543 | D22: =D18+D19-D20-D21 -> 533.91226 | E22: =E18+E19-E20-E21 -> 499.80068 | F22: =F18+F19-F20-F21 -> 444.70702 | G22: =G18+G19-G20-G21 -> 375.97895 | H22: =H18+H19-H20-H21 -> 297.82938
B23: Average Bal | C23: =(C18+C22)/2 -> 550.59701 | D23: =(D18+D22)/2 -> 539.47384 | E23: =(E18+E22)/2 -> 516.85647 | F23: =(F18+F22)/2 -> 472.25385 | G23: =(G18+G22)/2 -> 410.34299 | H23: =(H18+H22)/2 -> 336.90417
B24: Cash Interest | C24: =C18*$E$5 -> 38.931102 | D24: =D18*$E$5 -> 38.15248 | E24: =E18*$E$5 -> 37.373858 | F24: =F18*$E$5 -> 34.986048 | G24: =G18*$E$5 -> 31.129492 | H24: =H18*$E$5 -> 26.318527
B26: Junior / Mezz
B27: Beginning Balance | C27: =$D$6 -> 149.505 | D27: =C31 -> 149.505 | E27: =D31 -> 149.505 | F27: =E31 -> 149.505 | G27: =F31 -> 149.505 | H27: =G31 -> 149.505
B28: New Borrowing | C28: 0 | D28: 0 | E28: 0 | F28: 0 | G28: 0 | H28: 0
B29: Mandatory Repayment | C29: =MIN(C27+C28,$D$6*N($F$6)) -> 0 | D29: =MIN(D27+D28,$D$6*N($F$6)) -> 0 | E29: =MIN(E27+E28,$D$6*N($F$6)) -> 0 | F29: =MIN(F27+F28,$D$6*N($F$6)) -> 0 | G29: =MIN(G27+G28,$D$6*N($F$6)) -> 0 | H29: =MIN(H27+H28,$D$6*N($F$6)) -> 0
B30: Cash Sweep | C30: =MIN(C27+C28-C29,MAX(0,C51*$C$11-C39-C21)) -> 0 | D30: =MIN(D27+D28-D29,MAX(0,D51*$C$11-D39-D21)) -> 0 | E30: =MIN(E27+E28-E29,MAX(0,E51*$C$11-E39-E21)) -> 0 | F30: =MIN(F27+F28-F29,MAX(0,F51*$C$11-F39-F21)) -> 0 | G30: =MIN(G27+G28-G29,MAX(0,G51*$C$11-G39-G21)) -> 0 | H30: =MIN(H27+H28-H29,MAX(0,H51*$C$11-H39-H21)) -> 0
B31: Ending Bal | C31: =C27+C28-C29-C30 -> 149.505 | D31: =D27+D28-D29-D30 -> 149.505 | E31: =E27+E28-E29-E30 -> 149.505 | F31: =F27+F28-F29-F30 -> 149.505 | G31: =G27+G28-G29-G30 -> 149.505 | H31: =H27+H28-H29-H30 -> 149.505
B32: Average Bal | C32: =(C27+C31)/2 -> 149.505 | D32: =(D27+D31)/2 -> 149.505 | E32: =(E27+E31)/2 -> 149.505 | F32: =(F27+F31)/2 -> 149.505 | G32: =(G27+G31)/2 -> 149.505 | H32: =(H27+H31)/2 -> 149.505
B33: Cash Interest | C33: =C27*$E$6 -> 14.9505 | D33: =D27*$E$6 -> 14.9505 | E33: =E27*$E$6 -> 14.9505 | F33: =F27*$E$6 -> 14.9505 | G33: =G27*$E$6 -> 14.9505 | H33: =H27*$E$6 -> 14.9505
B35: Revolver
B36: Beginning Balance | C36: =N($D$7) -> 0 | D36: =C40 -> 21.909602 | E36: =D40 -> 7.6232981 | F36: =E40 -> 0 | G36: =F40 -> 0 | H36: =G40 -> 0
B37: New Borrowing | C37: =MAX(0,$C$10-C49) -> 21.909602 | D37: =MAX(0,$C$10-D49) -> 0 | E37: =MAX(0,$C$10-E49) -> 0 | F37: =MAX(0,$C$10-F49) -> 0 | G37: =MAX(0,$C$10-G49) -> 0 | H37: =MAX(0,$C$10-H49) -> 0
B38: Mandatory Repayment | C38: 0 | D38: =MIN(D36+D37,$D$7*$F$7) -> 0 | E38: =MIN(E36+E37,$D$7*$F$7) -> 0 | F38: =MIN(F36+F37,$D$7*$F$7) -> 0 | G38: =MIN(G36+G37,$D$7*$F$7) -> 0 | H38: =MIN(H36+H37,$D$7*$F$7) -> 0
B39: Cash Sweep | C39: =MIN(C36+C37-C38,C51*$C$11) -> 0 | D39: =MIN(D36+D37-D38,D51*$C$11) -> 14.286304 | E39: =MIN(E36+E37-E38,E51*$C$11) -> 7.6232981 | F39: =MIN(F36+F37-F38,F51*$C$11) -> 0 | G39: =MIN(G36+G37-G38,G51*$C$11) -> 0 | H39: =MIN(H36+H37-H38,H51*$C$11) -> 0
B40: Ending Bal | C40: =C36+C37-C38-C39 -> 21.909602 | D40: =D36+D37-D38-D39 -> 7.6232981 | E40: =E36+E37-E38-E39 -> 0 | F40: =F36+F37-F38-F39 -> 0 | G40: =G36+G37-G38-G39 -> 0 | H40: =H36+H37-H38-H39 -> 0
B41: Average Bal | C41: =(C36+C40)/2 -> 10.954801 | D41: =(D36+D40)/2 -> 14.76645 | E41: =(E36+E40)/2 -> 3.811649 | F41: =(F36+F40)/2 -> 0 | G41: =(G36+G40)/2 -> 0 | H41: =(H36+H40)/2 -> 0
B42: Cash Interest | C42: =C36*$E$7 -> 0 | D42: =D36*$E$7 -> 1.4241241 | E42: =E36*$E$7 -> 0.49551438 | F42: =F36*$E$7 -> 0 | G42: =G36*$E$7 -> 0 | H42: =H36*$E$7 -> 0
B44: Cash Flow Available for Debt Paydown
C45: 2026 | D45: =C45+1 -> 2027 | E45: =D45+1 -> 2028 | F45: =E45+1 -> 2029 | G45: =F45+1 -> 2030 | H45: =G45+1 -> 2031
...

Sheet LBO Returns Exit
A1: =HYPERLINK("#'Table of Contents'!A1","<--------") -> <--------
B2: LBO Returns ($mm) | J2: Manual Transaction Multiples(historical)
C3: 2026 | D3: =C3+1 -> 2027 | E3: =D3+1 -> 2028 | F3: =E3+1 -> 2029 | G3: =F3+1 -> 2030 | H3: =G3+1 -> 2031 | J3: Entry EBTIDA Multiple | K3: 8.2
B4: Exit EBITDA | C4: ='H.B. Fuller BAS Operating'!F$10 -> 119.604 | D4: ='H.B. Fuller BAS Operating'!G$10 -> 132.61869 | E4: ='H.B. Fuller BAS Operating'!H$10 -> 146.31354 | F4: ='H.B. Fuller BAS Operating'!I$10 -> 158.89987 | G4: ='H.B. Fuller BAS Operating'!J$10 -> 170.47451 | H4: ='H.B. Fuller BAS Operating'!K$10 -> 177.20874 | J4: Exit EBITDA Multiple | K4: 8.2
B5: Exit Multiple | C5: ='Assumptions Tab'!$F$26 -> 10.033109 | D5: ='Assumptions Tab'!$F$26 -> 10.033109 | E5: ='Assumptions Tab'!$F$26 -> 10.033109 | F5: ='Assumptions Tab'!$F$26 -> 10.033109 | G5: ='Assumptions Tab'!$F$26 -> 10.033109 | H5: ='Assumptions Tab'!$F$26 -> 10.033109
B6: Exit EV | C6: =C4*C5 -> 1200 | D6: =D4*D5 -> 1330.5778 | E6: =E4*E5 -> 1467.9797 | F6: =F4*F5 -> 1594.2597 | G6: =G4*G5 -> 1710.3893 | H6: =H4*H5 -> 1777.9547
B8: Ending Cash | C8: ='Debt Schedule'!C52 -> 25 | D8: ='Debt Schedule'!D52 -> 25 | E8: ='Debt Schedule'!E52 -> 25 | F8: ='Debt Schedule'!F52 -> 25 | G8: ='Debt Schedule'!G52 -> 25 | H8: ='Debt Schedule'!H52 -> 25
B9: Ending Debt | C9: ='Debt Schedule'!C$53 -> 716.45003 | D9: ='Debt Schedule'!D$53 -> 691.04055 | E9: ='Debt Schedule'!E$53 -> 649.30568 | F9: ='Debt Schedule'!F$53 -> 594.21202 | G9: ='Debt Schedule'!G$53 -> 525.48395 | H9: ='Debt Schedule'!H$53 -> 447.33438
B11: Exit Equity Value | C11: =C$6+C$8-C$9 -> 508.54997 | D11: =D$6+D$8-D$9 -> 664.53723 | E11: =E$6+E$8-E$9 -> 843.67404 | F11: =F$6+F$8-F$9 -> 1025.0477 | G11: =G$6+G$8-G$9 -> 1209.9054 | H11: =H$6+H$8-H$9 -> 1355.6203 | L11: 7.321
B13: Initial Sponsor Equity | C13: ='Sources And Uses'!$C$24 -> 568.8364 | D13: ='Sources And Uses'!$C$24 -> 568.8364 | E13: ='Sources And Uses'!$C$24 -> 568.8364 | F13: ='Sources And Uses'!$C$24 -> 568.8364 | G13: ='Sources And Uses'!$C$24 -> 568.8364 | H13: ='Sources And Uses'!$C$24 -> 568.8364
B14: Initial EV | C14: ='Sources And Uses'!$C$9 -> 1200 | D14: ='Sources And Uses'!$C$9 -> 1200 | E14: ='Sources And Uses'!$C$9 -> 1200 | F14: ='Sources And Uses'!$C$9 -> 1200 | G14: ='Sources And Uses'!$C$9 -> 1200 | H14: ='Sources And Uses'!$C$9 -> 1200
B16: MOIC | C16: =C$11/C$13 -> 0.89401798 | D16: =D$11/D$13 -> 1.1682396 | E16: =E$11/E$13 -> 1.4831576 | F16: =F$11/F$13 -> 1.802008 | G16: =G$11/G$13 -> 2.1269831 | H16: =H$11/H$13 -> 2.3831462
B17: IRR | C17: =(C11/C13) -1 -> -0.10598202 | D17: =(D11/D13)^(1) - 1 -> 0.16823964 | E17: =(E11/E13)^(1/2) - 1 -> 0.21784959 | F17: =(F11/F13)^(1/3) - 1 -> 0.21689256 | G17: =(G11/G13)^(1/4) - 1 -> 0.20764978 | H17: =(H11/H13)^(1/5) - 1 -> 0.18967993

Sheet Seller Impact
A1: =HYPERLINK("#'Table of Contents'!A1","<--------") -> <--------
B2: Seller Impact($mm)
B4: Transaction Summary | E4: Use of Proceeds | H4: Leverage Impact
B6: BAS Sale Price | C6: 1200 | E6: Debt Paydown | F6: =MIN($C$20,$C$10) -> 1008 | I6: Pre-Deal | J6: Pro Forma
B7: Less: Transaction Fees | C7: ='Assumptions Tab'!F27*'Seller Impact'!C6 -> 12 | E7: Cash Residual | F7: =MAX(0,$C$10-$C$20) -> 0 | H7: Net Debt ($mm) | I7: =C20 -> 1958.1 | J7: =C26 -> 950.1
A8: (see writeup) | B8: Less: Taxes | C8: =C6*0.15 -> 180 | H8: EBITDA | I8: =F16 -> 640.4 | J8: =F20 -> 492.7
E9: Total Use of Proceeds | F9: =$F$6+$F$7 -> 1008
B10: Net Sale Proceeds | C10: =C6-C7-C8 -> 1008 | H10: Net Debt/ EBITDA | I10: =$I$7/$I$8 -> 3.0576202 | J10: =1/($J$8/$J$7) -> 1.928354
B14: H.B. Fuller Debt Summaries | C14: (pre deal) | E14: New EBITDA | H14: Cash Flow Impact(6.3%) | K14: read wrietup
I15: Pre-Deal | J15: Pro Forma
B16: Gross Debt | C16: 2072.2 | E16: H.B. Fuller EBITDA | F16: 640.4 | H16: Cash Interest Expense | I16: 132.4 | J16: =$I$16-$J$17 -> 72.5437
B17: Less: Cash | C17: 114.1 | E17: Less: BAS EBITDA | F17: ='H.B. Fuller BAS Operating'!E9 -> 137.7 | H17: Interest Expense Savings | J17: =C26*0.063 -> 59.8563
E18: Less: Stranded Costs | F18: 10
B20: Net Debt | C20: =C16-C17 -> 1958.1 | E20: Remaining EBITDA | F20: =$F$16-$F$17-$F$18 -> 492.7 | H20: % reduction IE | J20: =$J$16/$I$16 -> 0.54791314
C22: (post deal)
B23: Gross Debt | C23: =$C$16-$F$6 -> 1064.2
B24: Less: Cash | C24: =$C$17+$F$7 -> 114.1
B26: Pro Forma Net Debt | C26: =$C$23-$C$24 -> 950.1
B28: Decision Check | H28: Conclusion
H29: Ancora's $1.2bn offer is approximately financeable at normal sponsor return(19% 5 year IRR) but H.B. Fuller could argue this undervalues BAS based on precedent transacions.
B30: Rejected Bid | C30: =C6 -> 1200
B31: Implied Value Range
B32: Low: | C32: ='H.B. Fuller BAS Operating'!E7*(1+'Assumptions Tab'!D11)*'Assumptions Tab'!D12*'Assumptions Tab'!D18 -> 1148.4738
B33: High: | C33: ='H.B. Fuller BAS Operating'!E7*(1+'Assumptions Tab'!P11)*'Assumptions Tab'!P12*'Assumptions Tab'!P18 -> 1809.9761
B35: Base Case Price | C35: ='H.B. Fuller BAS Operating'!E7*(1+'Assumptions Tab'!J11)*'Assumptions Tab'!J12*'Assumptions Tab'!J18 -> 1547.1331
B36: Max Affordable Price | C36: =(('LBO Returns Exit'!H11/(1+'Assumptions Tab'!I30)^'Assumptions Tab'!F28)+SUM('Debt Schedule'!D5:D7)-'Assumptions Tab'!I26-'Assumptions Tab'!I25)/(1+'Assumptions Tab'!F27) -> 1223.4829
B38: Base Premium to Bid | C38: =C35/C30-1 -> 0.2892776
B39: Sponsor Premium to Bid | C39: =C36/C35 - 1 -> -0.20919353

Sheet Precedent Transactions
B1: =HYPERLINK("#'Table of Contents'!A1","<--------") -> <-------- | E1: Search Result Columns
A3: Downloaded on: | B3: 46264
A4: Created for: | B4: Evan Hassan, University of Utah Marriott Library- Students
A5: Search Link: | B5: https://my.pitchbook.com/?pcc=1380958-66
A6: Search Criteria: | B6: Excluded Deals: 8; Deal Date: From: 30-Aug-2020; Deal Size: Min: 500M; Max: 3B; Deal Option: Search on a full transaction; Deal Status: Completed; Deal Types: All Buyout Types > Buyout/LBO; All Buyout Types > Corporate divestiture; M&A/Control Transactions > M&A; Locations: United States; Canada; Europe; Keywords: adhesives; construction chemicals; coatings; sealants; specialty chemicals;
A8: Deal ID | B8: Companies | C8: Valuation/EBITDA | D8: Debt/EBITDA | E8: Financing Status Note | F8: Primary PitchBook Industry Sector | G8: Current Financing Status | H8: CEO PBId | I8: CEO Phone | J8: CEO Email | K8: % Acquired | L8: Deal Synopsis | M8: Deal Status | N8: Lenders | O8: Investor Funds | P8: Sellers | Q8: Debt & Lenders | R8: Total Debt (from financials) | S8: Deal Date | T8: Deal Type | U8: Deal Size | V8: HQ Location | W8: Investors | X8: Post Valuation | Y8: Revenue | Z8: EBITDA | AA8: Net Income | AB8: Valuation/Revenue | AC8: Description | AD8: View Company Online
A9: 286685-20T | B9: Genesis Alkali | C9: 9.9 | E9: The company was acquired by We Soda (LON:DUMY0000082) for $1.425 billion on February 28, 2025. | F9: Materials and Resources | G9: Formerly PE-Backed | K9: 100 | L9: The company was acquired by We Soda (LON:DUMY0000082) for $1.425 billion on February 28, 2025. | M9: Completed | P9: Blackstone Credit and Insurance, Genesis Energy (Energy Transportation) | S9: 45716 | T9: Merger/Acquisition | U9: 1425 | V9: Philadelphia, PA | W9: We Soda(Alasdair Warren) | X9: 1425 | Y9: 745 | Z9: 144 | AB9: 1.91 | AC9: Manufacturer of specialty chemicals intended for a variety of industrial and consumer applications. The company offers a range of products including natural soda ash, sodium bicarbonate, caustic soda and other derivative products to be used in the production of glass, detergents, chemicals, pulp and paper. | AD9: =HYPERLINK("https://my.pitchbook.com?c=286685-20T", "View Company Online") -> View Company Online
A10: 228839-14T | B10: Chase | C10: 15.34 | D10: 1.63 | E10: The company completed a $550 million debt refinancing round on April 1, 2025. Previously, the company raised $100,000 of debt financing on November 15, 2024. | F10: Materials and Resources | G10: Private Equity-Backed | H10: 92202-13P | I10: +1 (781) 332-0700 | J10: adamchase@chasecorp.com | K10: 100 | L10: The company was acquired by Kohlberg Kravis Roberts through a $1.3 billion public-to-private LBO on November 15, 2023. The transaction was supported by $137.79 million of debt financing. | M10: Completed | N10: Antares Capital, Blackstone (NYS: BX), Blackstone Credit and Insurance, Crescent Capital BDC (NAS: CCAP), Crescent Capital Group, Crescent Private Credit Income BDC, Goldman Sachs Asset Management, Goldman Sachs Middle Market Lending Corp. II BDC | O10: KKR North America Fund XIII(Kohlberg Kravis Roberts) | Q10: Term Loan - $1.74M (Goldman Sachs Middle Market Lending Corp. II BDC), Term Loan - $118.10M (Goldman Sachs Middle Market Lending Corp. II BDC), Term Loan - $118.10M (Goldman Sachs Asset Management), Term Loan - $118.10M (Antares Capital), Revolving Credit - $17.94M (Goldman Sachs Asset Management), Term Loan - $1.74M (Goldman Sachs Asset Management), Term Loan - $118.10M (Crescent Private Credit Income BDC), Term Loan - $118.10M (Crescent Capital BDC), Revolving Credit - $17.94M (Crescent Capital BDC), Term Loan - $118.10M (Crescent Capital Group), Revolving Credit - $17.94M (Crescent Private Credit Income BDC), Revolving Credit - $17.94M (Crescent Capital Group), Term Loan - $118.10M (Blackstone Credit and Insurance), Revolving Credit - $17.94M (Blackstone Credit and Insurance), Term Loan - $118.10M (Blackstone), Revolving Credit - $17.94M (Blackstone) | R10: 110.11 | S10: 45245 | T10: Buyout/LBO | U10: 1300 | V10: Westwood, MA | W10: Kohlberg Kravis Roberts (NYS: KKR)(Joshua Weisenbeck) | X10: 1300 | Y10: 404.02 | Z10: 84.74 | AA10: 33.18 | AB10: 3.22 | AC10: Manufacturer of industrial chemicals intended for automotive, construction, medical, military, energy and other sectors. The company offers adhesives, sealants and additives, industrial tapes and corrosion protection and waterproofing chemicals, enabling clients to get safe products at lower prices. | AD10: =HYPERLINK("https://my.pitchbook.com?c=228839-14T", "View Company Online") -> View Company Online
A11: 176735-17T | B11: Henry Company | C11: 13.49 | E11: The company was acquired by Carlisle Companies (NYS: CSL) for $1605.5 billion on September 1, 2021. The consideration of $1605.5 billion was funded with borrowings from its revolving credit facility and cash on hand. Previously, the company raised $4 million of debt financing on June 30, 2021. | F11: Business Products and Services (B2B) | G11: Formerly PE-Backed | H11: 139429-90P | I11: +1 (626) 357-4599 | J11: fready@henry.com | K11: 100 | L11: The company was acquired by Carlisle Companies (NYS: CSL) for $1605.6 billion on September 1, 2021. The consideration of $1605.5 billion was funded with borrowings from its revolving credit facility and cash on hand. | M11: Completed | P11: American Securities | S11: 44440 | T11: Merger/Acquisition | U11: 1605.6 | V11: PA | W11: Carlisle Companies (NYS: CSL)(Nicholas Shears) | X11: 1605.6 | Y11: 511 | Z11: 119 | AB11: 3.14 | AC11: Manufacturer of roofing and building-envelope products designed for managing the flow of water, vapor and air through the entire building. The company offers air barrier systems, waterproofing, roofing, concrete, flooring, performance additives and driveway sealers, enduring improved structure's energy efficiency, livability and sustainability for the benefit of the owner, occupant and the environment. | AD11: =HYPERLINK("https://my.pitchbook.com?c=176735-17T", "View Company Online") -> View Company Online
A12: 167745-16T | B12: Surteco (ETR: SUR) | C12: 16.27 | E12: Banasino Investments entered into an agreement to acquire a stake in the company (ETR:SUR) for an undisclosed amount on October 4, 2024. The company will not receive any proceeds from the offering. Subsequently, the offering was withdrawn. Previously, the company was acquired by Banasino Investments for $608 million on October 4, 2024. | F12: Consumer Products and Services (B2C) | G12: Corporate Backed or Acquired | H12: 73360-72P | I12: +49 (0)82 7451 0 | J12: wolfgang.moyses@surteco-group.com | K12: 30.57 | L12: The company was acquired by The Schürfeld Group for $510 million on March 2, 2021. | M12: Completed | R12: 347.9 | S12: 44257 | T12: Merger/Acquisition | U12: 510 | V12: Buttenwiesen, Germany | W12: The Schürfeld Group | X12: 1668.3 | Y12: 714.71 | Z12: 102.52 | AA12: 38.4 | AB12: 2.33 | AC12: Surteco Group SE is engaged in the manufacture of decorative surface coatings for furniture, flooring, and interior design. It also develops, produces, and sells skirtings, technical extrusions, and coated fabrics. The group has five reportable segments which is: Surfaces bundles all the surface activities including melamine edgings in Europe and South America; Edgebands bundles the activities with plastic edgebandings in Europe and South America; Profiles bundles activities with skirtings and technical extrusions (profiles) in Europe and South America; and the regional segments North America and Asia / Pacific, which comprise all the activities in the relevant geographical markets, independently of product. Its geographic areas are Germany, Europe, America, Asia / Australia, and Others. | AD12: =HYPERLINK("https://my.pitchbook.com?c=167745-16T", "View Company Online") -> View Company Online
A14: © PitchBook Data, Inc. 2026
D23: 2

Sheet old artifcats
A1: Returns Sensitivity (2031, Base Case)
A2: IRR Rows: Entry Multiple Columns: Exit Multiple
A3: ='LBO Returns Exit'!P17 -> 0 | B3: 10 | C3: 12 | D3: 14 | E3: 16 | F3: 18 | G3: 20
A4: 10 | B4: 0.11800524 | C4: 0.1797623 | D4: 0.23077666 | E4: 0.27451292 | F4: 0.3129583 | G4: 0.3473659
A5: 12 | B5: 0.039457091 | C5: 0.096875255 | D5: 0.14430548 | E5: 0.18496894 | F5: 0.22071325 | G5: 0.25270346
A6: 14 | B6: -0.014478195 | C6: 0.039960658 | D6: 0.08492983 | E6: 0.12348335 | F6: 0.15737295 | G6: 0.18770326
A7: 16 | B7: -0.055043437 | C7: -0.0028453506 | D7: 0.040272837 | E7: 0.077239445 | F7: 0.10973412 | G7: 0.13881599
A8: 18 | B8: -0.087284233 | C8: -0.036867084 | D8: 0.0047799619 | E8: 0.040485313 | F8: 0.071871305 | G8: 0.099960944
A10: MOIC Rows: Entry Multiple Columns: Exit Multiple
A11: ='LBO Returns Exit'!P16 -> 0 | B11: 10 | C11: 12 | D11: 14 | E11: 16 | F11: 18 | G11: 20
A12: 10 | B12: 1.7467035 | C12: 2.2854544 | D12: 2.8242053 | E12: 3.3629562 | F12: 3.901707 | G12: 4.4404579
A13: 12 | B13: 1.2134806 | C13: 1.5877649 | D13: 1.9620492 | E13: 2.3363335 | F13: 2.7106178 | G13: 3.0849021
A14: 14 | B14: 0.92967507 | C14: 1.2164228 | D14: 1.5031705 | E14: 1.7899182 | F14: 2.076666 | G14: 2.3634137
A15: 16 | B15: 0.75345831 | C15: 0.98585398 | D15: 1.2182496 | E15: 1.4506453 | F15: 1.683041 | G15: 1.9154366
A16: 18 | B16: 0.63339957 | C16: 0.82876448 | D16: 1.0241294 | E16: 1.2194943 | F16: 1.4148592 | G16: 1.6102241
