Workbook
Name BOJA___AllReports: 'Bojales Raw'!$A$1:$F$166
Name FOGO___AllReports: 'Fogo De Chao'!$A$1:$E$166

Sheet Bojangles Financials
B1: Bojangles
B2: Consolidated Financials
B4: note: the numbers used in this company are not reflective of what I believe will actually happen. I used identical projections to see how LBO returns differ for both.
B10: Historical & "Forecast"
C11: Actual | H11: Controlled Scenario "Forecast" | M11: see writeup
B12: FYE December | C12: 41910 | D12: 42001 | E12: 42365 | F12: 42729 | G12: 43100 | H12: =EDATE(G12,12) -> 43465 | I12: =EDATE(H12,12) -> 43830 | J12: =EDATE(I12,12) -> 44196 | K12: =EDATE(J12,12) -> 44561 | L12: =EDATE(K12,12) -> 44926
C13: USD | D13: USD | E13: USD | F13: USD | G13: USD | H13: USD | I13: USD | J13: USD | K13: USD | L13: USD
C14: Million | D14: Million | E14: Million | F14: Million | G14: Million | H14: Million | I14: Million | J14: Million | K14: Million | L14: Million
B15: Total Revenue | C15: =INDEX('Bojales Raw'!$B$6:$F$144,MATCH($B15,'Bojales Raw'!$A$6:$A$144,0),MATCH('Bojangles Financials'!C$12,'Bojales Raw'!$B$3:$F$3,0)) -> 375.162 | D15: =INDEX('Bojales Raw'!$B$6:$F$144,MATCH($B15,'Bojales Raw'!$A$6:$A$144,0),MATCH('Bojangles Financials'!D$12,'Bojales Raw'!$B$3:$F$3,0)) -> 430.472 | E15: =INDEX('Bojales Raw'!$B$6:$F$144,MATCH($B15,'Bojales Raw'!$A$6:$A$144,0),MATCH('Bojangles Financials'!E$12,'Bojales Raw'!$B$3:$F$3,0)) -> 488.202 | F15: =INDEX('Bojales Raw'!$B$6:$F$144,MATCH($B15,'Bojales Raw'!$A$6:$A$144,0),MATCH('Bojangles Financials'!F$12,'Bojales Raw'!$B$3:$F$3,0)) -> 531.881 | G15: =INDEX('Bojales Raw'!$B$6:$F$144,MATCH($B15,'Bojales Raw'!$A$6:$A$144,0),MATCH('Bojangles Financials'!G$12,'Bojales Raw'!$B$3:$F$3,0)) -> 547.438 | H15: =G15*(1+H38) -> 574.8099 | I15: =H15*(1+I38) -> 603.55039 | J15: =I15*(1+J38) -> 633.72791 | K15: =J15*(1+K38) -> 665.41431 | L15: =K15*(1+L38) -> 698.68503
B16: Year-over-year growth | D16: =D38 -> 0.14742964 | E16: =E38 -> 0.13410861 | F16: =F38 -> 0.089469113 | G16: =G38 -> 0.029249024 | H16: =H38 -> 0.05 | I16: =I38 -> 0.05 | J16: =J38 -> 0.05 | K16: =K38 -> 0.05 | L16: =L38 -> 0.05
B18: Cost of Revenue, Total | C18: =INDEX('Bojales Raw'!$B$6:$F$144,MATCH($B18,'Bojales Raw'!$A$6:$A$144,0),MATCH('Bojangles Financials'!C$12,'Bojales Raw'!$B$3:$F$3,0)) -> 302.112 | D18: =INDEX('Bojales Raw'!$B$6:$F$144,MATCH($B18,'Bojales Raw'!$A$6:$A$144,0),MATCH('Bojangles Financials'!D$12,'Bojales Raw'!$B$3:$F$3,0)) -> 343.886 | E18: =INDEX('Bojales Raw'!$B$6:$F$144,MATCH($B18,'Bojales Raw'!$A$6:$A$144,0),MATCH('Bojangles Financials'!E$12,'Bojales Raw'!$B$3:$F$3,0)) -> 389.315 | F18: =INDEX('Bojales Raw'!$B$6:$F$144,MATCH($B18,'Bojales Raw'!$A$6:$A$144,0),MATCH('Bojangles Financials'!F$12,'Bojales Raw'!$B$3:$F$3,0)) -> 422.448 | G18: =INDEX('Bojales Raw'!$B$6:$F$144,MATCH($B18,'Bojales Raw'!$A$6:$A$144,0),MATCH('Bojangles Financials'!G$12,'Bojales Raw'!$B$3:$F$3,0)) -> 451.445 | H18: =H39*H$15 -> 474.01725 | I18: =I39*I$15 -> 497.71811 | J18: =J39*J$15 -> 522.60402 | K18: =K39*K$15 -> 548.73422 | L18: =L39*L$15 -> 576.17093
B19: Gross Profit | C19: =INDEX('Bojales Raw'!$B$6:$F$144,MATCH($B19,'Bojales Raw'!$A$6:$A$144,0),MATCH('Bojangles Financials'!C$12,'Bojales Raw'!$B$3:$F$3,0)) -> 73.05 | D19: =INDEX('Bojales Raw'!$B$6:$F$144,MATCH($B19,'Bojales Raw'!$A$6:$A$144,0),MATCH('Bojangles Financials'!D$12,'Bojales Raw'!$B$3:$F$3,0)) -> 86.586 | E19: =INDEX('Bojales Raw'!$B$6:$F$144,MATCH($B19,'Bojales Raw'!$A$6:$A$144,0),MATCH('Bojangles Financials'!E$12,'Bojales Raw'!$B$3:$F$3,0)) -> 98.887 | F19: =INDEX('Bojales Raw'!$B$6:$F$144,MATCH($B19,'Bojales Raw'!$A$6:$A$144,0),MATCH('Bojangles Financials'!F$12,'Bojales Raw'!$B$3:$F$3,0)) -> 109.433 | G19: =INDEX('Bojales Raw'!$B$6:$F$144,MATCH($B19,'Bojales Raw'!$A$6:$A$144,0),MATCH('Bojangles Financials'!G$12,'Bojales Raw'!$B$3:$F$3,0)) -> 95.993 | H19: =H15-H18 -> 100.79265 | I19: =I15-I18 -> 105.83228 | J19: =J15-J18 -> 111.1239 | K19: =K15-K18 -> 116.68009 | L19: =L15-L18 -> 122.5141
B20: Selling/General/Admin. Expenses, Total | C20: =INDEX('Bojales Raw'!$B$6:$F$144,MATCH($B20,'Bojales Raw'!$A$6:$A$144,0),MATCH('Bojangles Financials'!C$12,'Bojales Raw'!$B$3:$F$3,0)) -> 27.478 | D20: =INDEX('Bojales Raw'!$B$6:$F$144,MATCH($B20,'Bojales Raw'!$A$6:$A$144,0),MATCH('Bojangles Financials'!D$12,'Bojales Raw'!$B$3:$F$3,0)) -> 32.107 | E20: =INDEX('Bojales Raw'!$B$6:$F$144,MATCH($B20,'Bojales Raw'!$A$6:$A$144,0),MATCH('Bojangles Financials'!E$12,'Bojales Raw'!$B$3:$F$3,0)) -> 42.844 | F20: =INDEX('Bojales Raw'!$B$6:$F$144,MATCH($B20,'Bojales Raw'!$A$6:$A$144,0),MATCH('Bojangles Financials'!F$12,'Bojales Raw'!$B$3:$F$3,0)) -> 39.041 | G20: =INDEX('Bojales Raw'!$B$6:$F$144,MATCH($B20,'Bojales Raw'!$A$6:$A$144,0),MATCH('Bojangles Financials'!G$12,'Bojales Raw'!$B$3:$F$3,0)) -> 38.397 | H20: =H40*H$15 -> 40.31685 | I20: =I40*I$15 -> 42.332692 | J20: =J40*J$15 -> 44.449327 | K20: =K40*K$15 -> 46.671793 | L20: =L40*L$15 -> 49.005383
B21: Research & Development | C21: =INDEX('Bojales Raw'!$B$6:$F$144,MATCH($B21,'Bojales Raw'!$A$6:$A$144,0),MATCH('Bojangles Financials'!C$12,'Bojales Raw'!$B$3:$F$3,0)) -> 0 | D21: =INDEX('Bojales Raw'!$B$6:$F$144,MATCH($B21,'Bojales Raw'!$A$6:$A$144,0),MATCH('Bojangles Financials'!D$12,'Bojales Raw'!$B$3:$F$3,0)) -> 0 | E21: =INDEX('Bojales Raw'!$B$6:$F$144,MATCH($B21,'Bojales Raw'!$A$6:$A$144,0),MATCH('Bojangles Financials'!E$12,'Bojales Raw'!$B$3:$F$3,0)) -> 0 | F21: =INDEX('Bojales Raw'!$B$6:$F$144,MATCH($B21,'Bojales Raw'!$A$6:$A$144,0),MATCH('Bojangles Financials'!F$12,'Bojales Raw'!$B$3:$F$3,0)) -> 0 | G21: =INDEX('Bojales Raw'!$B$6:$F$144,MATCH($B21,'Bojales Raw'!$A$6:$A$144,0),MATCH('Bojangles Financials'!G$12,'Bojales Raw'!$B$3:$F$3,0)) -> 0 | H21: =H41*H$15 -> 0 | I21: =I41*I$15 -> 0 | J21: =J41*J$15 -> 0 | K21: =K41*K$15 -> 0 | L21: =L41*L$15 -> 0
B22: Depreciation/Amortization | C22: =INDEX('Bojales Raw'!$B$6:$F$144,MATCH($B22,'Bojales Raw'!$A$6:$A$144,0),MATCH('Bojangles Financials'!C$12,'Bojales Raw'!$B$3:$F$3,0)) -> 2.2 | D22: =INDEX('Bojales Raw'!$B$6:$F$144,MATCH($B22,'Bojales Raw'!$A$6:$A$144,0),MATCH('Bojangles Financials'!D$12,'Bojales Raw'!$B$3:$F$3,0)) -> 2.4 | E22: =INDEX('Bojales Raw'!$B$6:$F$144,MATCH($B22,'Bojales Raw'!$A$6:$A$144,0),MATCH('Bojangles Financials'!E$12,'Bojales Raw'!$B$3:$F$3,0)) -> 2.8 | F22: =INDEX('Bojales Raw'!$B$6:$F$144,MATCH($B22,'Bojales Raw'!$A$6:$A$144,0),MATCH('Bojangles Financials'!F$12,'Bojales Raw'!$B$3:$F$3,0)) -> 2.9 | G22: =INDEX('Bojales Raw'!$B$6:$F$144,MATCH($B22,'Bojales Raw'!$A$6:$A$144,0),MATCH('Bojangles Financials'!G$12,'Bojales Raw'!$B$3:$F$3,0)) -> 2.9 | H22: =H42*H$15 -> 3.045 | I22: =I42*I$15 -> 3.19725 | J22: =J42*J$15 -> 3.3571125 | K22: =K42*K$15 -> 3.5249681 | L22: =L42*L$15 -> 3.7012165
B23: Other Operating Expenses, Total | C23: =INDEX('Bojales Raw'!$B$6:$F$144,MATCH($B23,'Bojales Raw'!$A$6:$A$144,0),MATCH('Bojangles Financials'!C$12,'Bojales Raw'!$B$3:$F$3,0)) -> 0 | D23: =INDEX('Bojales Raw'!$B$6:$F$144,MATCH($B23,'Bojales Raw'!$A$6:$A$144,0),MATCH('Bojangles Financials'!D$12,'Bojales Raw'!$B$3:$F$3,0)) -> 0 | E23: =INDEX('Bojales Raw'!$B$6:$F$144,MATCH($B23,'Bojales Raw'!$A$6:$A$144,0),MATCH('Bojangles Financials'!E$12,'Bojales Raw'!$B$3:$F$3,0)) -> 0 | F23: =INDEX('Bojales Raw'!$B$6:$F$144,MATCH($B23,'Bojales Raw'!$A$6:$A$144,0),MATCH('Bojangles Financials'!F$12,'Bojales Raw'!$B$3:$F$3,0)) -> 0 | G23: =INDEX('Bojales Raw'!$B$6:$F$144,MATCH($B23,'Bojales Raw'!$A$6:$A$144,0),MATCH('Bojangles Financials'!G$12,'Bojales Raw'!$B$3:$F$3,0)) -> 0 | H23: =H43*H$15 -> 1.785 | I23: =I43*I$15 -> 1.87425 | J23: =J43*J$15 -> 1.9679625 | K23: =K43*K$15 -> 2.0663606 | L23: =L43*L$15 -> 2.1696787
B24: Unusual Expense (Income) | C24: =INDEX('Bojales Raw'!$B$6:$F$144,MATCH($B24,'Bojales Raw'!$A$6:$A$144,0),MATCH('Bojangles Financials'!C$12,'Bojales Raw'!$B$3:$F$3,0)) -> 0.1 | D24: =INDEX('Bojales Raw'!$B$6:$F$144,MATCH($B24,'Bojales Raw'!$A$6:$A$144,0),MATCH('Bojangles Financials'!D$12,'Bojales Raw'!$B$3:$F$3,0)) -> 0.5 | E24: =INDEX('Bojales Raw'!$B$6:$F$144,MATCH($B24,'Bojales Raw'!$A$6:$A$144,0),MATCH('Bojangles Financials'!E$12,'Bojales Raw'!$B$3:$F$3,0)) -> 1.5 | F24: =INDEX('Bojales Raw'!$B$6:$F$144,MATCH($B24,'Bojales Raw'!$A$6:$A$144,0),MATCH('Bojangles Financials'!F$12,'Bojales Raw'!$B$3:$F$3,0)) -> 2 | G24: =INDEX('Bojales Raw'!$B$6:$F$144,MATCH($B24,'Bojales Raw'!$A$6:$A$144,0),MATCH('Bojangles Financials'!G$12,'Bojales Raw'!$B$3:$F$3,0)) -> 1.7 | H24: =H44*H$15 -> 0 | I24: =I44*I$15 -> 0 | J24: =J44*J$15 -> 0 | K24: =K44*K$15 -> 0 | L24: =L44*L$15 -> 0
B26: Total Operating Expense | C26: =INDEX('Bojales Raw'!$B$6:$F$144,MATCH($B26,'Bojales Raw'!$A$6:$A$144,0),MATCH('Bojangles Financials'!C$12,'Bojales Raw'!$B$3:$F$3,0)) -> 331.8 | D26: =INDEX('Bojales Raw'!$B$6:$F$144,MATCH($B26,'Bojales Raw'!$A$6:$A$144,0),MATCH('Bojangles Financials'!D$12,'Bojales Raw'!$B$3:$F$3,0)) -> 378.9 | E26: =INDEX('Bojales Raw'!$B$6:$F$144,MATCH($B26,'Bojales Raw'!$A$6:$A$144,0),MATCH('Bojangles Financials'!E$12,'Bojales Raw'!$B$3:$F$3,0)) -> 436.5 | F26: =INDEX('Bojales Raw'!$B$6:$F$144,MATCH($B26,'Bojales Raw'!$A$6:$A$144,0),MATCH('Bojangles Financials'!F$12,'Bojales Raw'!$B$3:$F$3,0)) -> 466.4 | G26: =INDEX('Bojales Raw'!$B$6:$F$144,MATCH($B26,'Bojales Raw'!$A$6:$A$144,0),MATCH('Bojangles Financials'!G$12,'Bojales Raw'!$B$3:$F$3,0)) -> 494.5 | H26: =H18+SUM(H20:H24) -> 519.1641 | I26: =I18+SUM(I20:I24) -> 545.1223 | J26: =J18+SUM(J20:J24) -> 572.37842 | K26: =K18+SUM(K20:K24) -> 600.99734 | L26: =L18+SUM(L20:L24) -> 631.04721
B27: Operating Income | C27: =INDEX('Bojales Raw'!$B$6:$F$144,MATCH($B27,'Bojales Raw'!$A$6:$A$144,0),MATCH('Bojangles Financials'!C$12,'Bojales Raw'!$B$3:$F$3,0)) -> 43.321 | D27: =INDEX('Bojales Raw'!$B$6:$F$144,MATCH($B27,'Bojales Raw'!$A$6:$A$144,0),MATCH('Bojangles Financials'!D$12,'Bojales Raw'!$B$3:$F$3,0)) -> 51.563 | E27: =INDEX('Bojales Raw'!$B$6:$F$144,MATCH($B27,'Bojales Raw'!$A$6:$A$144,0),MATCH('Bojangles Financials'!E$12,'Bojales Raw'!$B$3:$F$3,0)) -> 51.688 | F27: =INDEX('Bojales Raw'!$B$6:$F$144,MATCH($B27,'Bojales Raw'!$A$6:$A$144,0),MATCH('Bojangles Financials'!F$12,'Bojales Raw'!$B$3:$F$3,0)) -> 65.501 | G27: =INDEX('Bojales Raw'!$B$6:$F$144,MATCH($B27,'Bojales Raw'!$A$6:$A$144,0),MATCH('Bojangles Financials'!G$12,'Bojales Raw'!$B$3:$F$3,0)) -> 52.942 | H27: =H15-H26 -> 55.6458 | I27: =I15-I26 -> 58.42809 | J27: =J15-J26 -> 61.349495 | K27: =K15-K26 -> 64.416969 | L27: =L15-L26 -> 67.637818
B28: Operating Margin | C28: =C27/C15 -> 0.11547278 | D28: =D27/D15 -> 0.11978247 | E28: =E27/E15 -> 0.10587421 | F28: =F27/F15 -> 0.12314973 | G28: =G27/G15 -> 0.096708668 | H28: =H27/H15 -> 0.09680731 | I28: =I27/I15 -> 0.09680731 | J28: =J27/J15 -> 0.09680731 | ... L28: =L27/L15 -> 0.09680731
B29: EBITDA | C29: =C27+C22 -> 45.521 | D29: =D27+D22 -> 53.963 | E29: =E27+E22 -> 54.488 | F29: =F27+F22 -> 68.401 | G29: =G27+G22 -> 55.842 | H29: =H27+H22 -> 58.6908 | I29: =I27+I22 -> 61.62534 | J29: =J27+J22 -> 64.706607 | ... L29: =L27+L22 -> 71.339034
B30: EBITDA Margin | C30: =C29/C15 -> 0.12133692 | D30: =D29/D15 -> 0.12535775 | E30: =E29/E15 -> 0.11160954 | F30: =F29/F15 -> 0.12860207 | G30: =G29/G15 -> 0.10200607 | H30: =H29/H15 -> 0.10210471 | I30: =I29/I15 -> 0.10210471 | J30: =J29/J15 -> 0.10210471 | ... L30: =L29/L15 -> 0.10210471 | M30: (held constant)
B32: Capital Expenditures | C32: =INDEX('Bojales Raw'!$B$6:$F$144,MATCH($B32,'Bojales Raw'!$A$6:$A$144,0),MATCH('Bojangles Financials'!C$12,'Bojales Raw'!$B$3:$F$3,0)) -> -9.431 | D32: =INDEX('Bojales Raw'!$B$6:$F$144,MATCH($B32,'Bojales Raw'!$A$6:$A$144,0),MATCH('Bojangles Financials'!D$12,'Bojales Raw'!$B$3:$F$3,0)) -> -10.682 | E32: =INDEX('Bojales Raw'!$B$6:$F$144,MATCH($B32,'Bojales Raw'!$A$6:$A$144,0),MATCH('Bojangles Financials'!E$12,'Bojales Raw'!$B$3:$F$3,0)) -> -12.233 | F32: =INDEX('Bojales Raw'!$B$6:$F$144,MATCH($B32,'Bojales Raw'!$A$6:$A$144,0),MATCH('Bojangles Financials'!F$12,'Bojales Raw'!$B$3:$F$3,0)) -> -9.795 | G32: =INDEX('Bojales Raw'!$B$6:$F$144,MATCH($B32,'Bojales Raw'!$A$6:$A$144,0),MATCH('Bojangles Financials'!G$12,'Bojales Raw'!$B$3:$F$3,0)) -> -9.616 | H32: =H46*-1*H15 -> -10.0968 | I32: =I46*-1*I15 -> -10.60164 | J32: =J46*-1*J15 -> -11.131722 | K32: =K46*-1*K15 -> -11.688308 | L32: =L46*-1*L15 -> -12.272724
B33: Changes in Working Capital | C33: =INDEX('Bojales Raw'!$B$6:$F$144,MATCH($B33,'Bojales Raw'!$A$6:$A$144,0),MATCH('Bojangles Financials'!C$12,'Bojales Raw'!$B$3:$F$3,0)) -> 3.675 | D33: =INDEX('Bojales Raw'!$B$6:$F$144,MATCH($B33,'Bojales Raw'!$A$6:$A$144,0),MATCH('Bojangles Financials'!D$12,'Bojales Raw'!$B$3:$F$3,0)) -> 1.532 | E33: =INDEX('Bojales Raw'!$B$6:$F$144,MATCH($B33,'Bojales Raw'!$A$6:$A$144,0),MATCH('Bojangles Financials'!E$12,'Bojales Raw'!$B$3:$F$3,0)) -> 2.779 | F33: =INDEX('Bojales Raw'!$B$6:$F$144,MATCH($B33,'Bojales Raw'!$A$6:$A$144,0),MATCH('Bojangles Financials'!F$12,'Bojales Raw'!$B$3:$F$3,0)) -> 1.36 | G33: =INDEX('Bojales Raw'!$B$6:$F$144,MATCH($B33,'Bojales Raw'!$A$6:$A$144,0),MATCH('Bojangles Financials'!G$12,'Bojales Raw'!$B$3:$F$3,0)) -> -2.83 | H33: =H16*H47 -> 0 | I33: =I16*I47 -> 0 | J33: =J16*J47 -> 0 | K33: =K16*K47 -> 0 | L33: =L16*L47 -> 0
B35: Key Model Drivers
B37: income Statement Driver
B38: YoY Growth | D38: =D15/C15 - 1 -> 0.14742964 | E38: =E15/D15 - 1 -> 0.13410861 | F38: =F15/E15 - 1 -> 0.089469113 | G38: =G15/F15 - 1 -> 0.029249024 | H38: 0.05 | I38: 0.05 | J38: 0.05 | K38: 0.05 | L38: 0.05
B39: Cost of revenue (% Revenue) | C39: =C18/C15 -> 0.80528412 | D39: =D18/D15 -> 0.798858 | E39: =E18/E15 -> 0.79744655 | F39: =F18/F15 -> 0.79425285 | G39: =G18/G15 -> 0.82465046 | H39: =$G$39 -> 0.82465046 | I39: =$G$39 -> 0.82465046 | J39: =$G$39 -> 0.82465046 | K39: =$G$39 -> 0.82465046 | L39: =$G$39 -> 0.82465046 | M39: see writeup
B40: SG&A (% of Revenue) | C40: =C20/C15 -> 0.073243026 | D40: =D20/D15 -> 0.074585571 | E40: =E20/E15 -> 0.087758756 | F40: =F20/F15 -> 0.073401757 | G40: =G20/G15 -> 0.07013945 | H40: =$G$40 -> 0.07013945 | I40: =$G$40 -> 0.07013945 | J40: =$G$40 -> 0.07013945 | K40: =$G$40 -> 0.07013945 | L40: =$G$40 -> 0.07013945
B41: R&D (% of Revenue) | C41: =C21/C15 -> 0 | D41: =D21/D15 -> 0 | E41: =E21/E15 -> 0 | F41: =F21/F15 -> 0 | G41: =G21/G15 -> 0 | H41: =$G$41 -> 0 | I41: =$G$41 -> 0 | J41: =$G$41 -> 0 | K41: =$G$41 -> 0 | L41: =$G$41 -> 0
B42: D&A (% of Revenue) | C42: =C22/C15 -> 0.0058641334 | D42: =D22/D15 -> 0.0055752755 | E42: =E22/E15 -> 0.0057353309 | F42: =F22/F15 -> 0.0054523474 | G42: =G22/G15 -> 0.0052974035 | H42: =$G$42 -> 0.0052974035 | I42: =$G$42 -> 0.0052974035 | J42: =$G$42 -> 0.0052974035 | K42: =$G$42 -> 0.0052974035 | L42: =$G$42 -> 0.0052974035
B43: Unusual Expense (% of Revenue) | C43: =C24/C15 -> 0.00026655152 | D43: =D24/D15 -> 0.0011615157 | E43: =E24/E15 -> 0.0030724987 | F43: =F24/F15 -> 0.0037602396 | G43: =G24/G15 -> 0.0031053745 | H43: =$G$43 -> 0.0031053745 | I43: =$G$43 -> 0.0031053745 | J43: =$G$43 -> 0.0031053745 | K43: =$G$43 -> 0.0031053745 | L43: =$G$43 -> 0.0031053745
B45: Cash Flow Drivers
B46: CapEx(% of revenue) | C46: =C32/C15*-1 -> 0.025138474 | D46: =D32/D15*-1 -> 0.024814622 | E46: =E32/E15*-1 -> 0.025057251 | F46: =F32/F15*-1 -> 0.018415773 | G46: =G32/G15*-1 -> 0.017565459 | H46: =$G$46 -> 0.017565459 | I46: =$G$46 -> 0.017565459 | J46: =$G$46 -> 0.017565459 | K46: =$G$46 -> 0.017565459 | L46: =$G$46 -> 0.017565459
B47: NWC (% of revenue) | C47: -0.0282305 | D47: -0.0253263 | E47: -0.0121976 | F47: -0.060999 | G47: 0.00723059 | H47: 0 | I47: 0 | J47: 0 | K47: 0 | L47: 0
B49: Tax Rate | C49: 0.24 | D49: =C49 -> 0.24 | E49: =D49 -> 0.24 | F49: =E49 -> 0.24 | G49: =F49 -> 0.24 | H49: =G49 -> 0.24 | I49: =H49 -> 0.24 | J49: =I49 -> 0.24 | K49: =J49 -> 0.24 | L49: =K49 -> 0.24
E58: =AVERAGE(C29:G29) -> 55.643

Sheet Fogo De Chao Financials
B1: Fogo De Chão
B2: Consolidated Financials
B4: note: the numbers used in this company are not reflective of what I believe will actually happen. I used identical projections to see how LBO returns differ for both.
B10: Consolidated Financials
G11: Controlled Scenario "Forecast" | L11: see writeup
B12: FYE December | C12: 42092 | D12: 42372 | E12: 42736 | F12: 43100 | G12: =EDATE(F12,12) -> 43465 | H12: =EDATE(G12,12) -> 43830 | I12: =EDATE(H12,12) -> 44196 | J12: =EDATE(I12,12) -> 44561 | K12: =EDATE(J12,12) -> 44926
C13: USD | D13: USD | E13: USD | F13: USD | G13: USD | H13: USD | I13: USD | J13: USD | K13: USD
C14: Million | D14: Million | E14: Million | F14: Million | G14: Million | H14: Million | I14: Million | J14: Million | K14: Million
B15: Total Revenue | C15: =INDEX('Fogo De Chao'!$B$6:$E$144,MATCH($B15,'Fogo De Chao'!$A$6:$A$144,0),MATCH('Fogo De Chao Financials'!C$12,'Fogo De Chao'!$B$3:$E$3,0)) -> 219.239 | D15: =INDEX('Fogo De Chao'!$B$6:$E$144,MATCH($B15,'Fogo De Chao'!$A$6:$A$144,0),MATCH('Fogo De Chao Financials'!D$12,'Fogo De Chao'!$B$3:$E$3,0)) -> 271.634 | E15: =INDEX('Fogo De Chao'!$B$6:$E$144,MATCH($B15,'Fogo De Chao'!$A$6:$A$144,0),MATCH('Fogo De Chao Financials'!E$12,'Fogo De Chao'!$B$3:$E$3,0)) -> 288.296 | F15: =INDEX('Fogo De Chao'!$B$6:$E$144,MATCH($B15,'Fogo De Chao'!$A$6:$A$144,0),MATCH('Fogo De Chao Financials'!F$12,'Fogo De Chao'!$B$3:$E$3,0)) -> 314.359 | G15: =F15*(1+G38) -> 330.07695 | H15: =G15*(1+H38) -> 346.5808 | I15: =H15*(1+I38) -> 363.90984 | J15: =I15*(1+J38) -> 382.10533 | K15: =J15*(1+K38) -> 401.2106
B16: Year-over-year growth | D16: =D38 -> 0.23898576 | E16: =E38 -> 0.061339891 | F16: =F38 -> 0.090403613 | G16: =G38 -> 0.05 | H16: =H38 -> 0.05 | I16: =I38 -> 0.05 | J16: =J38 -> 0.05 | K16: =K38 -> 0.05
B18: Cost of Revenue, Total | C18: =INDEX('Fogo De Chao'!$B$6:$E$144,MATCH($B18,'Fogo De Chao'!$A$6:$A$144,0),MATCH('Fogo De Chao Financials'!C$12,'Fogo De Chao'!$B$3:$E$3,0)) -> 113.862 | D18: =INDEX('Fogo De Chao'!$B$6:$E$144,MATCH($B18,'Fogo De Chao'!$A$6:$A$144,0),MATCH('Fogo De Chao Financials'!D$12,'Fogo De Chao'!$B$3:$E$3,0)) -> 140.286 | E18: =INDEX('Fogo De Chao'!$B$6:$E$144,MATCH($B18,'Fogo De Chao'!$A$6:$A$144,0),MATCH('Fogo De Chao Financials'!E$12,'Fogo De Chao'!$B$3:$E$3,0)) -> 148.521 | F18: =INDEX('Fogo De Chao'!$B$6:$E$144,MATCH($B18,'Fogo De Chao'!$A$6:$A$144,0),MATCH('Fogo De Chao Financials'!F$12,'Fogo De Chao'!$B$3:$E$3,0)) -> 164.837 | G18: =G39*G$15 -> 173.07885 | H18: =H39*H$15 -> 181.73279 | I18: =I39*I$15 -> 190.81943 | J18: =J39*J$15 -> 200.3604 | K18: =K39*K$15 -> 210.37842
B19: Gross Profit | C19: =INDEX('Fogo De Chao'!$B$6:$E$144,MATCH($B19,'Fogo De Chao'!$A$6:$A$144,0),MATCH('Fogo De Chao Financials'!C$12,'Fogo De Chao'!$B$3:$E$3,0)) -> 105.377 | D19: =INDEX('Fogo De Chao'!$B$6:$E$144,MATCH($B19,'Fogo De Chao'!$A$6:$A$144,0),MATCH('Fogo De Chao Financials'!D$12,'Fogo De Chao'!$B$3:$E$3,0)) -> 131.348 | E19: =INDEX('Fogo De Chao'!$B$6:$E$144,MATCH($B19,'Fogo De Chao'!$A$6:$A$144,0),MATCH('Fogo De Chao Financials'!E$12,'Fogo De Chao'!$B$3:$E$3,0)) -> 139.775 | F19: =INDEX('Fogo De Chao'!$B$6:$E$144,MATCH($B19,'Fogo De Chao'!$A$6:$A$144,0),MATCH('Fogo De Chao Financials'!F$12,'Fogo De Chao'!$B$3:$E$3,0)) -> 149.522 | G19: =G15-G18 -> 156.9981 | H19: =H15-H18 -> 164.84801 | I19: =I15-I18 -> 173.09041 | J19: =J15-J18 -> 181.74493 | K19: =K15-K18 -> 190.83217
B20: Selling/General/Admin. Expenses, Total | C20: =INDEX('Fogo De Chao'!$B$6:$E$144,MATCH($B20,'Fogo De Chao'!$A$6:$A$144,0),MATCH('Fogo De Chao Financials'!C$12,'Fogo De Chao'!$B$3:$E$3,0)) -> 65.894 | D20: =INDEX('Fogo De Chao'!$B$6:$E$144,MATCH($B20,'Fogo De Chao'!$A$6:$A$144,0),MATCH('Fogo De Chao Financials'!D$12,'Fogo De Chao'!$B$3:$E$3,0)) -> 90.195 | E20: =INDEX('Fogo De Chao'!$B$6:$E$144,MATCH($B20,'Fogo De Chao'!$A$6:$A$144,0),MATCH('Fogo De Chao Financials'!E$12,'Fogo De Chao'!$B$3:$E$3,0)) -> 85.289 | F20: =INDEX('Fogo De Chao'!$B$6:$E$144,MATCH($B20,'Fogo De Chao'!$A$6:$A$144,0),MATCH('Fogo De Chao Financials'!F$12,'Fogo De Chao'!$B$3:$E$3,0)) -> 96.483 | G20: =G40*G$15 -> 101.30715 | H20: =H40*H$15 -> 106.37251 | I20: =I40*I$15 -> 111.69113 | J20: =J40*J$15 -> 117.27569 | K20: =K40*K$15 -> 123.13947
B21: Research & Development | C21: =INDEX('Fogo De Chao'!$B$6:$E$144,MATCH($B21,'Fogo De Chao'!$A$6:$A$144,0),MATCH('Fogo De Chao Financials'!C$12,'Fogo De Chao'!$B$3:$E$3,0)) -> 0 | D21: =INDEX('Fogo De Chao'!$B$6:$E$144,MATCH($B21,'Fogo De Chao'!$A$6:$A$144,0),MATCH('Fogo De Chao Financials'!D$12,'Fogo De Chao'!$B$3:$E$3,0)) -> 0 | E21: =INDEX('Fogo De Chao'!$B$6:$E$144,MATCH($B21,'Fogo De Chao'!$A$6:$A$144,0),MATCH('Fogo De Chao Financials'!E$12,'Fogo De Chao'!$B$3:$E$3,0)) -> 0 | F21: =INDEX('Fogo De Chao'!$B$6:$E$144,MATCH($B21,'Fogo De Chao'!$A$6:$A$144,0),MATCH('Fogo De Chao Financials'!F$12,'Fogo De Chao'!$B$3:$E$3,0)) -> 0 | G21: =G41*G$15 -> 0 | H21: =H41*H$15 -> 0 | I21: =I41*I$15 -> 0 | J21: =J41*J$15 -> 0 | K21: =K41*K$15 -> 0
B22: Depreciation/Amortization | C22: =INDEX('Fogo De Chao'!$B$6:$E$144,MATCH($B22,'Fogo De Chao'!$A$6:$A$144,0),MATCH('Fogo De Chao Financials'!C$12,'Fogo De Chao'!$B$3:$E$3,0)) -> 9 | D22: =INDEX('Fogo De Chao'!$B$6:$E$144,MATCH($B22,'Fogo De Chao'!$A$6:$A$144,0),MATCH('Fogo De Chao Financials'!D$12,'Fogo De Chao'!$B$3:$E$3,0)) -> 12.5 | E22: =INDEX('Fogo De Chao'!$B$6:$E$144,MATCH($B22,'Fogo De Chao'!$A$6:$A$144,0),MATCH('Fogo De Chao Financials'!E$12,'Fogo De Chao'!$B$3:$E$3,0)) -> 15.7 | F22: =INDEX('Fogo De Chao'!$B$6:$E$144,MATCH($B22,'Fogo De Chao'!$A$6:$A$144,0),MATCH('Fogo De Chao Financials'!F$12,'Fogo De Chao'!$B$3:$E$3,0)) -> 19 | G22: =G42*G$15 -> 19.95 | H22: =H42*H$15 -> 20.9475 | I22: =I42*I$15 -> 21.994875 | J22: =J42*J$15 -> 23.094619 | K22: =K42*K$15 -> 24.24935
B23: Other Operating Expenses, Total | C23: =INDEX('Fogo De Chao'!$B$6:$E$144,MATCH($B23,'Fogo De Chao'!$A$6:$A$144,0),MATCH('Fogo De Chao Financials'!C$12,'Fogo De Chao'!$B$3:$E$3,0)) -> -0.4 | D23: =INDEX('Fogo De Chao'!$B$6:$E$144,MATCH($B23,'Fogo De Chao'!$A$6:$A$144,0),MATCH('Fogo De Chao Financials'!D$12,'Fogo De Chao'!$B$3:$E$3,0)) -> -0.3 | E23: =INDEX('Fogo De Chao'!$B$6:$E$144,MATCH($B23,'Fogo De Chao'!$A$6:$A$144,0),MATCH('Fogo De Chao Financials'!E$12,'Fogo De Chao'!$B$3:$E$3,0)) -> 0 | F23: =INDEX('Fogo De Chao'!$B$6:$E$144,MATCH($B23,'Fogo De Chao'!$A$6:$A$144,0),MATCH('Fogo De Chao Financials'!F$12,'Fogo De Chao'!$B$3:$E$3,0)) -> 0.3 | G23: =G43*G$15 -> 4.41 | H23: =H43*H$15 -> 4.6305 | I23: =I43*I$15 -> 4.862025 | J23: =J43*J$15 -> 5.1051263 | K23: =K43*K$15 -> 5.3603826
B24: Unusual Expense (Income) | C24: =INDEX('Fogo De Chao'!$B$6:$E$144,MATCH($B24,'Fogo De Chao'!$A$6:$A$144,0),MATCH('Fogo De Chao Financials'!C$12,'Fogo De Chao'!$B$3:$E$3,0)) -> 6.9 | D24: =INDEX('Fogo De Chao'!$B$6:$E$144,MATCH($B24,'Fogo De Chao'!$A$6:$A$144,0),MATCH('Fogo De Chao Financials'!D$12,'Fogo De Chao'!$B$3:$E$3,0)) -> 6 | E24: =INDEX('Fogo De Chao'!$B$6:$E$144,MATCH($B24,'Fogo De Chao'!$A$6:$A$144,0),MATCH('Fogo De Chao Financials'!E$12,'Fogo De Chao'!$B$3:$E$3,0)) -> 0.3 | F24: =INDEX('Fogo De Chao'!$B$6:$E$144,MATCH($B24,'Fogo De Chao'!$A$6:$A$144,0),MATCH('Fogo De Chao Financials'!F$12,'Fogo De Chao'!$B$3:$E$3,0)) -> 4.2 | G24: =G44*G$15 -> 0 | H24: =H44*H$15 -> 0 | I24: =I44*I$15 -> 0 | J24: =J44*J$15 -> 0 | K24: =K44*K$15 -> 0
B26: Total Operating Expense | C26: =INDEX('Fogo De Chao'!$B$6:$E$144,MATCH($B26,'Fogo De Chao'!$A$6:$A$144,0),MATCH('Fogo De Chao Financials'!C$12,'Fogo De Chao'!$B$3:$E$3,0)) -> 195.2 | D26: =INDEX('Fogo De Chao'!$B$6:$E$144,MATCH($B26,'Fogo De Chao'!$A$6:$A$144,0),MATCH('Fogo De Chao Financials'!D$12,'Fogo De Chao'!$B$3:$E$3,0)) -> 248.7 | E26: =INDEX('Fogo De Chao'!$B$6:$E$144,MATCH($B26,'Fogo De Chao'!$A$6:$A$144,0),MATCH('Fogo De Chao Financials'!E$12,'Fogo De Chao'!$B$3:$E$3,0)) -> 249.9 | F26: =INDEX('Fogo De Chao'!$B$6:$E$144,MATCH($B26,'Fogo De Chao'!$A$6:$A$144,0),MATCH('Fogo De Chao Financials'!F$12,'Fogo De Chao'!$B$3:$E$3,0)) -> 284.9 | G26: =G18+SUM(G20:G24) -> 298.746 | H26: =H18+SUM(H20:H24) -> 313.6833 | I26: =I18+SUM(I20:I24) -> 329.36747 | J26: =J18+SUM(J20:J24) -> 345.83584 | K26: =K18+SUM(K20:K24) -> 363.12763
B27: Operating Income | C27: =INDEX('Fogo De Chao'!$B$6:$E$144,MATCH($B27,'Fogo De Chao'!$A$6:$A$144,0),MATCH('Fogo De Chao Financials'!C$12,'Fogo De Chao'!$B$3:$E$3,0)) -> 23.99 | D27: =INDEX('Fogo De Chao'!$B$6:$E$144,MATCH($B27,'Fogo De Chao'!$A$6:$A$144,0),MATCH('Fogo De Chao Financials'!D$12,'Fogo De Chao'!$B$3:$E$3,0)) -> 22.982 | E27: =INDEX('Fogo De Chao'!$B$6:$E$144,MATCH($B27,'Fogo De Chao'!$A$6:$A$144,0),MATCH('Fogo De Chao Financials'!E$12,'Fogo De Chao'!$B$3:$E$3,0)) -> 38.416 | F27: =INDEX('Fogo De Chao'!$B$6:$E$144,MATCH($B27,'Fogo De Chao'!$A$6:$A$144,0),MATCH('Fogo De Chao Financials'!F$12,'Fogo De Chao'!$B$3:$E$3,0)) -> 29.484 | G27: =G15-G26 -> 31.33095 | H27: =H15-H26 -> 32.897497 | I27: =I15-I26 -> 34.542372 | J27: =J15-J26 -> 36.269491 | K27: =K15-K26 -> 38.082966
B28: Operating Margin | C28: =C27/C15 -> 0.10942396 | D28: =D27/D15 -> 0.084606493 | E28: =E27/E15 -> 0.13325194 | F28: =F27/F15 -> 0.093790857 | G28: =G27/G15 -> 0.094920139 | H28: =H27/H15 -> 0.094920139 | I28: =I27/I15 -> 0.094920139 | J28: =J27/J15 -> 0.094920139 | K28: =K27/K15 -> 0.094920139
B29: EBITDA | C29: =C27+C22 -> 32.99 | D29: =D27+D22 -> 35.482 | E29: =E27+E22 -> 54.116 | F29: =F27+F22 -> 48.484 | G29: =G27+G22 -> 51.28095 | H29: =H27+H22 -> 53.844997 | I29: =I27+I22 -> 56.537247 | J29: =J27+J22 -> 59.36411 | K29: =K27+K22 -> 62.332315
B30: EBITDA Margin | C30: =C29/C15 -> 0.15047505 | D30: =D29/D15 -> 0.1306243 | E30: =E29/E15 -> 0.18770985 | F30: =F29/F15 -> 0.15423131 | G30: =G29/G15 -> 0.15536059 | H30: =H29/H15 -> 0.15536059 | I30: =I29/I15 -> 0.15536059 | J30: =J29/J15 -> 0.15536059 | K30: =K29/K15 -> 0.15536059 | L30: (held constant)
B32: Capital Expenditures | C32: =INDEX('Fogo De Chao'!$B$6:$E$144,MATCH($B32,'Fogo De Chao'!$A$6:$A$144,0),MATCH('Fogo De Chao Financials'!C$12,'Fogo De Chao'!$B$3:$E$3,0)) -> -30.944 | D32: =INDEX('Fogo De Chao'!$B$6:$E$144,MATCH($B32,'Fogo De Chao'!$A$6:$A$144,0),MATCH('Fogo De Chao Financials'!D$12,'Fogo De Chao'!$B$3:$E$3,0)) -> -35.423 | E32: =INDEX('Fogo De Chao'!$B$6:$E$144,MATCH($B32,'Fogo De Chao'!$A$6:$A$144,0),MATCH('Fogo De Chao Financials'!E$12,'Fogo De Chao'!$B$3:$E$3,0)) -> -38.353 | F32: =INDEX('Fogo De Chao'!$B$6:$E$144,MATCH($B32,'Fogo De Chao'!$A$6:$A$144,0),MATCH('Fogo De Chao Financials'!F$12,'Fogo De Chao'!$B$3:$E$3,0)) -> -35.949 | G32: =-G15*G46 -> -37.74645 | H32: =-H15*H46 -> -39.633773 | I32: =-I15*I46 -> -41.615461 | J32: =-J15*J46 -> -43.696234 | K32: =-K15*K46 -> -45.881046
B33: Changes in Working Capital | C33: =INDEX('Fogo De Chao'!$B$6:$E$144,MATCH($B33,'Fogo De Chao'!$A$6:$A$144,0),MATCH('Fogo De Chao Financials'!C$12,'Fogo De Chao'!$B$3:$E$3,0)) -> 13.601 | D33: =INDEX('Fogo De Chao'!$B$6:$E$144,MATCH($B33,'Fogo De Chao'!$A$6:$A$144,0),MATCH('Fogo De Chao Financials'!D$12,'Fogo De Chao'!$B$3:$E$3,0)) -> -0.456 | E33: =INDEX('Fogo De Chao'!$B$6:$E$144,MATCH($B33,'Fogo De Chao'!$A$6:$A$144,0),MATCH('Fogo De Chao Financials'!E$12,'Fogo De Chao'!$B$3:$E$3,0)) -> 5.595 | F33: =INDEX('Fogo De Chao'!$B$6:$E$144,MATCH($B33,'Fogo De Chao'!$A$6:$A$144,0),MATCH('Fogo De Chao Financials'!F$12,'Fogo De Chao'!$B$3:$E$3,0)) -> 7.407 | G33: =G15*G47 -> 0 | H33: =H15*H47 -> 0 | I33: =I15*I47 -> 0 | J33: =J15*J47 -> 0 | K33: =K15*K47 -> 0
B35: Key Model Drivers
B37: income Statement Driver
B38: YoY Growth | D38: =D15/C15 - 1 -> 0.23898576 | E38: =E15/D15 - 1 -> 0.061339891 | F38: =F15/E15 - 1 -> 0.090403613 | G38: 0.05 | H38: 0.05 | I38: 0.05 | J38: 0.05 | K38: 0.05
B39: Cost of revenue (% Revenue) | C39: =C18/C15 -> 0.51935103 | D39: =D18/D15 -> 0.51645229 | E39: =E18/E15 -> 0.51516844 | F39: =F18/F15 -> 0.52435909 | G39: =$F$39 -> 0.52435909 | H39: =$F$39 -> 0.52435909 | I39: =$F$39 -> 0.52435909 | J39: =$F$39 -> 0.52435909 | K39: =$F$39 -> 0.52435909 | L39: see writeup
B40: SG&A (% of Revenue) | C40: =C20/C15 -> 0.30055784 | D40: =D20/D15 -> 0.33204606 | E40: =E20/E15 -> 0.29583831 | F40: =F20/F15 -> 0.3069198 | G40: =$F$40 -> 0.3069198 | H40: =$F$40 -> 0.3069198 | I40: =$F$40 -> 0.3069198 | J40: =$F$40 -> 0.3069198 | K40: =$F$40 -> 0.3069198
B41: R&D (% of Revenue) | C41: =C21/C15 -> 0 | D41: =D21/D15 -> 0 | E41: =E21/E15 -> 0 | F41: =F21/F15 -> 0 | G41: =$F$41 -> 0 | H41: =$F$41 -> 0 | I41: =$F$41 -> 0 | J41: =$F$41 -> 0 | K41: =$F$41 -> 0
B42: D&A (% of Revenue) | C42: =C22/C15 -> 0.04105109 | D42: =D22/D15 -> 0.046017803 | E42: =E22/E15 -> 0.054457918 | F42: =F22/F15 -> 0.060440452 | G42: =$F$42 -> 0.060440452 | H42: =$F$42 -> 0.060440452 | I42: =$F$42 -> 0.060440452 | J42: =$F$42 -> 0.060440452 | K42: =$F$42 -> 0.060440452
B43: Unusual Expense (% of Revenue) | C43: =C24/C15 -> 0.031472503 | D43: =D24/D15 -> 0.022088546 | E43: =E24/E15 -> 0.0010405972 | F43: =F24/F15 -> 0.013360521 | G43: =$F$43 -> 0.013360521 | H43: =$F$43 -> 0.013360521 | I43: =$F$43 -> 0.013360521 | J43: =$F$43 -> 0.013360521 | K43: =$F$43 -> 0.013360521
B45: Cash Flow Drivers
B46: CapEx(% of revenue) | C46: =-C32/C15 -> 0.14114277 | D46: =-D32/D15 -> 0.13040709 | E46: =-E32/E15 -> 0.13303341 | F46: =-F32/F15 -> 0.11435652 | G46: =$F$46 -> 0.11435652 | H46: =$F$46 -> 0.11435652 | I46: =$F$46 -> 0.11435652 | J46: =$F$46 -> 0.11435652 | K46: =$F$46 -> 0.11435652
B47: NWC (% of revenue) | C47: -0.0253263 | D47: -0.0121976 | E47: -0.060999 | F47: 0.00723059 | G47: 0 | H47: 0 | I47: 0 | J47: 0 | K47: 0
B49: Tax Rate | C49: 0.24 | D49: =C49 -> 0.24 | E49: =D49 -> 0.24 | F49: =E49 -> 0.24 | G49: =F49 -> 0.24 | H49: =G49 -> 0.24 | I49: =H49 -> 0.24 | J49: =I49 -> 0.24 | K49: =J49 -> 0.24
D52: =AVERAGE(C29:F29) -> 42.768

Sheet LBO
B2: Bojangles LBO | L2: Fogo De Chao LBO
B3: ($MM) | L3: ($MM)
B5: Assumptions | L5: Assumptions
B7: Entry | F7: Sources | L7: Entry | P7: Sources
B8: Entry Ebitda | D8: 70 | F8: Debt | H8: 425 | I8: =H8/H16 -> 0.59399022 | L8: Entry Ebitda | N8: 59.7 | P8: Debt | R8: 300 | S8: =R8/R16 -> 0.51903114
B9: Equity Purchase Price | D9: 593.7 | F9: Sponsor Equity | H9: =H16-H8 -> 290.5 | I9: =H9/H16 -> 0.40600978 | L9: Equity Purchase Price | N9: 458.3 | P9: Sponsor Equity | R9: =R16-R8 -> 278 | S9: =R9/R16 -> 0.48096886
B10: Existing Net debt | D10: 109 | L10: Existing Net debt | N10: 101.7
B11: EV | D11: =SUM(D9:D10) -> 702.7 | F11: Uses | L11: EV | N11: 560 | P11: Uses
B12: EV / Ebitda | D12: =D11/D8 -> 10.038571 | F12: Equity Value | H12: 593.7 | L12: EV / Ebitda | N12: =N11/N8 -> 9.3802345 | P12: Equity Value | R12: 458.3
F13: Net Debt Refinanced | H13: 109 | P13: Net Debt Refinanced | R13: 101.7
B14: Exit | F14: Other Fees | H14: 12.8 | L14: Exit | P14: Other Fees | R14: 18
B15: Exit Multiple | D15: =D12 -> 10.038571 | L15: Exit Multiple | N15: =N12 -> 9.3802345
B16: Mandatory Amortization | D16: 0 | F16: Total Uses: | H16: =SUM(H12:H14) -> 715.5 | L16: Mandatory Amortization (% Initial Debt) | N16: 0 | P16: Total Uses: | R16: =SUM(R12:R14) -> 578
B17: Cash Sweep | D17: 1 | L17: Cash Sweep | N17: 1
B18: Interest Rate | D18: 0.05 | L18: Interest Rate | N18: 0.05
D20: Forecast | N20: Forecast
D21: 2018 | E21: =D21+1 -> 2019 | F21: =E21+1 -> 2020 | G21: =F21+1 -> 2021 | H21: =G21+1 -> 2022 | N21: 2018 | O21: =N21+1 -> 2019 | P21: =O21+1 -> 2020 | Q21: =P21+1 -> 2021 | R21: =Q21+1 -> 2022
B23: Revenue | D23: ='Bojangles Financials'!H15 -> 574.8099 | E23: ='Bojangles Financials'!I15 -> 603.55039 | F23: ='Bojangles Financials'!J15 -> 633.72791 | G23: ='Bojangles Financials'!K15 -> 665.41431 | H23: ='Bojangles Financials'!L15 -> 698.68503 | L23: Revenue | N23: ='Fogo De Chao Financials'!G15 -> 330.07695 | O23: ='Fogo De Chao Financials'!H15 -> 346.5808 | P23: ='Fogo De Chao Financials'!I15 -> 363.90984 | Q23: ='Fogo De Chao Financials'!J15 -> 382.10533 | R23: ='Fogo De Chao Financials'!K15 -> 401.2106
B24: EBITDA | D24: ='Bojangles Financials'!H29 -> 58.6908 | E24: ='Bojangles Financials'!I29 -> 61.62534 | F24: ='Bojangles Financials'!J29 -> 64.706607 | G24: ='Bojangles Financials'!K29 -> 67.941937 | H24: ='Bojangles Financials'!L29 -> 71.339034 | L24: EBITDA | N24: ='Fogo De Chao Financials'!G29 -> 51.28095 | O24: ='Fogo De Chao Financials'!H29 -> 53.844997 | P24: ='Fogo De Chao Financials'!I29 -> 56.537247 | Q24: ='Fogo De Chao Financials'!J29 -> 59.36411 | R24: ='Fogo De Chao Financials'!K29 -> 62.332315
B25: EBITDA Margin | D25: =D24/D23 -> 0.10210471 | E25: =E24/E23 -> 0.10210471 | F25: =F24/F23 -> 0.10210471 | G25: =G24/G23 -> 0.10210471 | H25: =H24/H23 -> 0.10210471 | L25: EBITDA Margin | N25: =N24/N23 -> 0.15536059 | O25: =O24/O23 -> 0.15536059 | P25: =P24/P23 -> 0.15536059 | Q25: =Q24/Q23 -> 0.15536059 | R25: =R24/R23 -> 0.15536059
B26: D&A | D26: ='Bojangles Financials'!H22 -> 3.045 | E26: ='Bojangles Financials'!I22 -> 3.19725 | F26: ='Bojangles Financials'!J22 -> 3.3571125 | G26: ='Bojangles Financials'!K22 -> 3.5249681 | H26: ='Bojangles Financials'!L22 -> 3.7012165 | L26: D&A | N26: ='Fogo De Chao Financials'!G22 -> 19.95 | O26: ='Fogo De Chao Financials'!H22 -> 20.9475 | P26: ='Fogo De Chao Financials'!I22 -> 21.994875 | Q26: ='Fogo De Chao Financials'!J22 -> 23.094619 | R26: ='Fogo De Chao Financials'!K22 -> 24.24935
B27: CapEx | D27: ='Bojangles Financials'!H32 -> -10.0968 | E27: ='Bojangles Financials'!I32 -> -10.60164 | F27: ='Bojangles Financials'!J32 -> -11.131722 | G27: ='Bojangles Financials'!K32 -> -11.688308 | H27: ='Bojangles Financials'!L32 -> -12.272724 | L27: CapEx | N27: ='Fogo De Chao Financials'!G32 -> -37.74645 | O27: ='Fogo De Chao Financials'!H32 -> -39.633773 | P27: ='Fogo De Chao Financials'!I32 -> -41.615461 | Q27: ='Fogo De Chao Financials'!J32 -> -43.696234 | R27: ='Fogo De Chao Financials'!K32 -> -45.881046
B28: Change in NWC | D28: ='Bojangles Financials'!H33 -> 0 | E28: ='Bojangles Financials'!I33 -> 0 | F28: ='Bojangles Financials'!J33 -> 0 | G28: ='Bojangles Financials'!K33 -> 0 | H28: ='Bojangles Financials'!L33 -> 0 | L28: Change in NWC | N28: ='Fogo De Chao Financials'!G33 -> 0 | O28: ='Fogo De Chao Financials'!S33 -> 0 | P28: ='Fogo De Chao Financials'!T33 -> 0 | Q28: ='Fogo De Chao Financials'!U33 -> 0 | R28: ='Fogo De Chao Financials'!V33 -> 0
B29: Cash Tax Rate | D29: ='Bojangles Financials'!C49 -> 0.24 | E29: ='Bojangles Financials'!D49 -> 0.24 | F29: ='Bojangles Financials'!E49 -> 0.24 | G29: ='Bojangles Financials'!F49 -> 0.24 | H29: ='Bojangles Financials'!G49 -> 0.24 | L29: Cash Tax Rate | N29: ='Fogo De Chao Financials'!C49 -> 0.24 | O29: ='Fogo De Chao Financials'!D49 -> 0.24 | P29: ='Fogo De Chao Financials'!E49 -> 0.24 | Q29: ='Fogo De Chao Financials'!F49 -> 0.24 | R29: ='Fogo De Chao Financials'!G49 -> 0.24
B30: Interest Rate | D30: =$D$18 -> 0.05 | E30: =$D$18 -> 0.05 | F30: =$D$18 -> 0.05 | G30: =$D$18 -> 0.05 | H30: =$D$18 -> 0.05 | L30: Interest Rate | N30: =$N$18 -> 0.05 | O30: =$N$18 -> 0.05 | P30: =$N$18 -> 0.05 | Q30: =$N$18 -> 0.05 | R30: =$N$18 -> 0.05
B31: Cash Interest | D31: =D34*D30 -> 21.25 | E31: =E34*E30 -> 19.8828 | F31: =F34*F30 -> 18.325755 | G31: =G34*G30 -> 16.563298 | H31: =H34*H30 -> 14.578782 | L31: Cash Interest | N31: =N34*N30 -> 15 | O31: =O34*O30 -> 15 | P31: =P34*P30 -> 15 | Q31: =Q34*Q30 -> 15 | R31: =R34*R30 -> 14.966606
B32: Levered Free Cash Flow | D32: =(D23*D25)-D31+D27-D28 -> 27.344 | E32: =(E23*E25)-E31+E27-E28 -> 31.1409 | F32: =(F23*F25)-F31+F27-F28 -> 35.24913 | G32: =(G23*G25)-G31+G27-G28 -> 39.690331 | H32: =(H23*H25)-H31+H27-H28 -> 44.487529 | L32: Levered Free Cash Flow | N32: =(N23*N25)-N31+N27-N28 -> -1.4655 | O32: =(O23*O25)-O31+O27-O28 -> -0.788775 | P32: =(P23*P25)-P31+P27-P28 -> -0.07821375 | Q32: =(Q23*Q25)-Q31+Q27-Q28 -> 0.66787556 | R32: =(R23*R25)-R31+R27-R28 -> 1.4846631 | S32: (see writeup)
B34: Beginning Debt | D34: =H8 -> 425 | E34: =D37 -> 397.656 | F34: =E37 -> 366.5151 | G34: =F37 -> 331.26597 | H34: =G37 -> 291.57564 | L34: Beginning Debt | N34: =R8 -> 300 | O34: =N37 -> 300 | P34: =O37 -> 300 | Q34: =P37 -> 300 | R34: =Q37 -> 299.33212 | S34: (see writeup)
B35: Mandatory Amoritization | D35: =$D$16*$H$8 -> 0 | E35: =$D$16*$H$8 -> 0 | F35: =$D$16*$H$8 -> 0 | G35: =$D$16*$H$8 -> 0 | H35: =$D$16*$H$8 -> 0 | L35: Mandatory Amoritization | N35: =MIN($D$16*$R$8) -> 0 | O35: =MIN($D$16*$R$8) -> 0 | P35: =MIN($D$16*$R$8) -> 0 | Q35: =MIN($D$16*$R$8) -> 0 | R35: =MIN($D$16*$R$8) -> 0
B36: Cash Sweep Paydown | D36: =MAX(D32-D35,0) -> 27.344 | E36: =MAX(E32-E35,0) -> 31.1409 | F36: =MAX(F32-F35,0) -> 35.24913 | G36: =MAX(G32-G35,0) -> 39.690331 | H36: =MAX(H32-H35,0) -> 44.487529 | L36: Cash Sweep Paydown | N36: =MAX(N32-N35,0) -> 0 | O36: =MAX(O32-O35,0) -> 0 | P36: =MAX(P32-P35,0) -> 0 | Q36: =MAX(Q32-Q35,0) -> 0.66787556 | R36: =MAX(R32-R35,0) -> 1.4846631
B37: Ending Debt | D37: =D34-D35-D36 -> 397.656 | E37: =E34-E35-E36 -> 366.5151 | F37: =F34-F35-F36 -> 331.26597 | G37: =G34-G35-G36 -> 291.57564 | H37: =H34-H35-H36 -> 247.08811 | L37: Ending Debt | N37: =N34-N36 -> 300 | O37: =O34-O36 -> 300 | P37: =P34-P36 -> 300 | Q37: =Q34-Q36 -> 299.33212 | R37: =R34-R36 -> 297.84746
B39: Exit Enterprise value | D39: =H24*D15 -> 716.14199 | L39: Exit Enterprise value | N39: =R24*N15 -> 584.69173
B40: Exit Equity Value | D40: =D39-H37 -> 469.05388 | L40: Exit Equity Value | N40: =N39-R37-SUM(N32:P32) -> 289.17676
B42: IRR | D42: =(D40/H9)^(1/5)-1 -> 0.10056404 | L42: IRR | N42: =(N40/R9)^(1/5)-1 -> 0.0079145597
B43: MOIC | D43: =D40/H9 -> 1.6146433 | L43: MOIC | N43: =N40/R9 -> 1.0402042

Sheet Bojales Raw
A1: Bojangles' Inc (BOJA)
A2: Income Statement - Annual (As Originally Reported) | B2: 5 | C2: 4 | D2: 3 | E2: 2 | F2: 1
A3: FYE December | B3: 41910 | C3: 42001 | D3: 42365 | E3: 42729 | F3: 43100
A4: Currency | B4: USD | C4: USD | D4: USD | E4: USD | F4: USD
A5: Scale | B5: Million | C5: Million | D5: Million | E5: Million | F5: Million
A6: Total Revenue | B6: 375.162 | C6: 430.472 | D6: 488.202 | E6: 531.881 | F6: 547.438
A7: Cost of Revenue, Total | B7: 302.112 | C7: 343.886 | D7: 389.315 | E7: 422.448 | F7: 451.445
A8: Gross Profit | B8: 73.05 | C8: 86.586 | D8: 98.887 | E8: 109.433 | F8: 95.993
A9: Selling/General/Admin. Expenses, Total | B9: 27.478 | C9: 32.107 | D9: 42.844 | E9: 39.041 | F9: 38.397
A10: Research & Development
A11: Depreciation/Amortization | B11: 2.2 | C11: 2.4 | D11: 2.8 | E11: 2.9 | F11: 2.9
A12: Interest Exp.(Inc.), Net-Operating, Total
A13: Unusual Expense (Income) | B13: 0.1 | C13: 0.5 | D13: 1.5 | E13: 2 | F13: 1.7
A14: Other Operating Expenses, Total
A15: Total Operating Expense | B15: 331.8 | C15: 378.9 | D15: 436.5 | E15: 466.4 | F15: 494.5
A16: Operating Income | B16: 43.321 | C16: 51.563 | D16: 51.688 | E16: 65.501 | F16: 52.942
A17: Interest Inc.(Exp.),Net-Non-Op., Total | B17: -9.1 | C17: -9.9 | D17: -9.1 | E17: -8.2 | F17: -7.1
A18: Gain (Loss) on Sale of Assets
A19: Other, Net
A20: Net Income Before Taxes | B20: 34.242 | C20: 41.709 | D20: 42.56 | E20: 57.253 | F20: 45.881
A21: Provision for Income Taxes | B21: 9.915 | C21: 15.589 | D21: 16.034 | E21: 19.537 | F21: 13.975
A22: Net Income | B22: 24.327 | C22: 26.12 | D22: 26.526 | E22: 37.716 | F22: 72.006
A23: Preferred Dividends
A24: Basic EPS Excluding Extraordinary Items | B24: 0.68 | C24: 0.73 | D24: 1.15 | E24: 1.04 | F24: 0.87
A25: Basic EPS Including Extraordinary Items | B25: 0.68 | C25: 0.73 | D25: 1.15 | E25: 1.04 | F25: 1.95
A26: Normalized Basic EPS | B26: 0.65 | C26: 0.74 | D26: 1.15 | E26: 1.05 | F26: 0.87
A27: Basic Weighted Average Shares | B27: 36 | C27: 36 | D27: 23 | E27: 36 | F27: 37
A28: Diluted EPS Excluding ExtraOrd Items | B28: 0.68 | C28: 0.73 | D28: 0.71 | E28: 1 | F28: 0.83
A29: Diluted EPS Including ExtraOrd Items | B29: 0.68 | C29: 0.73 | D29: 0.71 | E29: 1 | F29: 1.87
A30: Normalized Diluted EPS | B30: 0.65 | C30: 0.74 | D30: 0.71 | E30: 1.01 | F30: 0.83
A31: Diluted Weighted Average Shares | B31: 36 | C31: 36 | D31: 37 | E31: 38 | F31: 39
A32: Dividends Per Share | B32: 0 | C32: 0
A33: Number of Employees | C33: 8800 | D33: 9520 | E33: 9850 | F33: 9900
A36: Bojangles' Inc (BOJA)
A37: Balance Sheet - Annual (As Originally Reported)
A38: FYE December | B38: 41910 | C38: 42001 | D38: 42365 | E38: 42729 | F38: 43100
A39: Currency | B39: USD | C39: USD | D39: USD | E39: USD | F39: USD
A40: Scale | B40: Million | C40: Million | D40: Million | E40: Million | F40: Million
A41: Cash & Equivalents | B41: 8.456 | C41: 13.201 | D41: 14.263 | E41: 13.898 | F41: 14.052
A42: Cash, Cash Equiv. & Short Term Inv. | B42: 8.456 | C42: 13.201 | D42: 14.263 | E42: 13.898 | F42: 14.052
...

Sheet Fogo De Chao
A1: Fogo De Chao Inc (FOGO)
A2: Income Statement - Annual (As Originally Reported)
A3: FYE December | B3: 42092 | C3: 42372 | D3: 42736 | E3: 43100
A4: Currency | B4: USD | C4: USD | D4: USD | E4: USD
A5: Scale | B5: Million | C5: Million | D5: Million | E5: Million
A6: Total Revenue | B6: 219.239 | C6: 271.634 | D6: 288.296 | E6: 314.359
A7: Cost of Revenue, Total | B7: 113.862 | C7: 140.286 | D7: 148.521 | E7: 164.837
A8: Gross Profit | B8: 105.377 | C8: 131.348 | D8: 139.775 | E8: 149.522
A9: Selling/General/Admin. Expenses, Total | B9: 65.894 | C9: 90.195 | D9: 85.289 | E9: 96.483
A10: Research & Development
A11: Depreciation/Amortization | B11: 9 | C11: 12.5 | D11: 15.7 | E11: 19
A12: Interest Exp.(Inc.), Net-Operating, Total
A13: Unusual Expense (Income) | B13: 6.9 | C13: 6 | D13: 0.3 | E13: 4.2
A14: Other Operating Expenses, Total | B14: -0.4 | C14: -0.3 | D14: 0 | E14: 0.3
A15: Total Operating Expense | B15: 195.2 | C15: 248.7 | D15: 249.9 | E15: 284.9
A16: Operating Income | B16: 23.99 | C16: 22.982 | D16: 38.416 | E16: 29.484
A17: Interest Inc.(Exp.),Net-Non-Op., Total | B17: -22.4 | C17: -9.1 | D17: -2.2 | E17: -2.6
A18: Gain (Loss) on Sale of Assets
A19: Other, Net | B19: -0.1 | C19: 0 | D19: 0 | E19: 0
A20: Net Income Before Taxes | B20: 1.535 | C20: 13.829 | D20: 36.219 | E20: 26.935
A21: Provision for Income Taxes | B21: 2.472 | C21: -14.168 | D21: 11.957 | E21: 7.051
A22: Net Income | B22: -0.937 | C22: 27.865 | D22: 24.437 | E22: 28.789
A23: Preferred Dividends
A24: Basic EPS Excluding Extraordinary Items | B24: -0.03 | C24: 1.09 | D24: 0.87 | E24: 0.72
A25: Basic EPS Including Extraordinary Items | B25: -0.03 | C25: 1.09 | D25: 0.87 | E25: 1.02
A26: Normalized Basic EPS | B26: 0.13 | C26: 1.24 | D26: 0.88 | E26: 0.83
A27: Basic Weighted Average Shares | B27: 27 | C27: 26 | D27: 28 | E27: 28
A28: Diluted EPS Excluding ExtraOrd Items | B28: -0.03 | C28: 1.06 | D28: 0.85 | E28: 0.7
A29: Diluted EPS Including ExtraOrd Items | B29: -0.03 | C29: 1.06 | D29: 0.85 | E29: 1
A30: Normalized Diluted EPS | B30: 0.13 | C30: 1.21 | D30: 0.86 | E30: 0.81
A31: Diluted Weighted Average Shares | B31: 27 | C31: 26 | D31: 29 | E31: 29
A32: Dividends Per Share | B32: 0 | C32: 0
A33: Number of Employees | C33: 2848 | D33: 3154 | E33: 3491
A36: Fogo De Chao Inc (FOGO)
A37: Balance Sheet - Annual (As Originally Reported)
A38: FYE December | B38: 42092 | C38: 42372 | D38: 42736 | E38: 43100
A39: Currency | B39: USD | C39: USD | D39: USD | E39: USD
A40: Scale | B40: Million | C40: Million | D40: Million | E40: Million
A41: Cash & Equivalents | B41: 16.01 | C41: 24.919 | D41: 31.275 | E41: 38.342
A42: Cash, Cash Equiv. & Short Term Inv. | B42: 16.01 | C42: 24.919 | D42: 31.275 | E42: 38.342
...
